[2023-06-12 08:56:50,113] root - INFO - Training pipleine config: TrainingPipelineConfig(artifact_dir='C:\\Users\\Sumeet Maheshwari\\Desktop\\end to end project\\Store Sales Forcasting using Time series\\store-sales-forcasting\\Sales_Forecasting_Artifact\\Artifact')
[2023-06-12 08:56:50,113] root - INFO - Data Ingestion config: DataIngestionConfig(raw_data_dir='C:\\Users\\Sumeet Maheshwari\\Desktop\\end to end project\\Store Sales Forcasting using Time series\\store-sales-forcasting\\Sales_Forecasting_Artifact\\Artifact\\data_ingestion\\2023-06-12-08-56-45\\raw_data', ingested_data_dir='C:\\Users\\Sumeet Maheshwari\\Desktop\\end to end project\\Store Sales Forcasting using Time series\\store-sales-forcasting\\Sales_Forecasting_Artifact\\Artifact\\data_ingestion\\2023-06-12-08-56-45\\ingested_data')
[2023-06-12 08:56:50,115] root - INFO - >>>>>>>>>>>>>>>>>>>>>>>>>>>>>>>>>>>>>>>>>>>>>>>>>>>>>>>>>>>>Data Ingestion log started.<<<<<<<<<<<<<<<<<<<<<<<<<<<<<<<<<<<<<<<<<<<<<<<<<<<<<<<<<<<< 


[2023-06-12 08:56:50,396] root - INFO - Data Ingestion Artifact
[2023-06-12 08:56:50,396] root - INFO - File Path : C:\Users\Sumeet Maheshwari\Desktop\Store sales Forecasting (2)\Jup_Notebook\Merged_dataset\outlier_clean.csv
[2023-06-12 08:56:50,396] root - INFO - File Name: final_data.csv
[2023-06-12 08:56:50,396] root - INFO - File Ingested File Path: C:\Users\Sumeet Maheshwari\Desktop\end to end project\Store Sales Forcasting using Time series\store-sales-forcasting\Sales_Forecasting_Artifact\Artifact\data_ingestion\2023-06-12-08-56-45\raw_data\final_data.csv
[2023-06-12 08:56:50,396] root - INFO - >>>>>>>>>>>>>>>>>>>>>>>>>>>>>>>>>>>>>>>>>>>>>>>>>>>>>>>>>>>>Data Validation log started.<<<<<<<<<<<<<<<<<<<<<<<<<<<<<<<<<<<<<<<<<<<<<<<<<<<<<<<<<<<< 


[2023-06-12 08:56:50,396] root - INFO - *****************Ingested data validation Started****************
[2023-06-12 08:56:50,403] root - INFO - Validation Process Started
[2023-06-12 08:56:50,403] root - INFO - Checking filename
[2023-06-12 08:56:50,404] root - INFO - Checking check_column_names
[2023-06-12 08:56:57,850] root - INFO - Checking missing_values_whole_columns
[2023-06-12 08:57:04,810] root - INFO - Checking replacinig_null_values_with_null
[2023-06-12 08:57:13,968] root - INFO - replacinig_null_values_with_null is sucessfully
[2023-06-12 08:57:14,068] root - INFO - Train_set status|is Train filename validated?: True|is train column name validated?: True|whole missing columns?True
[2023-06-12 08:57:14,313] root - INFO - Exported validated  dataset to file: [C:\Users\Sumeet Maheshwari\Desktop\end to end project\Store Sales Forcasting using Time series\store-sales-forcasting\Sales_Forecasting_Artifact\Artifact\data_validation\2023-06-12-08-56-45\validated_data]
[2023-06-12 08:57:14,313] root - INFO - Checking for Data Drift
[2023-06-12 08:57:14,313] root - INFO - Generating data drift report.json file
[2023-06-12 08:58:19,973] root - INFO - Report.json file generation successful!!
[2023-06-12 08:58:20,042] root - INFO - Generating data drift report.html page
[2023-06-12 08:59:25,559] root - INFO - Report.html page generation successful!!
[2023-06-12 08:59:25,639] root - INFO - Data validation artifact: DataValidationArtifact(schema_file_path='C:\\Users\\Sumeet Maheshwari\\Desktop\\end to end project\\Store Sales Forcasting using Time series\\store-sales-forcasting\\config\\schema.yaml', report_file_path='C:\\Users\\Sumeet Maheshwari\\Desktop\\end to end project\\Store Sales Forcasting using Time series\\store-sales-forcasting\\Sales_Forecasting_Artifact\\Artifact\\data_validation\\2023-06-12-08-56-45\\report.json', report_page_file_path='C:\\Users\\Sumeet Maheshwari\\Desktop\\end to end project\\Store Sales Forcasting using Time series\\store-sales-forcasting\\Sales_Forecasting_Artifact\\Artifact\\data_validation\\2023-06-12-08-56-45\\report.html', validated_file_path='C:\\Users\\Sumeet Maheshwari\\Desktop\\end to end project\\Store Sales Forcasting using Time series\\store-sales-forcasting\\Sales_Forecasting_Artifact\\Artifact\\data_validation\\2023-06-12-08-56-45\\validated_data', message='Validated')
[2023-06-12 08:59:25,639] root - INFO - >>>>>>>>>>>>>>>>>>>>>>>>>>>>>>>>>>>>>>>>>>>>>>>>>>>>>>>>>>>>Data Validation log completed.<<<<<<<<<<<<<<<<<<<<<<<<<<<<<<<<<<<<<<<<<<<<<<<<<<<<<<<<<<<<
[2023-06-12 08:59:25,639] root - INFO - Data Transformation Config: DataTransformationConfig(transformed_train_dir='C:\\Users\\Sumeet Maheshwari\\Desktop\\end to end project\\Store Sales Forcasting using Time series\\store-sales-forcasting\\Sales_Forecasting_Artifact\\Artifact\\data_transformation\\2023-06-12-08-56-45\\transformed_data\\train', transformed_test_dir='C:\\Users\\Sumeet Maheshwari\\Desktop\\end to end project\\Store Sales Forcasting using Time series\\store-sales-forcasting\\Sales_Forecasting_Artifact\\Artifact\\data_transformation\\2023-06-12-08-56-45\\transformed_data\\test', time_series_data_file_path='C:\\Users\\Sumeet Maheshwari\\Desktop\\end to end project\\Store Sales Forcasting using Time series\\store-sales-forcasting\\Sales_Forecasting_Artifact\\Artifact\\data_transformation\\2023-06-12-08-56-45\\transformed_data\\time_series_data', preprocessed_object_file_path='C:\\Users\\Sumeet Maheshwari\\Desktop\\end to end project\\Store Sales Forcasting using Time series\\store-sales-forcasting\\Sales_Forecasting_Artifact\\Artifact\\data_transformation\\2023-06-12-08-56-45\\preprocessed\\preprocessed.pkl', feature_engineering_object_file_path='C:\\Users\\Sumeet Maheshwari\\Desktop\\end to end project\\Store Sales Forcasting using Time series\\store-sales-forcasting\\Sales_Forecasting_Artifact\\Artifact\\data_transformation\\2023-06-12-08-56-45\\preprocessed\\feat_eng.pkl')
[2023-06-12 08:59:25,639] root - INFO - 
******************** Data Transformation log started ********************


[2023-06-12 08:59:25,644] root - INFO - Obtaining file from file path 
[2023-06-12 08:59:25,644] root - INFO - Loading Data as pandas dataframe.
[2023-06-12 08:59:31,361] root - INFO -  Data columns Index(['date', 'store_nbr', 'family', 'sales', 'onpromotion', 'holiday_type',
       'locale', 'locale_name', 'description', 'transferred', 'oil_price',
       'city', 'state', 'store_type', 'cluster', 'transactions', 'year',
       'month', 'week', 'quarter', 'day_of_week'],
      dtype='object')
[2023-06-12 08:59:31,361] root - INFO - Numerical columns: ['store_nbr', 'onpromotion', 'oil_price', 'cluster', 'transactions']
[2023-06-12 08:59:31,361] root - INFO - Categorical columns: ['family', 'holiday_type', 'locale', 'locale_name', 'description', 'city', 'state', 'store_type', 'transferred']
[2023-06-12 08:59:31,361] root - INFO - Target Column: ['sales']
[2023-06-12 08:59:31,361] root - INFO - Date column :['date']
[2023-06-12 08:59:31,361] root - INFO - All columns: ['store_nbr', 'onpromotion', 'oil_price', 'cluster', 'transactions', 'family', 'holiday_type', 'locale', 'locale_name', 'description', 'city', 'state', 'store_type', 'transferred', 'date', 'sales']
[2023-06-12 08:59:31,714] root - INFO - Obtaining feature engineering object.
[2023-06-12 08:59:31,714] root - INFO - 
******************** Feature Engneering Started ********************


[2023-06-12 08:59:31,714] root - INFO -  Numerical Columns , Categorical Columns , Target Column initialised in Feature engineering Pipeline 
[2023-06-12 08:59:31,714] root - INFO - <class 'sklearn.pipeline.Pipeline'>
[2023-06-12 08:59:31,714] root - INFO - Feature engineering object droping unwanted columns
[2023-06-12 08:59:31,714] root - INFO - Applying feature engineering object on training dataframe and testing dataframe
[2023-06-12 08:59:31,714] root - INFO - >>>>>>>>>>>>>>>>>>>>>>>>>>>>>>>>>>>>>>>>>>>>>>>>>>>>>>>>>>>> Training data <<<<<<<<<<<<<<<<<<<<<<<<<<<<<<<<<<<<<<<<<<<<<<<<<<<<<<<<<<<<
[2023-06-12 08:59:31,714] root - INFO - Feature Enineering - Train Data 
[2023-06-12 08:59:31,714] root - INFO - Columns not found: ['year', 'month', 'week', 'quarter', 'day_of_week']
[2023-06-12 08:59:32,179] root - INFO -  Oil Price column renamed 
[2023-06-12 08:59:32,194] root - INFO -    store_nbr  onpromotion  oil_price  cluster  transactions  ...      state store_type transferred       date sales
0          1            0      93.14       13   1697.071441  ...  Pichincha          D       False 2013-01-01   0.0
1          1            0      93.14       13   1697.071441  ...  Pichincha          D       False 2013-01-01   0.0
2          1            0      93.14       13   1697.071441  ...  Pichincha          D       False 2013-01-01   0.0
3          1            0      93.14       13   1697.071441  ...  Pichincha          D       False 2013-01-01   0.0
4          1            0      93.14       13   1697.071441  ...  Pichincha          D       False 2013-01-01   0.0

[5 rows x 16 columns]
[2023-06-12 08:59:34,372] root - INFO - Shape before removing duplicates: (3054348, 16)
[2023-06-12 08:59:34,372] root - INFO - Shape after removing duplicates: (3054348, 16)
[2023-06-12 08:59:34,372] root - INFO - Count of duplicate values: 0
[2023-06-12 08:59:36,680] root - INFO - No missing values found in the dataframe.
[2023-06-12 08:59:36,680] root - INFO - 'id' column not found. Skipping dropping operation.
[2023-06-12 08:59:36,681] root - INFO - Dropping rows with null values...
[2023-06-12 08:59:36,681] root - INFO - Resetting DataFrame index...
[2023-06-12 08:59:36,681] root - INFO - Columns dropped, null values removed, and index reset.
[2023-06-12 08:59:36,692] root - INFO - Top 5 rows of df: 
    store_nbr  onpromotion  oil_price  cluster  transactions  ...      state store_type transferred       date sales
0          1            0      93.14       13   1697.071441  ...  Pichincha          D       False 2013-01-01   0.0
1          1            0      93.14       13   1697.071441  ...  Pichincha          D       False 2013-01-01   0.0
2          1            0      93.14       13   1697.071441  ...  Pichincha          D       False 2013-01-01   0.0
3          1            0      93.14       13   1697.071441  ...  Pichincha          D       False 2013-01-01   0.0
4          1            0      93.14       13   1697.071441  ...  Pichincha          D       False 2013-01-01   0.0

[5 rows x 16 columns]
[2023-06-12 08:59:36,692] root - INFO - Handling missing values in 'transactions' column...
[2023-06-12 08:59:36,726] root - INFO - Checking 'oil_price' column for missing values...
[2023-06-12 08:59:36,731] root - INFO - Number of missing values: 0
[2023-06-12 08:59:36,731] root - INFO - interpolate missing values in 'oil_price' column...
[2023-06-12 08:59:36,759] root - INFO - Number of missing values after filling: 0
[2023-06-12 08:59:36,889] root - INFO - 0    Holiday
Name: holiday_type, dtype: object
[2023-06-12 08:59:36,889] root - INFO - Filling missing values in 'holiday_type' column with mode...
[2023-06-12 08:59:37,131] root - INFO - Filling missing values in 'locale' column with mode...
[2023-06-12 08:59:37,346] root - INFO - Filling missing values in 'locale_name' column with mode...
[2023-06-12 08:59:37,571] root - INFO - Filling missing values in 'description' column with mode...
[2023-06-12 08:59:37,789] root - INFO - Filling missing values in 'transferred' column with mode...
[2023-06-12 08:59:37,803] root - INFO - Missing values handled.
[2023-06-12 08:59:38,053] root - INFO - Column 'family' converted to 'category' data type.
[2023-06-12 08:59:38,265] root - INFO - Column 'holiday_type' converted to 'category' data type.
[2023-06-12 08:59:38,467] root - INFO - Column 'locale' converted to 'category' data type.
[2023-06-12 08:59:38,638] root - INFO - Column 'locale_name' converted to 'category' data type.
[2023-06-12 08:59:38,829] root - INFO - Column 'description' converted to 'category' data type.
[2023-06-12 08:59:38,977] root - INFO - Column 'city' converted to 'category' data type.
[2023-06-12 08:59:39,126] root - INFO - Column 'state' converted to 'category' data type.
[2023-06-12 08:59:39,231] root - INFO - Column 'store_type' converted to 'category' data type.
[2023-06-12 08:59:39,273] root - INFO - Column 'transferred' converted to 'category' data type.
[2023-06-12 08:59:39,274] root - INFO - Dropping unwanted columns form dataframe
[2023-06-12 09:00:07,034] root - INFO - Mapping unique values of categorical columns:
[2023-06-12 09:00:07,061] root - INFO - Column: 'family', Unique Values: ['AUTOMOTIVE', 'BABY CARE', 'BEAUTY', 'BEVERAGES', 'BOOKS', ..., 'POULTRY', 'PREPARED FOODS', 'PRODUCE', 'SCHOOL AND OFFICE SUPPLIES', 'SEAFOOD']
Length: 33
Categories (33, object): ['AUTOMOTIVE', 'BABY CARE', 'BEAUTY', 'BEVERAGES', ..., 'PREPARED FOODS',
                          'PRODUCE', 'SCHOOL AND OFFICE SUPPLIES', 'SEAFOOD']
[2023-06-12 09:00:07,090] root - INFO - Column: 'holiday_type', Unique Values: ['Holiday', 'Work Day', 'Additional', 'Event', 'Transfer', 'Bridge']
Categories (6, object): ['Additional', 'Bridge', 'Event', 'Holiday', 'Transfer', 'Work Day']
[2023-06-12 09:00:07,119] root - INFO - Column: 'store_type', Unique Values: ['D', 'C', 'B', 'E', 'A']
Categories (5, object): ['A', 'B', 'C', 'D', 'E']
[2023-06-12 09:00:07,128] root - INFO -    store_nbr  onpromotion  oil_price  cluster  transactions family holiday_type store_type       date  sales
0          1            0      93.14       13   1697.071441      0            0          0 2013-01-01    0.0
1          1            0      93.14       13   1697.071441      1            0          0 2013-01-01    0.0
2          1            0      93.14       13   1697.071441      2            0          0 2013-01-01    0.0
3          1            0      93.14       13   1697.071441      3            0          0 2013-01-01    0.0
4          1            0      93.14       13   1697.071441      4            0          0 2013-01-01    0.0
[2023-06-12 09:00:07,128] root - INFO -  Data Modification Done
[2023-06-12 09:00:07,128] root - INFO - Column Data Types:
[2023-06-12 09:00:07,128] root - INFO - Column: 'store_nbr': int64
[2023-06-12 09:00:07,128] root - INFO - Column: 'onpromotion': int64
[2023-06-12 09:00:07,128] root - INFO - Column: 'oil_price': float64
[2023-06-12 09:00:07,129] root - INFO - Column: 'cluster': int64
[2023-06-12 09:00:07,129] root - INFO - Column: 'transactions': float64
[2023-06-12 09:00:07,129] root - INFO - Column: 'family': category
[2023-06-12 09:00:07,129] root - INFO - Column: 'holiday_type': category
[2023-06-12 09:00:07,129] root - INFO - Column: 'store_type': category
[2023-06-12 09:00:07,129] root - INFO - Column: 'date': datetime64[ns]
[2023-06-12 09:00:07,129] root - INFO - Column: 'sales': float64
[2023-06-12 09:00:07,210] root - INFO - Data Wrangling Done
[2023-06-12 09:00:11,489] root - INFO - Converting featured engineered array into dataframe.
[2023-06-12 09:00:12,773] root - INFO - Feature Engineering - Train Completed
[2023-06-12 09:00:12,774] root - INFO - Index(['store_nbr', 'onpromotion', 'oil_price', 'cluster', 'transactions',
       'family', 'holiday_type', 'locale', 'locale_name', 'description',
       'city', 'state', 'store_type', 'transferred', 'date', 'sales'],
      dtype='object')
[2023-06-12 09:00:13,976] root - INFO -  X_Train_Shape :(2443478, 8) Y_Train_Shape : (2443478, 1)
[2023-06-12 09:00:13,976] root - INFO -  X_Test_Shape :(610870, 8) Y_Test_Shape : (610870, 1)
[2023-06-12 09:00:13,977] root - INFO - Input Columns in Split data : Index(['store_nbr', 'onpromotion', 'oil_price', 'cluster', 'transactions',
       'family', 'holiday_type', 'store_type'],
      dtype='object')| Target Column Index(['sales'], dtype='object')
[2023-06-12 09:00:13,977] root - INFO - Applying preprocessing object on training dataframe and testing dataframe
[2023-06-12 09:00:13,977] root - INFO - Creating Data Transformer Object
[2023-06-12 09:00:20,789] root - INFO - Saving Transformed Train and Transformed test file
[2023-06-12 09:00:43,992] root - INFO - Transformed Train and Transformed test file saved
[2023-06-12 09:00:43,992] root - INFO - Saving Feature Engineering Object
[2023-06-12 09:00:43,995] root - INFO - Saving Preprocessing Object
[2023-06-12 09:00:44,001] root - INFO - Data Transformation Artifact: DataTransformationArtifact(message='Data transformation successfull.', transformed_train_file_path='C:\\Users\\Sumeet Maheshwari\\Desktop\\end to end project\\Store Sales Forcasting using Time series\\store-sales-forcasting\\Sales_Forecasting_Artifact\\Artifact\\data_transformation\\2023-06-12-08-56-45\\transformed_data\\train\\transformed_train.csv', transformed_test_file_path='C:\\Users\\Sumeet Maheshwari\\Desktop\\end to end project\\Store Sales Forcasting using Time series\\store-sales-forcasting\\Sales_Forecasting_Artifact\\Artifact\\data_transformation\\2023-06-12-08-56-45\\transformed_data\\test\\transformed_test.csv', time_series_data_file_path='C:\\Users\\Sumeet Maheshwari\\Desktop\\end to end project\\Store Sales Forcasting using Time series\\store-sales-forcasting\\Sales_Forecasting_Artifact\\Artifact\\data_transformation\\2023-06-12-08-56-45\\transformed_data\\time_series_data\\time_series_data.csv', preprocessed_object_file_path='C:\\Users\\Sumeet Maheshwari\\Desktop\\end to end project\\Store Sales Forcasting using Time series\\store-sales-forcasting\\Sales_Forecasting_Artifact\\Artifact\\data_transformation\\2023-06-12-08-56-45\\preprocessed\\preprocessed.pkl', feature_engineering_object_file_path='C:\\Users\\Sumeet Maheshwari\\Desktop\\end to end project\\Store Sales Forcasting using Time series\\store-sales-forcasting\\Sales_Forecasting_Artifact\\Artifact\\data_transformation\\2023-06-12-08-56-45\\preprocessed\\feat_eng.pkl')
[2023-06-12 09:00:45,364] root - INFO - 
******************** Data Transformation log completed ********************


[2023-06-12 09:00:45,364] root - INFO - Model Trainer Config : ModelTrainerConfig(trained_model_file_path='C:\\Users\\Sumeet Maheshwari\\Desktop\\end to end project\\Store Sales Forcasting using Time series\\store-sales-forcasting\\Sales_Forecasting_Artifact\\Artifact\\model_training\\2023-06-12-08-56-45\\trained_model\\model.pkl')
[2023-06-12 09:00:45,364] root - INFO - 
******************** Model Training started ********************


[2023-06-12 09:00:45,364] root - INFO - Finding transformed Training and Test
[2023-06-12 09:00:45,364] root - INFO - Transformed Data found!!! Now, converting it into dataframe
[2023-06-12 09:00:48,323] root - INFO - Splitting Input features and Target Feature for train and test data
[2023-06-12 09:00:48,381] root - INFO - Best Model Finder function called
[2023-06-12 09:00:48,381] root - INFO - Fitting XG_Boost...
[2023-06-12 09:03:10,004] root - ERROR - 
                        error occured in script: 
                        [C:\Users\Sumeet Maheshwari\Desktop\end to end project\Store Sales Forcasting using Time series\store-sales-forcasting\store_sales\pipeline\training_pipeline.py] at 
                        try block line number: [93] execption block line number: [98]
                        error message: [
                        error occured in script: 
                        [C:\Users\Sumeet Maheshwari\Desktop\end to end project\Store Sales Forcasting using Time series\store-sales-forcasting\store_sales\pipeline\training_pipeline.py] at 
                        try block line number: [72] execption block line number: [74]
                        error message: [
                        error occured in script: 
                        [C:\Users\Sumeet Maheshwari\Desktop\end to end project\Store Sales Forcasting using Time series\store-sales-forcasting\store_sales\components\model_trainer.py] at 
                        try block line number: [149] execption block line number: [166]
                        error message: [
All the 180 fits failed.
It is very likely that your model is misconfigured.
You can try to debug the error by setting error_score='raise'.

Below are more details about the failures:
--------------------------------------------------------------------------------
1 fits failed with the following error:
Traceback (most recent call last):
  File "C:\Users\Sumeet Maheshwari\anaconda3\lib\site-packages\sklearn\model_selection\_validation.py", line 686, in _fit_and_score
    estimator.fit(X_train, y_train, **fit_params)
  File "C:\Users\Sumeet Maheshwari\anaconda3\lib\site-packages\xgboost\sklearn.py", line 391, in fit
    self._Booster = train(params, trainDmatrix,
  File "C:\Users\Sumeet Maheshwari\anaconda3\lib\site-packages\xgboost\training.py", line 212, in train
    return _train_internal(params, dtrain,
  File "C:\Users\Sumeet Maheshwari\anaconda3\lib\site-packages\xgboost\training.py", line 74, in _train_internal
    bst.update(dtrain, i, obj)
  File "C:\Users\Sumeet Maheshwari\anaconda3\lib\site-packages\xgboost\core.py", line 1108, in update
    _check_call(_LIB.XGBoosterUpdateOneIter(self.handle, ctypes.c_int(iteration),
  File "C:\Users\Sumeet Maheshwari\anaconda3\lib\site-packages\xgboost\core.py", line 176, in _check_call
    raise XGBoostError(py_str(_LIB.XGBGetLastError()))
xgboost.core.XGBoostError: [09:00:49] C:\Jenkins\workspace\xgboost-win64_release_0.90\src\metric\metric.cc:23: Unknown metric function r2

--------------------------------------------------------------------------------
2 fits failed with the following error:
Traceback (most recent call last):
  File "C:\Users\Sumeet Maheshwari\anaconda3\lib\site-packages\sklearn\model_selection\_validation.py", line 686, in _fit_and_score
    estimator.fit(X_train, y_train, **fit_params)
  File "C:\Users\Sumeet Maheshwari\anaconda3\lib\site-packages\xgboost\sklearn.py", line 391, in fit
    self._Booster = train(params, trainDmatrix,
  File "C:\Users\Sumeet Maheshwari\anaconda3\lib\site-packages\xgboost\training.py", line 212, in train
    return _train_internal(params, dtrain,
  File "C:\Users\Sumeet Maheshwari\anaconda3\lib\site-packages\xgboost\training.py", line 74, in _train_internal
    bst.update(dtrain, i, obj)
  File "C:\Users\Sumeet Maheshwari\anaconda3\lib\site-packages\xgboost\core.py", line 1108, in update
    _check_call(_LIB.XGBoosterUpdateOneIter(self.handle, ctypes.c_int(iteration),
  File "C:\Users\Sumeet Maheshwari\anaconda3\lib\site-packages\xgboost\core.py", line 176, in _check_call
    raise XGBoostError(py_str(_LIB.XGBGetLastError()))
xgboost.core.XGBoostError: [09:00:50] C:\Jenkins\workspace\xgboost-win64_release_0.90\src\metric\metric.cc:23: Unknown metric function r2

--------------------------------------------------------------------------------
1 fits failed with the following error:
Traceback (most recent call last):
  File "C:\Users\Sumeet Maheshwari\anaconda3\lib\site-packages\sklearn\model_selection\_validation.py", line 686, in _fit_and_score
    estimator.fit(X_train, y_train, **fit_params)
  File "C:\Users\Sumeet Maheshwari\anaconda3\lib\site-packages\xgboost\sklearn.py", line 391, in fit
    self._Booster = train(params, trainDmatrix,
  File "C:\Users\Sumeet Maheshwari\anaconda3\lib\site-packages\xgboost\training.py", line 212, in train
    return _train_internal(params, dtrain,
  File "C:\Users\Sumeet Maheshwari\anaconda3\lib\site-packages\xgboost\training.py", line 74, in _train_internal
    bst.update(dtrain, i, obj)
  File "C:\Users\Sumeet Maheshwari\anaconda3\lib\site-packages\xgboost\core.py", line 1108, in update
    _check_call(_LIB.XGBoosterUpdateOneIter(self.handle, ctypes.c_int(iteration),
  File "C:\Users\Sumeet Maheshwari\anaconda3\lib\site-packages\xgboost\core.py", line 176, in _check_call
    raise XGBoostError(py_str(_LIB.XGBGetLastError()))
xgboost.core.XGBoostError: [09:00:51] C:\Jenkins\workspace\xgboost-win64_release_0.90\src\metric\metric.cc:23: Unknown metric function r2

--------------------------------------------------------------------------------
1 fits failed with the following error:
Traceback (most recent call last):
  File "C:\Users\Sumeet Maheshwari\anaconda3\lib\site-packages\sklearn\model_selection\_validation.py", line 686, in _fit_and_score
    estimator.fit(X_train, y_train, **fit_params)
  File "C:\Users\Sumeet Maheshwari\anaconda3\lib\site-packages\xgboost\sklearn.py", line 391, in fit
    self._Booster = train(params, trainDmatrix,
  File "C:\Users\Sumeet Maheshwari\anaconda3\lib\site-packages\xgboost\training.py", line 212, in train
    return _train_internal(params, dtrain,
  File "C:\Users\Sumeet Maheshwari\anaconda3\lib\site-packages\xgboost\training.py", line 74, in _train_internal
    bst.update(dtrain, i, obj)
  File "C:\Users\Sumeet Maheshwari\anaconda3\lib\site-packages\xgboost\core.py", line 1108, in update
    _check_call(_LIB.XGBoosterUpdateOneIter(self.handle, ctypes.c_int(iteration),
  File "C:\Users\Sumeet Maheshwari\anaconda3\lib\site-packages\xgboost\core.py", line 176, in _check_call
    raise XGBoostError(py_str(_LIB.XGBGetLastError()))
xgboost.core.XGBoostError: [09:00:52] C:\Jenkins\workspace\xgboost-win64_release_0.90\src\metric\metric.cc:23: Unknown metric function r2

--------------------------------------------------------------------------------
2 fits failed with the following error:
Traceback (most recent call last):
  File "C:\Users\Sumeet Maheshwari\anaconda3\lib\site-packages\sklearn\model_selection\_validation.py", line 686, in _fit_and_score
    estimator.fit(X_train, y_train, **fit_params)
  File "C:\Users\Sumeet Maheshwari\anaconda3\lib\site-packages\xgboost\sklearn.py", line 391, in fit
    self._Booster = train(params, trainDmatrix,
  File "C:\Users\Sumeet Maheshwari\anaconda3\lib\site-packages\xgboost\training.py", line 212, in train
    return _train_internal(params, dtrain,
  File "C:\Users\Sumeet Maheshwari\anaconda3\lib\site-packages\xgboost\training.py", line 74, in _train_internal
    bst.update(dtrain, i, obj)
  File "C:\Users\Sumeet Maheshwari\anaconda3\lib\site-packages\xgboost\core.py", line 1108, in update
    _check_call(_LIB.XGBoosterUpdateOneIter(self.handle, ctypes.c_int(iteration),
  File "C:\Users\Sumeet Maheshwari\anaconda3\lib\site-packages\xgboost\core.py", line 176, in _check_call
    raise XGBoostError(py_str(_LIB.XGBGetLastError()))
xgboost.core.XGBoostError: [09:00:53] C:\Jenkins\workspace\xgboost-win64_release_0.90\src\metric\metric.cc:23: Unknown metric function r2

--------------------------------------------------------------------------------
1 fits failed with the following error:
Traceback (most recent call last):
  File "C:\Users\Sumeet Maheshwari\anaconda3\lib\site-packages\sklearn\model_selection\_validation.py", line 686, in _fit_and_score
    estimator.fit(X_train, y_train, **fit_params)
  File "C:\Users\Sumeet Maheshwari\anaconda3\lib\site-packages\xgboost\sklearn.py", line 391, in fit
    self._Booster = train(params, trainDmatrix,
  File "C:\Users\Sumeet Maheshwari\anaconda3\lib\site-packages\xgboost\training.py", line 212, in train
    return _train_internal(params, dtrain,
  File "C:\Users\Sumeet Maheshwari\anaconda3\lib\site-packages\xgboost\training.py", line 74, in _train_internal
    bst.update(dtrain, i, obj)
  File "C:\Users\Sumeet Maheshwari\anaconda3\lib\site-packages\xgboost\core.py", line 1108, in update
    _check_call(_LIB.XGBoosterUpdateOneIter(self.handle, ctypes.c_int(iteration),
  File "C:\Users\Sumeet Maheshwari\anaconda3\lib\site-packages\xgboost\core.py", line 176, in _check_call
    raise XGBoostError(py_str(_LIB.XGBGetLastError()))
xgboost.core.XGBoostError: [09:00:54] C:\Jenkins\workspace\xgboost-win64_release_0.90\src\metric\metric.cc:23: Unknown metric function r2

--------------------------------------------------------------------------------
1 fits failed with the following error:
Traceback (most recent call last):
  File "C:\Users\Sumeet Maheshwari\anaconda3\lib\site-packages\sklearn\model_selection\_validation.py", line 686, in _fit_and_score
    estimator.fit(X_train, y_train, **fit_params)
  File "C:\Users\Sumeet Maheshwari\anaconda3\lib\site-packages\xgboost\sklearn.py", line 391, in fit
    self._Booster = train(params, trainDmatrix,
  File "C:\Users\Sumeet Maheshwari\anaconda3\lib\site-packages\xgboost\training.py", line 212, in train
    return _train_internal(params, dtrain,
  File "C:\Users\Sumeet Maheshwari\anaconda3\lib\site-packages\xgboost\training.py", line 74, in _train_internal
    bst.update(dtrain, i, obj)
  File "C:\Users\Sumeet Maheshwari\anaconda3\lib\site-packages\xgboost\core.py", line 1108, in update
    _check_call(_LIB.XGBoosterUpdateOneIter(self.handle, ctypes.c_int(iteration),
  File "C:\Users\Sumeet Maheshwari\anaconda3\lib\site-packages\xgboost\core.py", line 176, in _check_call
    raise XGBoostError(py_str(_LIB.XGBGetLastError()))
xgboost.core.XGBoostError: [09:00:55] C:\Jenkins\workspace\xgboost-win64_release_0.90\src\metric\metric.cc:23: Unknown metric function r2

--------------------------------------------------------------------------------
1 fits failed with the following error:
Traceback (most recent call last):
  File "C:\Users\Sumeet Maheshwari\anaconda3\lib\site-packages\sklearn\model_selection\_validation.py", line 686, in _fit_and_score
    estimator.fit(X_train, y_train, **fit_params)
  File "C:\Users\Sumeet Maheshwari\anaconda3\lib\site-packages\xgboost\sklearn.py", line 391, in fit
    self._Booster = train(params, trainDmatrix,
  File "C:\Users\Sumeet Maheshwari\anaconda3\lib\site-packages\xgboost\training.py", line 212, in train
    return _train_internal(params, dtrain,
  File "C:\Users\Sumeet Maheshwari\anaconda3\lib\site-packages\xgboost\training.py", line 74, in _train_internal
    bst.update(dtrain, i, obj)
  File "C:\Users\Sumeet Maheshwari\anaconda3\lib\site-packages\xgboost\core.py", line 1108, in update
    _check_call(_LIB.XGBoosterUpdateOneIter(self.handle, ctypes.c_int(iteration),
  File "C:\Users\Sumeet Maheshwari\anaconda3\lib\site-packages\xgboost\core.py", line 176, in _check_call
    raise XGBoostError(py_str(_LIB.XGBGetLastError()))
xgboost.core.XGBoostError: [09:00:56] C:\Jenkins\workspace\xgboost-win64_release_0.90\src\metric\metric.cc:23: Unknown metric function r2

--------------------------------------------------------------------------------
1 fits failed with the following error:
Traceback (most recent call last):
  File "C:\Users\Sumeet Maheshwari\anaconda3\lib\site-packages\sklearn\model_selection\_validation.py", line 686, in _fit_and_score
    estimator.fit(X_train, y_train, **fit_params)
  File "C:\Users\Sumeet Maheshwari\anaconda3\lib\site-packages\xgboost\sklearn.py", line 391, in fit
    self._Booster = train(params, trainDmatrix,
  File "C:\Users\Sumeet Maheshwari\anaconda3\lib\site-packages\xgboost\training.py", line 212, in train
    return _train_internal(params, dtrain,
  File "C:\Users\Sumeet Maheshwari\anaconda3\lib\site-packages\xgboost\training.py", line 74, in _train_internal
    bst.update(dtrain, i, obj)
  File "C:\Users\Sumeet Maheshwari\anaconda3\lib\site-packages\xgboost\core.py", line 1108, in update
    _check_call(_LIB.XGBoosterUpdateOneIter(self.handle, ctypes.c_int(iteration),
  File "C:\Users\Sumeet Maheshwari\anaconda3\lib\site-packages\xgboost\core.py", line 176, in _check_call
    raise XGBoostError(py_str(_LIB.XGBGetLastError()))
xgboost.core.XGBoostError: [09:00:57] C:\Jenkins\workspace\xgboost-win64_release_0.90\src\metric\metric.cc:23: Unknown metric function r2

--------------------------------------------------------------------------------
1 fits failed with the following error:
Traceback (most recent call last):
  File "C:\Users\Sumeet Maheshwari\anaconda3\lib\site-packages\sklearn\model_selection\_validation.py", line 686, in _fit_and_score
    estimator.fit(X_train, y_train, **fit_params)
  File "C:\Users\Sumeet Maheshwari\anaconda3\lib\site-packages\xgboost\sklearn.py", line 391, in fit
    self._Booster = train(params, trainDmatrix,
  File "C:\Users\Sumeet Maheshwari\anaconda3\lib\site-packages\xgboost\training.py", line 212, in train
    return _train_internal(params, dtrain,
  File "C:\Users\Sumeet Maheshwari\anaconda3\lib\site-packages\xgboost\training.py", line 74, in _train_internal
    bst.update(dtrain, i, obj)
  File "C:\Users\Sumeet Maheshwari\anaconda3\lib\site-packages\xgboost\core.py", line 1108, in update
    _check_call(_LIB.XGBoosterUpdateOneIter(self.handle, ctypes.c_int(iteration),
  File "C:\Users\Sumeet Maheshwari\anaconda3\lib\site-packages\xgboost\core.py", line 176, in _check_call
    raise XGBoostError(py_str(_LIB.XGBGetLastError()))
xgboost.core.XGBoostError: [09:00:58] C:\Jenkins\workspace\xgboost-win64_release_0.90\src\metric\metric.cc:23: Unknown metric function r2

--------------------------------------------------------------------------------
2 fits failed with the following error:
Traceback (most recent call last):
  File "C:\Users\Sumeet Maheshwari\anaconda3\lib\site-packages\sklearn\model_selection\_validation.py", line 686, in _fit_and_score
    estimator.fit(X_train, y_train, **fit_params)
  File "C:\Users\Sumeet Maheshwari\anaconda3\lib\site-packages\xgboost\sklearn.py", line 391, in fit
    self._Booster = train(params, trainDmatrix,
  File "C:\Users\Sumeet Maheshwari\anaconda3\lib\site-packages\xgboost\training.py", line 212, in train
    return _train_internal(params, dtrain,
  File "C:\Users\Sumeet Maheshwari\anaconda3\lib\site-packages\xgboost\training.py", line 74, in _train_internal
    bst.update(dtrain, i, obj)
  File "C:\Users\Sumeet Maheshwari\anaconda3\lib\site-packages\xgboost\core.py", line 1108, in update
    _check_call(_LIB.XGBoosterUpdateOneIter(self.handle, ctypes.c_int(iteration),
  File "C:\Users\Sumeet Maheshwari\anaconda3\lib\site-packages\xgboost\core.py", line 176, in _check_call
    raise XGBoostError(py_str(_LIB.XGBGetLastError()))
xgboost.core.XGBoostError: [09:00:59] C:\Jenkins\workspace\xgboost-win64_release_0.90\src\metric\metric.cc:23: Unknown metric function r2

--------------------------------------------------------------------------------
1 fits failed with the following error:
Traceback (most recent call last):
  File "C:\Users\Sumeet Maheshwari\anaconda3\lib\site-packages\sklearn\model_selection\_validation.py", line 686, in _fit_and_score
    estimator.fit(X_train, y_train, **fit_params)
  File "C:\Users\Sumeet Maheshwari\anaconda3\lib\site-packages\xgboost\sklearn.py", line 391, in fit
    self._Booster = train(params, trainDmatrix,
  File "C:\Users\Sumeet Maheshwari\anaconda3\lib\site-packages\xgboost\training.py", line 212, in train
    return _train_internal(params, dtrain,
  File "C:\Users\Sumeet Maheshwari\anaconda3\lib\site-packages\xgboost\training.py", line 74, in _train_internal
    bst.update(dtrain, i, obj)
  File "C:\Users\Sumeet Maheshwari\anaconda3\lib\site-packages\xgboost\core.py", line 1108, in update
    _check_call(_LIB.XGBoosterUpdateOneIter(self.handle, ctypes.c_int(iteration),
  File "C:\Users\Sumeet Maheshwari\anaconda3\lib\site-packages\xgboost\core.py", line 176, in _check_call
    raise XGBoostError(py_str(_LIB.XGBGetLastError()))
xgboost.core.XGBoostError: [09:01:00] C:\Jenkins\workspace\xgboost-win64_release_0.90\src\metric\metric.cc:23: Unknown metric function r2

--------------------------------------------------------------------------------
1 fits failed with the following error:
Traceback (most recent call last):
  File "C:\Users\Sumeet Maheshwari\anaconda3\lib\site-packages\sklearn\model_selection\_validation.py", line 686, in _fit_and_score
    estimator.fit(X_train, y_train, **fit_params)
  File "C:\Users\Sumeet Maheshwari\anaconda3\lib\site-packages\xgboost\sklearn.py", line 391, in fit
    self._Booster = train(params, trainDmatrix,
  File "C:\Users\Sumeet Maheshwari\anaconda3\lib\site-packages\xgboost\training.py", line 212, in train
    return _train_internal(params, dtrain,
  File "C:\Users\Sumeet Maheshwari\anaconda3\lib\site-packages\xgboost\training.py", line 74, in _train_internal
    bst.update(dtrain, i, obj)
  File "C:\Users\Sumeet Maheshwari\anaconda3\lib\site-packages\xgboost\core.py", line 1108, in update
    _check_call(_LIB.XGBoosterUpdateOneIter(self.handle, ctypes.c_int(iteration),
  File "C:\Users\Sumeet Maheshwari\anaconda3\lib\site-packages\xgboost\core.py", line 176, in _check_call
    raise XGBoostError(py_str(_LIB.XGBGetLastError()))
xgboost.core.XGBoostError: [09:01:01] C:\Jenkins\workspace\xgboost-win64_release_0.90\src\metric\metric.cc:23: Unknown metric function r2

--------------------------------------------------------------------------------
1 fits failed with the following error:
Traceback (most recent call last):
  File "C:\Users\Sumeet Maheshwari\anaconda3\lib\site-packages\sklearn\model_selection\_validation.py", line 686, in _fit_and_score
    estimator.fit(X_train, y_train, **fit_params)
  File "C:\Users\Sumeet Maheshwari\anaconda3\lib\site-packages\xgboost\sklearn.py", line 391, in fit
    self._Booster = train(params, trainDmatrix,
  File "C:\Users\Sumeet Maheshwari\anaconda3\lib\site-packages\xgboost\training.py", line 212, in train
    return _train_internal(params, dtrain,
  File "C:\Users\Sumeet Maheshwari\anaconda3\lib\site-packages\xgboost\training.py", line 74, in _train_internal
    bst.update(dtrain, i, obj)
  File "C:\Users\Sumeet Maheshwari\anaconda3\lib\site-packages\xgboost\core.py", line 1108, in update
    _check_call(_LIB.XGBoosterUpdateOneIter(self.handle, ctypes.c_int(iteration),
  File "C:\Users\Sumeet Maheshwari\anaconda3\lib\site-packages\xgboost\core.py", line 176, in _check_call
    raise XGBoostError(py_str(_LIB.XGBGetLastError()))
xgboost.core.XGBoostError: [09:01:02] C:\Jenkins\workspace\xgboost-win64_release_0.90\src\metric\metric.cc:23: Unknown metric function r2

--------------------------------------------------------------------------------
1 fits failed with the following error:
Traceback (most recent call last):
  File "C:\Users\Sumeet Maheshwari\anaconda3\lib\site-packages\sklearn\model_selection\_validation.py", line 686, in _fit_and_score
    estimator.fit(X_train, y_train, **fit_params)
  File "C:\Users\Sumeet Maheshwari\anaconda3\lib\site-packages\xgboost\sklearn.py", line 391, in fit
    self._Booster = train(params, trainDmatrix,
  File "C:\Users\Sumeet Maheshwari\anaconda3\lib\site-packages\xgboost\training.py", line 212, in train
    return _train_internal(params, dtrain,
  File "C:\Users\Sumeet Maheshwari\anaconda3\lib\site-packages\xgboost\training.py", line 74, in _train_internal
    bst.update(dtrain, i, obj)
  File "C:\Users\Sumeet Maheshwari\anaconda3\lib\site-packages\xgboost\core.py", line 1108, in update
    _check_call(_LIB.XGBoosterUpdateOneIter(self.handle, ctypes.c_int(iteration),
  File "C:\Users\Sumeet Maheshwari\anaconda3\lib\site-packages\xgboost\core.py", line 176, in _check_call
    raise XGBoostError(py_str(_LIB.XGBGetLastError()))
xgboost.core.XGBoostError: [09:01:03] C:\Jenkins\workspace\xgboost-win64_release_0.90\src\metric\metric.cc:23: Unknown metric function r2

--------------------------------------------------------------------------------
2 fits failed with the following error:
Traceback (most recent call last):
  File "C:\Users\Sumeet Maheshwari\anaconda3\lib\site-packages\sklearn\model_selection\_validation.py", line 686, in _fit_and_score
    estimator.fit(X_train, y_train, **fit_params)
  File "C:\Users\Sumeet Maheshwari\anaconda3\lib\site-packages\xgboost\sklearn.py", line 391, in fit
    self._Booster = train(params, trainDmatrix,
  File "C:\Users\Sumeet Maheshwari\anaconda3\lib\site-packages\xgboost\training.py", line 212, in train
    return _train_internal(params, dtrain,
  File "C:\Users\Sumeet Maheshwari\anaconda3\lib\site-packages\xgboost\training.py", line 74, in _train_internal
    bst.update(dtrain, i, obj)
  File "C:\Users\Sumeet Maheshwari\anaconda3\lib\site-packages\xgboost\core.py", line 1108, in update
    _check_call(_LIB.XGBoosterUpdateOneIter(self.handle, ctypes.c_int(iteration),
  File "C:\Users\Sumeet Maheshwari\anaconda3\lib\site-packages\xgboost\core.py", line 176, in _check_call
    raise XGBoostError(py_str(_LIB.XGBGetLastError()))
xgboost.core.XGBoostError: [09:01:04] C:\Jenkins\workspace\xgboost-win64_release_0.90\src\metric\metric.cc:23: Unknown metric function r2

--------------------------------------------------------------------------------
1 fits failed with the following error:
Traceback (most recent call last):
  File "C:\Users\Sumeet Maheshwari\anaconda3\lib\site-packages\sklearn\model_selection\_validation.py", line 686, in _fit_and_score
    estimator.fit(X_train, y_train, **fit_params)
  File "C:\Users\Sumeet Maheshwari\anaconda3\lib\site-packages\xgboost\sklearn.py", line 391, in fit
    self._Booster = train(params, trainDmatrix,
  File "C:\Users\Sumeet Maheshwari\anaconda3\lib\site-packages\xgboost\training.py", line 212, in train
    return _train_internal(params, dtrain,
  File "C:\Users\Sumeet Maheshwari\anaconda3\lib\site-packages\xgboost\training.py", line 74, in _train_internal
    bst.update(dtrain, i, obj)
  File "C:\Users\Sumeet Maheshwari\anaconda3\lib\site-packages\xgboost\core.py", line 1108, in update
    _check_call(_LIB.XGBoosterUpdateOneIter(self.handle, ctypes.c_int(iteration),
  File "C:\Users\Sumeet Maheshwari\anaconda3\lib\site-packages\xgboost\core.py", line 176, in _check_call
    raise XGBoostError(py_str(_LIB.XGBGetLastError()))
xgboost.core.XGBoostError: [09:01:05] C:\Jenkins\workspace\xgboost-win64_release_0.90\src\metric\metric.cc:23: Unknown metric function r2

--------------------------------------------------------------------------------
1 fits failed with the following error:
Traceback (most recent call last):
  File "C:\Users\Sumeet Maheshwari\anaconda3\lib\site-packages\sklearn\model_selection\_validation.py", line 686, in _fit_and_score
    estimator.fit(X_train, y_train, **fit_params)
  File "C:\Users\Sumeet Maheshwari\anaconda3\lib\site-packages\xgboost\sklearn.py", line 391, in fit
    self._Booster = train(params, trainDmatrix,
  File "C:\Users\Sumeet Maheshwari\anaconda3\lib\site-packages\xgboost\training.py", line 212, in train
    return _train_internal(params, dtrain,
  File "C:\Users\Sumeet Maheshwari\anaconda3\lib\site-packages\xgboost\training.py", line 74, in _train_internal
    bst.update(dtrain, i, obj)
  File "C:\Users\Sumeet Maheshwari\anaconda3\lib\site-packages\xgboost\core.py", line 1108, in update
    _check_call(_LIB.XGBoosterUpdateOneIter(self.handle, ctypes.c_int(iteration),
  File "C:\Users\Sumeet Maheshwari\anaconda3\lib\site-packages\xgboost\core.py", line 176, in _check_call
    raise XGBoostError(py_str(_LIB.XGBGetLastError()))
xgboost.core.XGBoostError: [09:01:06] C:\Jenkins\workspace\xgboost-win64_release_0.90\src\metric\metric.cc:23: Unknown metric function r2

--------------------------------------------------------------------------------
1 fits failed with the following error:
Traceback (most recent call last):
  File "C:\Users\Sumeet Maheshwari\anaconda3\lib\site-packages\sklearn\model_selection\_validation.py", line 686, in _fit_and_score
    estimator.fit(X_train, y_train, **fit_params)
  File "C:\Users\Sumeet Maheshwari\anaconda3\lib\site-packages\xgboost\sklearn.py", line 391, in fit
    self._Booster = train(params, trainDmatrix,
  File "C:\Users\Sumeet Maheshwari\anaconda3\lib\site-packages\xgboost\training.py", line 212, in train
    return _train_internal(params, dtrain,
  File "C:\Users\Sumeet Maheshwari\anaconda3\lib\site-packages\xgboost\training.py", line 74, in _train_internal
    bst.update(dtrain, i, obj)
  File "C:\Users\Sumeet Maheshwari\anaconda3\lib\site-packages\xgboost\core.py", line 1108, in update
    _check_call(_LIB.XGBoosterUpdateOneIter(self.handle, ctypes.c_int(iteration),
  File "C:\Users\Sumeet Maheshwari\anaconda3\lib\site-packages\xgboost\core.py", line 176, in _check_call
    raise XGBoostError(py_str(_LIB.XGBGetLastError()))
xgboost.core.XGBoostError: [09:01:07] C:\Jenkins\workspace\xgboost-win64_release_0.90\src\metric\metric.cc:23: Unknown metric function r2

--------------------------------------------------------------------------------
2 fits failed with the following error:
Traceback (most recent call last):
  File "C:\Users\Sumeet Maheshwari\anaconda3\lib\site-packages\sklearn\model_selection\_validation.py", line 686, in _fit_and_score
    estimator.fit(X_train, y_train, **fit_params)
  File "C:\Users\Sumeet Maheshwari\anaconda3\lib\site-packages\xgboost\sklearn.py", line 391, in fit
    self._Booster = train(params, trainDmatrix,
  File "C:\Users\Sumeet Maheshwari\anaconda3\lib\site-packages\xgboost\training.py", line 212, in train
    return _train_internal(params, dtrain,
  File "C:\Users\Sumeet Maheshwari\anaconda3\lib\site-packages\xgboost\training.py", line 74, in _train_internal
    bst.update(dtrain, i, obj)
  File "C:\Users\Sumeet Maheshwari\anaconda3\lib\site-packages\xgboost\core.py", line 1108, in update
    _check_call(_LIB.XGBoosterUpdateOneIter(self.handle, ctypes.c_int(iteration),
  File "C:\Users\Sumeet Maheshwari\anaconda3\lib\site-packages\xgboost\core.py", line 176, in _check_call
    raise XGBoostError(py_str(_LIB.XGBGetLastError()))
xgboost.core.XGBoostError: [09:01:08] C:\Jenkins\workspace\xgboost-win64_release_0.90\src\metric\metric.cc:23: Unknown metric function r2

--------------------------------------------------------------------------------
1 fits failed with the following error:
Traceback (most recent call last):
  File "C:\Users\Sumeet Maheshwari\anaconda3\lib\site-packages\sklearn\model_selection\_validation.py", line 686, in _fit_and_score
    estimator.fit(X_train, y_train, **fit_params)
  File "C:\Users\Sumeet Maheshwari\anaconda3\lib\site-packages\xgboost\sklearn.py", line 391, in fit
    self._Booster = train(params, trainDmatrix,
  File "C:\Users\Sumeet Maheshwari\anaconda3\lib\site-packages\xgboost\training.py", line 212, in train
    return _train_internal(params, dtrain,
  File "C:\Users\Sumeet Maheshwari\anaconda3\lib\site-packages\xgboost\training.py", line 74, in _train_internal
    bst.update(dtrain, i, obj)
  File "C:\Users\Sumeet Maheshwari\anaconda3\lib\site-packages\xgboost\core.py", line 1108, in update
    _check_call(_LIB.XGBoosterUpdateOneIter(self.handle, ctypes.c_int(iteration),
  File "C:\Users\Sumeet Maheshwari\anaconda3\lib\site-packages\xgboost\core.py", line 176, in _check_call
    raise XGBoostError(py_str(_LIB.XGBGetLastError()))
xgboost.core.XGBoostError: [09:01:09] C:\Jenkins\workspace\xgboost-win64_release_0.90\src\metric\metric.cc:23: Unknown metric function r2

--------------------------------------------------------------------------------
1 fits failed with the following error:
Traceback (most recent call last):
  File "C:\Users\Sumeet Maheshwari\anaconda3\lib\site-packages\sklearn\model_selection\_validation.py", line 686, in _fit_and_score
    estimator.fit(X_train, y_train, **fit_params)
  File "C:\Users\Sumeet Maheshwari\anaconda3\lib\site-packages\xgboost\sklearn.py", line 391, in fit
    self._Booster = train(params, trainDmatrix,
  File "C:\Users\Sumeet Maheshwari\anaconda3\lib\site-packages\xgboost\training.py", line 212, in train
    return _train_internal(params, dtrain,
  File "C:\Users\Sumeet Maheshwari\anaconda3\lib\site-packages\xgboost\training.py", line 74, in _train_internal
    bst.update(dtrain, i, obj)
  File "C:\Users\Sumeet Maheshwari\anaconda3\lib\site-packages\xgboost\core.py", line 1108, in update
    _check_call(_LIB.XGBoosterUpdateOneIter(self.handle, ctypes.c_int(iteration),
  File "C:\Users\Sumeet Maheshwari\anaconda3\lib\site-packages\xgboost\core.py", line 176, in _check_call
    raise XGBoostError(py_str(_LIB.XGBGetLastError()))
xgboost.core.XGBoostError: [09:01:10] C:\Jenkins\workspace\xgboost-win64_release_0.90\src\metric\metric.cc:23: Unknown metric function r2

--------------------------------------------------------------------------------
2 fits failed with the following error:
Traceback (most recent call last):
  File "C:\Users\Sumeet Maheshwari\anaconda3\lib\site-packages\sklearn\model_selection\_validation.py", line 686, in _fit_and_score
    estimator.fit(X_train, y_train, **fit_params)
  File "C:\Users\Sumeet Maheshwari\anaconda3\lib\site-packages\xgboost\sklearn.py", line 391, in fit
    self._Booster = train(params, trainDmatrix,
  File "C:\Users\Sumeet Maheshwari\anaconda3\lib\site-packages\xgboost\training.py", line 212, in train
    return _train_internal(params, dtrain,
  File "C:\Users\Sumeet Maheshwari\anaconda3\lib\site-packages\xgboost\training.py", line 74, in _train_internal
    bst.update(dtrain, i, obj)
  File "C:\Users\Sumeet Maheshwari\anaconda3\lib\site-packages\xgboost\core.py", line 1108, in update
    _check_call(_LIB.XGBoosterUpdateOneIter(self.handle, ctypes.c_int(iteration),
  File "C:\Users\Sumeet Maheshwari\anaconda3\lib\site-packages\xgboost\core.py", line 176, in _check_call
    raise XGBoostError(py_str(_LIB.XGBGetLastError()))
xgboost.core.XGBoostError: [09:01:11] C:\Jenkins\workspace\xgboost-win64_release_0.90\src\metric\metric.cc:23: Unknown metric function r2

--------------------------------------------------------------------------------
1 fits failed with the following error:
Traceback (most recent call last):
  File "C:\Users\Sumeet Maheshwari\anaconda3\lib\site-packages\sklearn\model_selection\_validation.py", line 686, in _fit_and_score
    estimator.fit(X_train, y_train, **fit_params)
  File "C:\Users\Sumeet Maheshwari\anaconda3\lib\site-packages\xgboost\sklearn.py", line 391, in fit
    self._Booster = train(params, trainDmatrix,
  File "C:\Users\Sumeet Maheshwari\anaconda3\lib\site-packages\xgboost\training.py", line 212, in train
    return _train_internal(params, dtrain,
  File "C:\Users\Sumeet Maheshwari\anaconda3\lib\site-packages\xgboost\training.py", line 74, in _train_internal
    bst.update(dtrain, i, obj)
  File "C:\Users\Sumeet Maheshwari\anaconda3\lib\site-packages\xgboost\core.py", line 1108, in update
    _check_call(_LIB.XGBoosterUpdateOneIter(self.handle, ctypes.c_int(iteration),
  File "C:\Users\Sumeet Maheshwari\anaconda3\lib\site-packages\xgboost\core.py", line 176, in _check_call
    raise XGBoostError(py_str(_LIB.XGBGetLastError()))
xgboost.core.XGBoostError: [09:01:12] C:\Jenkins\workspace\xgboost-win64_release_0.90\src\metric\metric.cc:23: Unknown metric function r2

--------------------------------------------------------------------------------
1 fits failed with the following error:
Traceback (most recent call last):
  File "C:\Users\Sumeet Maheshwari\anaconda3\lib\site-packages\sklearn\model_selection\_validation.py", line 686, in _fit_and_score
    estimator.fit(X_train, y_train, **fit_params)
  File "C:\Users\Sumeet Maheshwari\anaconda3\lib\site-packages\xgboost\sklearn.py", line 391, in fit
    self._Booster = train(params, trainDmatrix,
  File "C:\Users\Sumeet Maheshwari\anaconda3\lib\site-packages\xgboost\training.py", line 212, in train
    return _train_internal(params, dtrain,
  File "C:\Users\Sumeet Maheshwari\anaconda3\lib\site-packages\xgboost\training.py", line 74, in _train_internal
    bst.update(dtrain, i, obj)
  File "C:\Users\Sumeet Maheshwari\anaconda3\lib\site-packages\xgboost\core.py", line 1108, in update
    _check_call(_LIB.XGBoosterUpdateOneIter(self.handle, ctypes.c_int(iteration),
  File "C:\Users\Sumeet Maheshwari\anaconda3\lib\site-packages\xgboost\core.py", line 176, in _check_call
    raise XGBoostError(py_str(_LIB.XGBGetLastError()))
xgboost.core.XGBoostError: [09:01:13] C:\Jenkins\workspace\xgboost-win64_release_0.90\src\metric\metric.cc:23: Unknown metric function r2

--------------------------------------------------------------------------------
2 fits failed with the following error:
Traceback (most recent call last):
  File "C:\Users\Sumeet Maheshwari\anaconda3\lib\site-packages\sklearn\model_selection\_validation.py", line 686, in _fit_and_score
    estimator.fit(X_train, y_train, **fit_params)
  File "C:\Users\Sumeet Maheshwari\anaconda3\lib\site-packages\xgboost\sklearn.py", line 391, in fit
    self._Booster = train(params, trainDmatrix,
  File "C:\Users\Sumeet Maheshwari\anaconda3\lib\site-packages\xgboost\training.py", line 212, in train
    return _train_internal(params, dtrain,
  File "C:\Users\Sumeet Maheshwari\anaconda3\lib\site-packages\xgboost\training.py", line 74, in _train_internal
    bst.update(dtrain, i, obj)
  File "C:\Users\Sumeet Maheshwari\anaconda3\lib\site-packages\xgboost\core.py", line 1108, in update
    _check_call(_LIB.XGBoosterUpdateOneIter(self.handle, ctypes.c_int(iteration),
  File "C:\Users\Sumeet Maheshwari\anaconda3\lib\site-packages\xgboost\core.py", line 176, in _check_call
    raise XGBoostError(py_str(_LIB.XGBGetLastError()))
xgboost.core.XGBoostError: [09:01:14] C:\Jenkins\workspace\xgboost-win64_release_0.90\src\metric\metric.cc:23: Unknown metric function r2

--------------------------------------------------------------------------------
1 fits failed with the following error:
Traceback (most recent call last):
  File "C:\Users\Sumeet Maheshwari\anaconda3\lib\site-packages\sklearn\model_selection\_validation.py", line 686, in _fit_and_score
    estimator.fit(X_train, y_train, **fit_params)
  File "C:\Users\Sumeet Maheshwari\anaconda3\lib\site-packages\xgboost\sklearn.py", line 391, in fit
    self._Booster = train(params, trainDmatrix,
  File "C:\Users\Sumeet Maheshwari\anaconda3\lib\site-packages\xgboost\training.py", line 212, in train
    return _train_internal(params, dtrain,
  File "C:\Users\Sumeet Maheshwari\anaconda3\lib\site-packages\xgboost\training.py", line 74, in _train_internal
    bst.update(dtrain, i, obj)
  File "C:\Users\Sumeet Maheshwari\anaconda3\lib\site-packages\xgboost\core.py", line 1108, in update
    _check_call(_LIB.XGBoosterUpdateOneIter(self.handle, ctypes.c_int(iteration),
  File "C:\Users\Sumeet Maheshwari\anaconda3\lib\site-packages\xgboost\core.py", line 176, in _check_call
    raise XGBoostError(py_str(_LIB.XGBGetLastError()))
xgboost.core.XGBoostError: [09:01:15] C:\Jenkins\workspace\xgboost-win64_release_0.90\src\metric\metric.cc:23: Unknown metric function r2

--------------------------------------------------------------------------------
1 fits failed with the following error:
Traceback (most recent call last):
  File "C:\Users\Sumeet Maheshwari\anaconda3\lib\site-packages\sklearn\model_selection\_validation.py", line 686, in _fit_and_score
    estimator.fit(X_train, y_train, **fit_params)
  File "C:\Users\Sumeet Maheshwari\anaconda3\lib\site-packages\xgboost\sklearn.py", line 391, in fit
    self._Booster = train(params, trainDmatrix,
  File "C:\Users\Sumeet Maheshwari\anaconda3\lib\site-packages\xgboost\training.py", line 212, in train
    return _train_internal(params, dtrain,
  File "C:\Users\Sumeet Maheshwari\anaconda3\lib\site-packages\xgboost\training.py", line 74, in _train_internal
    bst.update(dtrain, i, obj)
  File "C:\Users\Sumeet Maheshwari\anaconda3\lib\site-packages\xgboost\core.py", line 1108, in update
    _check_call(_LIB.XGBoosterUpdateOneIter(self.handle, ctypes.c_int(iteration),
  File "C:\Users\Sumeet Maheshwari\anaconda3\lib\site-packages\xgboost\core.py", line 176, in _check_call
    raise XGBoostError(py_str(_LIB.XGBGetLastError()))
xgboost.core.XGBoostError: [09:01:16] C:\Jenkins\workspace\xgboost-win64_release_0.90\src\metric\metric.cc:23: Unknown metric function r2

--------------------------------------------------------------------------------
1 fits failed with the following error:
Traceback (most recent call last):
  File "C:\Users\Sumeet Maheshwari\anaconda3\lib\site-packages\sklearn\model_selection\_validation.py", line 686, in _fit_and_score
    estimator.fit(X_train, y_train, **fit_params)
  File "C:\Users\Sumeet Maheshwari\anaconda3\lib\site-packages\xgboost\sklearn.py", line 391, in fit
    self._Booster = train(params, trainDmatrix,
  File "C:\Users\Sumeet Maheshwari\anaconda3\lib\site-packages\xgboost\training.py", line 212, in train
    return _train_internal(params, dtrain,
  File "C:\Users\Sumeet Maheshwari\anaconda3\lib\site-packages\xgboost\training.py", line 74, in _train_internal
    bst.update(dtrain, i, obj)
  File "C:\Users\Sumeet Maheshwari\anaconda3\lib\site-packages\xgboost\core.py", line 1108, in update
    _check_call(_LIB.XGBoosterUpdateOneIter(self.handle, ctypes.c_int(iteration),
  File "C:\Users\Sumeet Maheshwari\anaconda3\lib\site-packages\xgboost\core.py", line 176, in _check_call
    raise XGBoostError(py_str(_LIB.XGBGetLastError()))
xgboost.core.XGBoostError: [09:01:17] C:\Jenkins\workspace\xgboost-win64_release_0.90\src\metric\metric.cc:23: Unknown metric function r2

--------------------------------------------------------------------------------
2 fits failed with the following error:
Traceback (most recent call last):
  File "C:\Users\Sumeet Maheshwari\anaconda3\lib\site-packages\sklearn\model_selection\_validation.py", line 686, in _fit_and_score
    estimator.fit(X_train, y_train, **fit_params)
  File "C:\Users\Sumeet Maheshwari\anaconda3\lib\site-packages\xgboost\sklearn.py", line 391, in fit
    self._Booster = train(params, trainDmatrix,
  File "C:\Users\Sumeet Maheshwari\anaconda3\lib\site-packages\xgboost\training.py", line 212, in train
    return _train_internal(params, dtrain,
  File "C:\Users\Sumeet Maheshwari\anaconda3\lib\site-packages\xgboost\training.py", line 74, in _train_internal
    bst.update(dtrain, i, obj)
  File "C:\Users\Sumeet Maheshwari\anaconda3\lib\site-packages\xgboost\core.py", line 1108, in update
    _check_call(_LIB.XGBoosterUpdateOneIter(self.handle, ctypes.c_int(iteration),
  File "C:\Users\Sumeet Maheshwari\anaconda3\lib\site-packages\xgboost\core.py", line 176, in _check_call
    raise XGBoostError(py_str(_LIB.XGBGetLastError()))
xgboost.core.XGBoostError: [09:01:18] C:\Jenkins\workspace\xgboost-win64_release_0.90\src\metric\metric.cc:23: Unknown metric function r2

--------------------------------------------------------------------------------
1 fits failed with the following error:
Traceback (most recent call last):
  File "C:\Users\Sumeet Maheshwari\anaconda3\lib\site-packages\sklearn\model_selection\_validation.py", line 686, in _fit_and_score
    estimator.fit(X_train, y_train, **fit_params)
  File "C:\Users\Sumeet Maheshwari\anaconda3\lib\site-packages\xgboost\sklearn.py", line 391, in fit
    self._Booster = train(params, trainDmatrix,
  File "C:\Users\Sumeet Maheshwari\anaconda3\lib\site-packages\xgboost\training.py", line 212, in train
    return _train_internal(params, dtrain,
  File "C:\Users\Sumeet Maheshwari\anaconda3\lib\site-packages\xgboost\training.py", line 74, in _train_internal
    bst.update(dtrain, i, obj)
  File "C:\Users\Sumeet Maheshwari\anaconda3\lib\site-packages\xgboost\core.py", line 1108, in update
    _check_call(_LIB.XGBoosterUpdateOneIter(self.handle, ctypes.c_int(iteration),
  File "C:\Users\Sumeet Maheshwari\anaconda3\lib\site-packages\xgboost\core.py", line 176, in _check_call
    raise XGBoostError(py_str(_LIB.XGBGetLastError()))
xgboost.core.XGBoostError: [09:01:19] C:\Jenkins\workspace\xgboost-win64_release_0.90\src\metric\metric.cc:23: Unknown metric function r2

--------------------------------------------------------------------------------
1 fits failed with the following error:
Traceback (most recent call last):
  File "C:\Users\Sumeet Maheshwari\anaconda3\lib\site-packages\sklearn\model_selection\_validation.py", line 686, in _fit_and_score
    estimator.fit(X_train, y_train, **fit_params)
  File "C:\Users\Sumeet Maheshwari\anaconda3\lib\site-packages\xgboost\sklearn.py", line 391, in fit
    self._Booster = train(params, trainDmatrix,
  File "C:\Users\Sumeet Maheshwari\anaconda3\lib\site-packages\xgboost\training.py", line 212, in train
    return _train_internal(params, dtrain,
  File "C:\Users\Sumeet Maheshwari\anaconda3\lib\site-packages\xgboost\training.py", line 74, in _train_internal
    bst.update(dtrain, i, obj)
  File "C:\Users\Sumeet Maheshwari\anaconda3\lib\site-packages\xgboost\core.py", line 1108, in update
    _check_call(_LIB.XGBoosterUpdateOneIter(self.handle, ctypes.c_int(iteration),
  File "C:\Users\Sumeet Maheshwari\anaconda3\lib\site-packages\xgboost\core.py", line 176, in _check_call
    raise XGBoostError(py_str(_LIB.XGBGetLastError()))
xgboost.core.XGBoostError: [09:01:20] C:\Jenkins\workspace\xgboost-win64_release_0.90\src\metric\metric.cc:23: Unknown metric function r2

--------------------------------------------------------------------------------
2 fits failed with the following error:
Traceback (most recent call last):
  File "C:\Users\Sumeet Maheshwari\anaconda3\lib\site-packages\sklearn\model_selection\_validation.py", line 686, in _fit_and_score
    estimator.fit(X_train, y_train, **fit_params)
  File "C:\Users\Sumeet Maheshwari\anaconda3\lib\site-packages\xgboost\sklearn.py", line 391, in fit
    self._Booster = train(params, trainDmatrix,
  File "C:\Users\Sumeet Maheshwari\anaconda3\lib\site-packages\xgboost\training.py", line 212, in train
    return _train_internal(params, dtrain,
  File "C:\Users\Sumeet Maheshwari\anaconda3\lib\site-packages\xgboost\training.py", line 74, in _train_internal
    bst.update(dtrain, i, obj)
  File "C:\Users\Sumeet Maheshwari\anaconda3\lib\site-packages\xgboost\core.py", line 1108, in update
    _check_call(_LIB.XGBoosterUpdateOneIter(self.handle, ctypes.c_int(iteration),
  File "C:\Users\Sumeet Maheshwari\anaconda3\lib\site-packages\xgboost\core.py", line 176, in _check_call
    raise XGBoostError(py_str(_LIB.XGBGetLastError()))
xgboost.core.XGBoostError: [09:01:21] C:\Jenkins\workspace\xgboost-win64_release_0.90\src\metric\metric.cc:23: Unknown metric function r2

--------------------------------------------------------------------------------
1 fits failed with the following error:
Traceback (most recent call last):
  File "C:\Users\Sumeet Maheshwari\anaconda3\lib\site-packages\sklearn\model_selection\_validation.py", line 686, in _fit_and_score
    estimator.fit(X_train, y_train, **fit_params)
  File "C:\Users\Sumeet Maheshwari\anaconda3\lib\site-packages\xgboost\sklearn.py", line 391, in fit
    self._Booster = train(params, trainDmatrix,
  File "C:\Users\Sumeet Maheshwari\anaconda3\lib\site-packages\xgboost\training.py", line 212, in train
    return _train_internal(params, dtrain,
  File "C:\Users\Sumeet Maheshwari\anaconda3\lib\site-packages\xgboost\training.py", line 74, in _train_internal
    bst.update(dtrain, i, obj)
  File "C:\Users\Sumeet Maheshwari\anaconda3\lib\site-packages\xgboost\core.py", line 1108, in update
    _check_call(_LIB.XGBoosterUpdateOneIter(self.handle, ctypes.c_int(iteration),
  File "C:\Users\Sumeet Maheshwari\anaconda3\lib\site-packages\xgboost\core.py", line 176, in _check_call
    raise XGBoostError(py_str(_LIB.XGBGetLastError()))
xgboost.core.XGBoostError: [09:01:22] C:\Jenkins\workspace\xgboost-win64_release_0.90\src\metric\metric.cc:23: Unknown metric function r2

--------------------------------------------------------------------------------
1 fits failed with the following error:
Traceback (most recent call last):
  File "C:\Users\Sumeet Maheshwari\anaconda3\lib\site-packages\sklearn\model_selection\_validation.py", line 686, in _fit_and_score
    estimator.fit(X_train, y_train, **fit_params)
  File "C:\Users\Sumeet Maheshwari\anaconda3\lib\site-packages\xgboost\sklearn.py", line 391, in fit
    self._Booster = train(params, trainDmatrix,
  File "C:\Users\Sumeet Maheshwari\anaconda3\lib\site-packages\xgboost\training.py", line 212, in train
    return _train_internal(params, dtrain,
  File "C:\Users\Sumeet Maheshwari\anaconda3\lib\site-packages\xgboost\training.py", line 74, in _train_internal
    bst.update(dtrain, i, obj)
  File "C:\Users\Sumeet Maheshwari\anaconda3\lib\site-packages\xgboost\core.py", line 1108, in update
    _check_call(_LIB.XGBoosterUpdateOneIter(self.handle, ctypes.c_int(iteration),
  File "C:\Users\Sumeet Maheshwari\anaconda3\lib\site-packages\xgboost\core.py", line 176, in _check_call
    raise XGBoostError(py_str(_LIB.XGBGetLastError()))
xgboost.core.XGBoostError: [09:01:23] C:\Jenkins\workspace\xgboost-win64_release_0.90\src\metric\metric.cc:23: Unknown metric function r2

--------------------------------------------------------------------------------
1 fits failed with the following error:
Traceback (most recent call last):
  File "C:\Users\Sumeet Maheshwari\anaconda3\lib\site-packages\sklearn\model_selection\_validation.py", line 686, in _fit_and_score
    estimator.fit(X_train, y_train, **fit_params)
  File "C:\Users\Sumeet Maheshwari\anaconda3\lib\site-packages\xgboost\sklearn.py", line 391, in fit
    self._Booster = train(params, trainDmatrix,
  File "C:\Users\Sumeet Maheshwari\anaconda3\lib\site-packages\xgboost\training.py", line 212, in train
    return _train_internal(params, dtrain,
  File "C:\Users\Sumeet Maheshwari\anaconda3\lib\site-packages\xgboost\training.py", line 74, in _train_internal
    bst.update(dtrain, i, obj)
  File "C:\Users\Sumeet Maheshwari\anaconda3\lib\site-packages\xgboost\core.py", line 1108, in update
    _check_call(_LIB.XGBoosterUpdateOneIter(self.handle, ctypes.c_int(iteration),
  File "C:\Users\Sumeet Maheshwari\anaconda3\lib\site-packages\xgboost\core.py", line 176, in _check_call
    raise XGBoostError(py_str(_LIB.XGBGetLastError()))
xgboost.core.XGBoostError: [09:01:24] C:\Jenkins\workspace\xgboost-win64_release_0.90\src\metric\metric.cc:23: Unknown metric function r2

--------------------------------------------------------------------------------
2 fits failed with the following error:
Traceback (most recent call last):
  File "C:\Users\Sumeet Maheshwari\anaconda3\lib\site-packages\sklearn\model_selection\_validation.py", line 686, in _fit_and_score
    estimator.fit(X_train, y_train, **fit_params)
  File "C:\Users\Sumeet Maheshwari\anaconda3\lib\site-packages\xgboost\sklearn.py", line 391, in fit
    self._Booster = train(params, trainDmatrix,
  File "C:\Users\Sumeet Maheshwari\anaconda3\lib\site-packages\xgboost\training.py", line 212, in train
    return _train_internal(params, dtrain,
  File "C:\Users\Sumeet Maheshwari\anaconda3\lib\site-packages\xgboost\training.py", line 74, in _train_internal
    bst.update(dtrain, i, obj)
  File "C:\Users\Sumeet Maheshwari\anaconda3\lib\site-packages\xgboost\core.py", line 1108, in update
    _check_call(_LIB.XGBoosterUpdateOneIter(self.handle, ctypes.c_int(iteration),
  File "C:\Users\Sumeet Maheshwari\anaconda3\lib\site-packages\xgboost\core.py", line 176, in _check_call
    raise XGBoostError(py_str(_LIB.XGBGetLastError()))
xgboost.core.XGBoostError: [09:01:25] C:\Jenkins\workspace\xgboost-win64_release_0.90\src\metric\metric.cc:23: Unknown metric function r2

--------------------------------------------------------------------------------
1 fits failed with the following error:
Traceback (most recent call last):
  File "C:\Users\Sumeet Maheshwari\anaconda3\lib\site-packages\sklearn\model_selection\_validation.py", line 686, in _fit_and_score
    estimator.fit(X_train, y_train, **fit_params)
  File "C:\Users\Sumeet Maheshwari\anaconda3\lib\site-packages\xgboost\sklearn.py", line 391, in fit
    self._Booster = train(params, trainDmatrix,
  File "C:\Users\Sumeet Maheshwari\anaconda3\lib\site-packages\xgboost\training.py", line 212, in train
    return _train_internal(params, dtrain,
  File "C:\Users\Sumeet Maheshwari\anaconda3\lib\site-packages\xgboost\training.py", line 74, in _train_internal
    bst.update(dtrain, i, obj)
  File "C:\Users\Sumeet Maheshwari\anaconda3\lib\site-packages\xgboost\core.py", line 1108, in update
    _check_call(_LIB.XGBoosterUpdateOneIter(self.handle, ctypes.c_int(iteration),
  File "C:\Users\Sumeet Maheshwari\anaconda3\lib\site-packages\xgboost\core.py", line 176, in _check_call
    raise XGBoostError(py_str(_LIB.XGBGetLastError()))
xgboost.core.XGBoostError: [09:01:26] C:\Jenkins\workspace\xgboost-win64_release_0.90\src\metric\metric.cc:23: Unknown metric function r2

--------------------------------------------------------------------------------
1 fits failed with the following error:
Traceback (most recent call last):
  File "C:\Users\Sumeet Maheshwari\anaconda3\lib\site-packages\sklearn\model_selection\_validation.py", line 686, in _fit_and_score
    estimator.fit(X_train, y_train, **fit_params)
  File "C:\Users\Sumeet Maheshwari\anaconda3\lib\site-packages\xgboost\sklearn.py", line 391, in fit
    self._Booster = train(params, trainDmatrix,
  File "C:\Users\Sumeet Maheshwari\anaconda3\lib\site-packages\xgboost\training.py", line 212, in train
    return _train_internal(params, dtrain,
  File "C:\Users\Sumeet Maheshwari\anaconda3\lib\site-packages\xgboost\training.py", line 74, in _train_internal
    bst.update(dtrain, i, obj)
  File "C:\Users\Sumeet Maheshwari\anaconda3\lib\site-packages\xgboost\core.py", line 1108, in update
    _check_call(_LIB.XGBoosterUpdateOneIter(self.handle, ctypes.c_int(iteration),
  File "C:\Users\Sumeet Maheshwari\anaconda3\lib\site-packages\xgboost\core.py", line 176, in _check_call
    raise XGBoostError(py_str(_LIB.XGBGetLastError()))
xgboost.core.XGBoostError: [09:01:27] C:\Jenkins\workspace\xgboost-win64_release_0.90\src\metric\metric.cc:23: Unknown metric function r2

--------------------------------------------------------------------------------
2 fits failed with the following error:
Traceback (most recent call last):
  File "C:\Users\Sumeet Maheshwari\anaconda3\lib\site-packages\sklearn\model_selection\_validation.py", line 686, in _fit_and_score
    estimator.fit(X_train, y_train, **fit_params)
  File "C:\Users\Sumeet Maheshwari\anaconda3\lib\site-packages\xgboost\sklearn.py", line 391, in fit
    self._Booster = train(params, trainDmatrix,
  File "C:\Users\Sumeet Maheshwari\anaconda3\lib\site-packages\xgboost\training.py", line 212, in train
    return _train_internal(params, dtrain,
  File "C:\Users\Sumeet Maheshwari\anaconda3\lib\site-packages\xgboost\training.py", line 74, in _train_internal
    bst.update(dtrain, i, obj)
  File "C:\Users\Sumeet Maheshwari\anaconda3\lib\site-packages\xgboost\core.py", line 1108, in update
    _check_call(_LIB.XGBoosterUpdateOneIter(self.handle, ctypes.c_int(iteration),
  File "C:\Users\Sumeet Maheshwari\anaconda3\lib\site-packages\xgboost\core.py", line 176, in _check_call
    raise XGBoostError(py_str(_LIB.XGBGetLastError()))
xgboost.core.XGBoostError: [09:01:28] C:\Jenkins\workspace\xgboost-win64_release_0.90\src\metric\metric.cc:23: Unknown metric function r2

--------------------------------------------------------------------------------
1 fits failed with the following error:
Traceback (most recent call last):
  File "C:\Users\Sumeet Maheshwari\anaconda3\lib\site-packages\sklearn\model_selection\_validation.py", line 686, in _fit_and_score
    estimator.fit(X_train, y_train, **fit_params)
  File "C:\Users\Sumeet Maheshwari\anaconda3\lib\site-packages\xgboost\sklearn.py", line 391, in fit
    self._Booster = train(params, trainDmatrix,
  File "C:\Users\Sumeet Maheshwari\anaconda3\lib\site-packages\xgboost\training.py", line 212, in train
    return _train_internal(params, dtrain,
  File "C:\Users\Sumeet Maheshwari\anaconda3\lib\site-packages\xgboost\training.py", line 74, in _train_internal
    bst.update(dtrain, i, obj)
  File "C:\Users\Sumeet Maheshwari\anaconda3\lib\site-packages\xgboost\core.py", line 1108, in update
    _check_call(_LIB.XGBoosterUpdateOneIter(self.handle, ctypes.c_int(iteration),
  File "C:\Users\Sumeet Maheshwari\anaconda3\lib\site-packages\xgboost\core.py", line 176, in _check_call
    raise XGBoostError(py_str(_LIB.XGBGetLastError()))
xgboost.core.XGBoostError: [09:01:29] C:\Jenkins\workspace\xgboost-win64_release_0.90\src\metric\metric.cc:23: Unknown metric function r2

--------------------------------------------------------------------------------
1 fits failed with the following error:
Traceback (most recent call last):
  File "C:\Users\Sumeet Maheshwari\anaconda3\lib\site-packages\sklearn\model_selection\_validation.py", line 686, in _fit_and_score
    estimator.fit(X_train, y_train, **fit_params)
  File "C:\Users\Sumeet Maheshwari\anaconda3\lib\site-packages\xgboost\sklearn.py", line 391, in fit
    self._Booster = train(params, trainDmatrix,
  File "C:\Users\Sumeet Maheshwari\anaconda3\lib\site-packages\xgboost\training.py", line 212, in train
    return _train_internal(params, dtrain,
  File "C:\Users\Sumeet Maheshwari\anaconda3\lib\site-packages\xgboost\training.py", line 74, in _train_internal
    bst.update(dtrain, i, obj)
  File "C:\Users\Sumeet Maheshwari\anaconda3\lib\site-packages\xgboost\core.py", line 1108, in update
    _check_call(_LIB.XGBoosterUpdateOneIter(self.handle, ctypes.c_int(iteration),
  File "C:\Users\Sumeet Maheshwari\anaconda3\lib\site-packages\xgboost\core.py", line 176, in _check_call
    raise XGBoostError(py_str(_LIB.XGBGetLastError()))
xgboost.core.XGBoostError: [09:01:30] C:\Jenkins\workspace\xgboost-win64_release_0.90\src\metric\metric.cc:23: Unknown metric function r2

--------------------------------------------------------------------------------
1 fits failed with the following error:
Traceback (most recent call last):
  File "C:\Users\Sumeet Maheshwari\anaconda3\lib\site-packages\sklearn\model_selection\_validation.py", line 686, in _fit_and_score
    estimator.fit(X_train, y_train, **fit_params)
  File "C:\Users\Sumeet Maheshwari\anaconda3\lib\site-packages\xgboost\sklearn.py", line 391, in fit
    self._Booster = train(params, trainDmatrix,
  File "C:\Users\Sumeet Maheshwari\anaconda3\lib\site-packages\xgboost\training.py", line 212, in train
    return _train_internal(params, dtrain,
  File "C:\Users\Sumeet Maheshwari\anaconda3\lib\site-packages\xgboost\training.py", line 74, in _train_internal
    bst.update(dtrain, i, obj)
  File "C:\Users\Sumeet Maheshwari\anaconda3\lib\site-packages\xgboost\core.py", line 1108, in update
    _check_call(_LIB.XGBoosterUpdateOneIter(self.handle, ctypes.c_int(iteration),
  File "C:\Users\Sumeet Maheshwari\anaconda3\lib\site-packages\xgboost\core.py", line 176, in _check_call
    raise XGBoostError(py_str(_LIB.XGBGetLastError()))
xgboost.core.XGBoostError: [09:01:31] C:\Jenkins\workspace\xgboost-win64_release_0.90\src\metric\metric.cc:23: Unknown metric function r2

--------------------------------------------------------------------------------
2 fits failed with the following error:
Traceback (most recent call last):
  File "C:\Users\Sumeet Maheshwari\anaconda3\lib\site-packages\sklearn\model_selection\_validation.py", line 686, in _fit_and_score
    estimator.fit(X_train, y_train, **fit_params)
  File "C:\Users\Sumeet Maheshwari\anaconda3\lib\site-packages\xgboost\sklearn.py", line 391, in fit
    self._Booster = train(params, trainDmatrix,
  File "C:\Users\Sumeet Maheshwari\anaconda3\lib\site-packages\xgboost\training.py", line 212, in train
    return _train_internal(params, dtrain,
  File "C:\Users\Sumeet Maheshwari\anaconda3\lib\site-packages\xgboost\training.py", line 74, in _train_internal
    bst.update(dtrain, i, obj)
  File "C:\Users\Sumeet Maheshwari\anaconda3\lib\site-packages\xgboost\core.py", line 1108, in update
    _check_call(_LIB.XGBoosterUpdateOneIter(self.handle, ctypes.c_int(iteration),
  File "C:\Users\Sumeet Maheshwari\anaconda3\lib\site-packages\xgboost\core.py", line 176, in _check_call
    raise XGBoostError(py_str(_LIB.XGBGetLastError()))
xgboost.core.XGBoostError: [09:01:32] C:\Jenkins\workspace\xgboost-win64_release_0.90\src\metric\metric.cc:23: Unknown metric function r2

--------------------------------------------------------------------------------
1 fits failed with the following error:
Traceback (most recent call last):
  File "C:\Users\Sumeet Maheshwari\anaconda3\lib\site-packages\sklearn\model_selection\_validation.py", line 686, in _fit_and_score
    estimator.fit(X_train, y_train, **fit_params)
  File "C:\Users\Sumeet Maheshwari\anaconda3\lib\site-packages\xgboost\sklearn.py", line 391, in fit
    self._Booster = train(params, trainDmatrix,
  File "C:\Users\Sumeet Maheshwari\anaconda3\lib\site-packages\xgboost\training.py", line 212, in train
    return _train_internal(params, dtrain,
  File "C:\Users\Sumeet Maheshwari\anaconda3\lib\site-packages\xgboost\training.py", line 74, in _train_internal
    bst.update(dtrain, i, obj)
  File "C:\Users\Sumeet Maheshwari\anaconda3\lib\site-packages\xgboost\core.py", line 1108, in update
    _check_call(_LIB.XGBoosterUpdateOneIter(self.handle, ctypes.c_int(iteration),
  File "C:\Users\Sumeet Maheshwari\anaconda3\lib\site-packages\xgboost\core.py", line 176, in _check_call
    raise XGBoostError(py_str(_LIB.XGBGetLastError()))
xgboost.core.XGBoostError: [09:01:33] C:\Jenkins\workspace\xgboost-win64_release_0.90\src\metric\metric.cc:23: Unknown metric function r2

--------------------------------------------------------------------------------
1 fits failed with the following error:
Traceback (most recent call last):
  File "C:\Users\Sumeet Maheshwari\anaconda3\lib\site-packages\sklearn\model_selection\_validation.py", line 686, in _fit_and_score
    estimator.fit(X_train, y_train, **fit_params)
  File "C:\Users\Sumeet Maheshwari\anaconda3\lib\site-packages\xgboost\sklearn.py", line 391, in fit
    self._Booster = train(params, trainDmatrix,
  File "C:\Users\Sumeet Maheshwari\anaconda3\lib\site-packages\xgboost\training.py", line 212, in train
    return _train_internal(params, dtrain,
  File "C:\Users\Sumeet Maheshwari\anaconda3\lib\site-packages\xgboost\training.py", line 74, in _train_internal
    bst.update(dtrain, i, obj)
  File "C:\Users\Sumeet Maheshwari\anaconda3\lib\site-packages\xgboost\core.py", line 1108, in update
    _check_call(_LIB.XGBoosterUpdateOneIter(self.handle, ctypes.c_int(iteration),
  File "C:\Users\Sumeet Maheshwari\anaconda3\lib\site-packages\xgboost\core.py", line 176, in _check_call
    raise XGBoostError(py_str(_LIB.XGBGetLastError()))
xgboost.core.XGBoostError: [09:01:34] C:\Jenkins\workspace\xgboost-win64_release_0.90\src\metric\metric.cc:23: Unknown metric function r2

--------------------------------------------------------------------------------
2 fits failed with the following error:
Traceback (most recent call last):
  File "C:\Users\Sumeet Maheshwari\anaconda3\lib\site-packages\sklearn\model_selection\_validation.py", line 686, in _fit_and_score
    estimator.fit(X_train, y_train, **fit_params)
  File "C:\Users\Sumeet Maheshwari\anaconda3\lib\site-packages\xgboost\sklearn.py", line 391, in fit
    self._Booster = train(params, trainDmatrix,
  File "C:\Users\Sumeet Maheshwari\anaconda3\lib\site-packages\xgboost\training.py", line 212, in train
    return _train_internal(params, dtrain,
  File "C:\Users\Sumeet Maheshwari\anaconda3\lib\site-packages\xgboost\training.py", line 74, in _train_internal
    bst.update(dtrain, i, obj)
  File "C:\Users\Sumeet Maheshwari\anaconda3\lib\site-packages\xgboost\core.py", line 1108, in update
    _check_call(_LIB.XGBoosterUpdateOneIter(self.handle, ctypes.c_int(iteration),
  File "C:\Users\Sumeet Maheshwari\anaconda3\lib\site-packages\xgboost\core.py", line 176, in _check_call
    raise XGBoostError(py_str(_LIB.XGBGetLastError()))
xgboost.core.XGBoostError: [09:01:35] C:\Jenkins\workspace\xgboost-win64_release_0.90\src\metric\metric.cc:23: Unknown metric function r2

--------------------------------------------------------------------------------
1 fits failed with the following error:
Traceback (most recent call last):
  File "C:\Users\Sumeet Maheshwari\anaconda3\lib\site-packages\sklearn\model_selection\_validation.py", line 686, in _fit_and_score
    estimator.fit(X_train, y_train, **fit_params)
  File "C:\Users\Sumeet Maheshwari\anaconda3\lib\site-packages\xgboost\sklearn.py", line 391, in fit
    self._Booster = train(params, trainDmatrix,
  File "C:\Users\Sumeet Maheshwari\anaconda3\lib\site-packages\xgboost\training.py", line 212, in train
    return _train_internal(params, dtrain,
  File "C:\Users\Sumeet Maheshwari\anaconda3\lib\site-packages\xgboost\training.py", line 74, in _train_internal
    bst.update(dtrain, i, obj)
  File "C:\Users\Sumeet Maheshwari\anaconda3\lib\site-packages\xgboost\core.py", line 1108, in update
    _check_call(_LIB.XGBoosterUpdateOneIter(self.handle, ctypes.c_int(iteration),
  File "C:\Users\Sumeet Maheshwari\anaconda3\lib\site-packages\xgboost\core.py", line 176, in _check_call
    raise XGBoostError(py_str(_LIB.XGBGetLastError()))
xgboost.core.XGBoostError: [09:01:36] C:\Jenkins\workspace\xgboost-win64_release_0.90\src\metric\metric.cc:23: Unknown metric function r2

--------------------------------------------------------------------------------
1 fits failed with the following error:
Traceback (most recent call last):
  File "C:\Users\Sumeet Maheshwari\anaconda3\lib\site-packages\sklearn\model_selection\_validation.py", line 686, in _fit_and_score
    estimator.fit(X_train, y_train, **fit_params)
  File "C:\Users\Sumeet Maheshwari\anaconda3\lib\site-packages\xgboost\sklearn.py", line 391, in fit
    self._Booster = train(params, trainDmatrix,
  File "C:\Users\Sumeet Maheshwari\anaconda3\lib\site-packages\xgboost\training.py", line 212, in train
    return _train_internal(params, dtrain,
  File "C:\Users\Sumeet Maheshwari\anaconda3\lib\site-packages\xgboost\training.py", line 74, in _train_internal
    bst.update(dtrain, i, obj)
  File "C:\Users\Sumeet Maheshwari\anaconda3\lib\site-packages\xgboost\core.py", line 1108, in update
    _check_call(_LIB.XGBoosterUpdateOneIter(self.handle, ctypes.c_int(iteration),
  File "C:\Users\Sumeet Maheshwari\anaconda3\lib\site-packages\xgboost\core.py", line 176, in _check_call
    raise XGBoostError(py_str(_LIB.XGBGetLastError()))
xgboost.core.XGBoostError: [09:01:37] C:\Jenkins\workspace\xgboost-win64_release_0.90\src\metric\metric.cc:23: Unknown metric function r2

--------------------------------------------------------------------------------
2 fits failed with the following error:
Traceback (most recent call last):
  File "C:\Users\Sumeet Maheshwari\anaconda3\lib\site-packages\sklearn\model_selection\_validation.py", line 686, in _fit_and_score
    estimator.fit(X_train, y_train, **fit_params)
  File "C:\Users\Sumeet Maheshwari\anaconda3\lib\site-packages\xgboost\sklearn.py", line 391, in fit
    self._Booster = train(params, trainDmatrix,
  File "C:\Users\Sumeet Maheshwari\anaconda3\lib\site-packages\xgboost\training.py", line 212, in train
    return _train_internal(params, dtrain,
  File "C:\Users\Sumeet Maheshwari\anaconda3\lib\site-packages\xgboost\training.py", line 74, in _train_internal
    bst.update(dtrain, i, obj)
  File "C:\Users\Sumeet Maheshwari\anaconda3\lib\site-packages\xgboost\core.py", line 1108, in update
    _check_call(_LIB.XGBoosterUpdateOneIter(self.handle, ctypes.c_int(iteration),
  File "C:\Users\Sumeet Maheshwari\anaconda3\lib\site-packages\xgboost\core.py", line 176, in _check_call
    raise XGBoostError(py_str(_LIB.XGBGetLastError()))
xgboost.core.XGBoostError: [09:01:38] C:\Jenkins\workspace\xgboost-win64_release_0.90\src\metric\metric.cc:23: Unknown metric function r2

--------------------------------------------------------------------------------
1 fits failed with the following error:
Traceback (most recent call last):
  File "C:\Users\Sumeet Maheshwari\anaconda3\lib\site-packages\sklearn\model_selection\_validation.py", line 686, in _fit_and_score
    estimator.fit(X_train, y_train, **fit_params)
  File "C:\Users\Sumeet Maheshwari\anaconda3\lib\site-packages\xgboost\sklearn.py", line 391, in fit
    self._Booster = train(params, trainDmatrix,
  File "C:\Users\Sumeet Maheshwari\anaconda3\lib\site-packages\xgboost\training.py", line 212, in train
    return _train_internal(params, dtrain,
  File "C:\Users\Sumeet Maheshwari\anaconda3\lib\site-packages\xgboost\training.py", line 74, in _train_internal
    bst.update(dtrain, i, obj)
  File "C:\Users\Sumeet Maheshwari\anaconda3\lib\site-packages\xgboost\core.py", line 1108, in update
    _check_call(_LIB.XGBoosterUpdateOneIter(self.handle, ctypes.c_int(iteration),
  File "C:\Users\Sumeet Maheshwari\anaconda3\lib\site-packages\xgboost\core.py", line 176, in _check_call
    raise XGBoostError(py_str(_LIB.XGBGetLastError()))
xgboost.core.XGBoostError: [09:01:39] C:\Jenkins\workspace\xgboost-win64_release_0.90\src\metric\metric.cc:23: Unknown metric function r2

--------------------------------------------------------------------------------
1 fits failed with the following error:
Traceback (most recent call last):
  File "C:\Users\Sumeet Maheshwari\anaconda3\lib\site-packages\sklearn\model_selection\_validation.py", line 686, in _fit_and_score
    estimator.fit(X_train, y_train, **fit_params)
  File "C:\Users\Sumeet Maheshwari\anaconda3\lib\site-packages\xgboost\sklearn.py", line 391, in fit
    self._Booster = train(params, trainDmatrix,
  File "C:\Users\Sumeet Maheshwari\anaconda3\lib\site-packages\xgboost\training.py", line 212, in train
    return _train_internal(params, dtrain,
  File "C:\Users\Sumeet Maheshwari\anaconda3\lib\site-packages\xgboost\training.py", line 74, in _train_internal
    bst.update(dtrain, i, obj)
  File "C:\Users\Sumeet Maheshwari\anaconda3\lib\site-packages\xgboost\core.py", line 1108, in update
    _check_call(_LIB.XGBoosterUpdateOneIter(self.handle, ctypes.c_int(iteration),
  File "C:\Users\Sumeet Maheshwari\anaconda3\lib\site-packages\xgboost\core.py", line 176, in _check_call
    raise XGBoostError(py_str(_LIB.XGBGetLastError()))
xgboost.core.XGBoostError: [09:01:40] C:\Jenkins\workspace\xgboost-win64_release_0.90\src\metric\metric.cc:23: Unknown metric function r2

--------------------------------------------------------------------------------
1 fits failed with the following error:
Traceback (most recent call last):
  File "C:\Users\Sumeet Maheshwari\anaconda3\lib\site-packages\sklearn\model_selection\_validation.py", line 686, in _fit_and_score
    estimator.fit(X_train, y_train, **fit_params)
  File "C:\Users\Sumeet Maheshwari\anaconda3\lib\site-packages\xgboost\sklearn.py", line 391, in fit
    self._Booster = train(params, trainDmatrix,
  File "C:\Users\Sumeet Maheshwari\anaconda3\lib\site-packages\xgboost\training.py", line 212, in train
    return _train_internal(params, dtrain,
  File "C:\Users\Sumeet Maheshwari\anaconda3\lib\site-packages\xgboost\training.py", line 74, in _train_internal
    bst.update(dtrain, i, obj)
  File "C:\Users\Sumeet Maheshwari\anaconda3\lib\site-packages\xgboost\core.py", line 1108, in update
    _check_call(_LIB.XGBoosterUpdateOneIter(self.handle, ctypes.c_int(iteration),
  File "C:\Users\Sumeet Maheshwari\anaconda3\lib\site-packages\xgboost\core.py", line 176, in _check_call
    raise XGBoostError(py_str(_LIB.XGBGetLastError()))
xgboost.core.XGBoostError: [09:01:41] C:\Jenkins\workspace\xgboost-win64_release_0.90\src\metric\metric.cc:23: Unknown metric function r2

--------------------------------------------------------------------------------
2 fits failed with the following error:
Traceback (most recent call last):
  File "C:\Users\Sumeet Maheshwari\anaconda3\lib\site-packages\sklearn\model_selection\_validation.py", line 686, in _fit_and_score
    estimator.fit(X_train, y_train, **fit_params)
  File "C:\Users\Sumeet Maheshwari\anaconda3\lib\site-packages\xgboost\sklearn.py", line 391, in fit
    self._Booster = train(params, trainDmatrix,
  File "C:\Users\Sumeet Maheshwari\anaconda3\lib\site-packages\xgboost\training.py", line 212, in train
    return _train_internal(params, dtrain,
  File "C:\Users\Sumeet Maheshwari\anaconda3\lib\site-packages\xgboost\training.py", line 74, in _train_internal
    bst.update(dtrain, i, obj)
  File "C:\Users\Sumeet Maheshwari\anaconda3\lib\site-packages\xgboost\core.py", line 1108, in update
    _check_call(_LIB.XGBoosterUpdateOneIter(self.handle, ctypes.c_int(iteration),
  File "C:\Users\Sumeet Maheshwari\anaconda3\lib\site-packages\xgboost\core.py", line 176, in _check_call
    raise XGBoostError(py_str(_LIB.XGBGetLastError()))
xgboost.core.XGBoostError: [09:01:42] C:\Jenkins\workspace\xgboost-win64_release_0.90\src\metric\metric.cc:23: Unknown metric function r2

--------------------------------------------------------------------------------
1 fits failed with the following error:
Traceback (most recent call last):
  File "C:\Users\Sumeet Maheshwari\anaconda3\lib\site-packages\sklearn\model_selection\_validation.py", line 686, in _fit_and_score
    estimator.fit(X_train, y_train, **fit_params)
  File "C:\Users\Sumeet Maheshwari\anaconda3\lib\site-packages\xgboost\sklearn.py", line 391, in fit
    self._Booster = train(params, trainDmatrix,
  File "C:\Users\Sumeet Maheshwari\anaconda3\lib\site-packages\xgboost\training.py", line 212, in train
    return _train_internal(params, dtrain,
  File "C:\Users\Sumeet Maheshwari\anaconda3\lib\site-packages\xgboost\training.py", line 74, in _train_internal
    bst.update(dtrain, i, obj)
  File "C:\Users\Sumeet Maheshwari\anaconda3\lib\site-packages\xgboost\core.py", line 1108, in update
    _check_call(_LIB.XGBoosterUpdateOneIter(self.handle, ctypes.c_int(iteration),
  File "C:\Users\Sumeet Maheshwari\anaconda3\lib\site-packages\xgboost\core.py", line 176, in _check_call
    raise XGBoostError(py_str(_LIB.XGBGetLastError()))
xgboost.core.XGBoostError: [09:01:43] C:\Jenkins\workspace\xgboost-win64_release_0.90\src\metric\metric.cc:23: Unknown metric function r2

--------------------------------------------------------------------------------
1 fits failed with the following error:
Traceback (most recent call last):
  File "C:\Users\Sumeet Maheshwari\anaconda3\lib\site-packages\sklearn\model_selection\_validation.py", line 686, in _fit_and_score
    estimator.fit(X_train, y_train, **fit_params)
  File "C:\Users\Sumeet Maheshwari\anaconda3\lib\site-packages\xgboost\sklearn.py", line 391, in fit
    self._Booster = train(params, trainDmatrix,
  File "C:\Users\Sumeet Maheshwari\anaconda3\lib\site-packages\xgboost\training.py", line 212, in train
    return _train_internal(params, dtrain,
  File "C:\Users\Sumeet Maheshwari\anaconda3\lib\site-packages\xgboost\training.py", line 74, in _train_internal
    bst.update(dtrain, i, obj)
  File "C:\Users\Sumeet Maheshwari\anaconda3\lib\site-packages\xgboost\core.py", line 1108, in update
    _check_call(_LIB.XGBoosterUpdateOneIter(self.handle, ctypes.c_int(iteration),
  File "C:\Users\Sumeet Maheshwari\anaconda3\lib\site-packages\xgboost\core.py", line 176, in _check_call
    raise XGBoostError(py_str(_LIB.XGBGetLastError()))
xgboost.core.XGBoostError: [09:01:44] C:\Jenkins\workspace\xgboost-win64_release_0.90\src\metric\metric.cc:23: Unknown metric function r2

--------------------------------------------------------------------------------
2 fits failed with the following error:
Traceback (most recent call last):
  File "C:\Users\Sumeet Maheshwari\anaconda3\lib\site-packages\sklearn\model_selection\_validation.py", line 686, in _fit_and_score
    estimator.fit(X_train, y_train, **fit_params)
  File "C:\Users\Sumeet Maheshwari\anaconda3\lib\site-packages\xgboost\sklearn.py", line 391, in fit
    self._Booster = train(params, trainDmatrix,
  File "C:\Users\Sumeet Maheshwari\anaconda3\lib\site-packages\xgboost\training.py", line 212, in train
    return _train_internal(params, dtrain,
  File "C:\Users\Sumeet Maheshwari\anaconda3\lib\site-packages\xgboost\training.py", line 74, in _train_internal
    bst.update(dtrain, i, obj)
  File "C:\Users\Sumeet Maheshwari\anaconda3\lib\site-packages\xgboost\core.py", line 1108, in update
    _check_call(_LIB.XGBoosterUpdateOneIter(self.handle, ctypes.c_int(iteration),
  File "C:\Users\Sumeet Maheshwari\anaconda3\lib\site-packages\xgboost\core.py", line 176, in _check_call
    raise XGBoostError(py_str(_LIB.XGBGetLastError()))
xgboost.core.XGBoostError: [09:01:45] C:\Jenkins\workspace\xgboost-win64_release_0.90\src\metric\metric.cc:23: Unknown metric function r2

--------------------------------------------------------------------------------
1 fits failed with the following error:
Traceback (most recent call last):
  File "C:\Users\Sumeet Maheshwari\anaconda3\lib\site-packages\sklearn\model_selection\_validation.py", line 686, in _fit_and_score
    estimator.fit(X_train, y_train, **fit_params)
  File "C:\Users\Sumeet Maheshwari\anaconda3\lib\site-packages\xgboost\sklearn.py", line 391, in fit
    self._Booster = train(params, trainDmatrix,
  File "C:\Users\Sumeet Maheshwari\anaconda3\lib\site-packages\xgboost\training.py", line 212, in train
    return _train_internal(params, dtrain,
  File "C:\Users\Sumeet Maheshwari\anaconda3\lib\site-packages\xgboost\training.py", line 74, in _train_internal
    bst.update(dtrain, i, obj)
  File "C:\Users\Sumeet Maheshwari\anaconda3\lib\site-packages\xgboost\core.py", line 1108, in update
    _check_call(_LIB.XGBoosterUpdateOneIter(self.handle, ctypes.c_int(iteration),
  File "C:\Users\Sumeet Maheshwari\anaconda3\lib\site-packages\xgboost\core.py", line 176, in _check_call
    raise XGBoostError(py_str(_LIB.XGBGetLastError()))
xgboost.core.XGBoostError: [09:01:46] C:\Jenkins\workspace\xgboost-win64_release_0.90\src\metric\metric.cc:23: Unknown metric function r2

--------------------------------------------------------------------------------
1 fits failed with the following error:
Traceback (most recent call last):
  File "C:\Users\Sumeet Maheshwari\anaconda3\lib\site-packages\sklearn\model_selection\_validation.py", line 686, in _fit_and_score
    estimator.fit(X_train, y_train, **fit_params)
  File "C:\Users\Sumeet Maheshwari\anaconda3\lib\site-packages\xgboost\sklearn.py", line 391, in fit
    self._Booster = train(params, trainDmatrix,
  File "C:\Users\Sumeet Maheshwari\anaconda3\lib\site-packages\xgboost\training.py", line 212, in train
    return _train_internal(params, dtrain,
  File "C:\Users\Sumeet Maheshwari\anaconda3\lib\site-packages\xgboost\training.py", line 74, in _train_internal
    bst.update(dtrain, i, obj)
  File "C:\Users\Sumeet Maheshwari\anaconda3\lib\site-packages\xgboost\core.py", line 1108, in update
    _check_call(_LIB.XGBoosterUpdateOneIter(self.handle, ctypes.c_int(iteration),
  File "C:\Users\Sumeet Maheshwari\anaconda3\lib\site-packages\xgboost\core.py", line 176, in _check_call
    raise XGBoostError(py_str(_LIB.XGBGetLastError()))
xgboost.core.XGBoostError: [09:01:47] C:\Jenkins\workspace\xgboost-win64_release_0.90\src\metric\metric.cc:23: Unknown metric function r2

--------------------------------------------------------------------------------
2 fits failed with the following error:
Traceback (most recent call last):
  File "C:\Users\Sumeet Maheshwari\anaconda3\lib\site-packages\sklearn\model_selection\_validation.py", line 686, in _fit_and_score
    estimator.fit(X_train, y_train, **fit_params)
  File "C:\Users\Sumeet Maheshwari\anaconda3\lib\site-packages\xgboost\sklearn.py", line 391, in fit
    self._Booster = train(params, trainDmatrix,
  File "C:\Users\Sumeet Maheshwari\anaconda3\lib\site-packages\xgboost\training.py", line 212, in train
    return _train_internal(params, dtrain,
  File "C:\Users\Sumeet Maheshwari\anaconda3\lib\site-packages\xgboost\training.py", line 74, in _train_internal
    bst.update(dtrain, i, obj)
  File "C:\Users\Sumeet Maheshwari\anaconda3\lib\site-packages\xgboost\core.py", line 1108, in update
    _check_call(_LIB.XGBoosterUpdateOneIter(self.handle, ctypes.c_int(iteration),
  File "C:\Users\Sumeet Maheshwari\anaconda3\lib\site-packages\xgboost\core.py", line 176, in _check_call
    raise XGBoostError(py_str(_LIB.XGBGetLastError()))
xgboost.core.XGBoostError: [09:01:48] C:\Jenkins\workspace\xgboost-win64_release_0.90\src\metric\metric.cc:23: Unknown metric function r2

--------------------------------------------------------------------------------
1 fits failed with the following error:
Traceback (most recent call last):
  File "C:\Users\Sumeet Maheshwari\anaconda3\lib\site-packages\sklearn\model_selection\_validation.py", line 686, in _fit_and_score
    estimator.fit(X_train, y_train, **fit_params)
  File "C:\Users\Sumeet Maheshwari\anaconda3\lib\site-packages\xgboost\sklearn.py", line 391, in fit
    self._Booster = train(params, trainDmatrix,
  File "C:\Users\Sumeet Maheshwari\anaconda3\lib\site-packages\xgboost\training.py", line 212, in train
    return _train_internal(params, dtrain,
  File "C:\Users\Sumeet Maheshwari\anaconda3\lib\site-packages\xgboost\training.py", line 74, in _train_internal
    bst.update(dtrain, i, obj)
  File "C:\Users\Sumeet Maheshwari\anaconda3\lib\site-packages\xgboost\core.py", line 1108, in update
    _check_call(_LIB.XGBoosterUpdateOneIter(self.handle, ctypes.c_int(iteration),
  File "C:\Users\Sumeet Maheshwari\anaconda3\lib\site-packages\xgboost\core.py", line 176, in _check_call
    raise XGBoostError(py_str(_LIB.XGBGetLastError()))
xgboost.core.XGBoostError: [09:01:49] C:\Jenkins\workspace\xgboost-win64_release_0.90\src\metric\metric.cc:23: Unknown metric function r2

--------------------------------------------------------------------------------
1 fits failed with the following error:
Traceback (most recent call last):
  File "C:\Users\Sumeet Maheshwari\anaconda3\lib\site-packages\sklearn\model_selection\_validation.py", line 686, in _fit_and_score
    estimator.fit(X_train, y_train, **fit_params)
  File "C:\Users\Sumeet Maheshwari\anaconda3\lib\site-packages\xgboost\sklearn.py", line 391, in fit
    self._Booster = train(params, trainDmatrix,
  File "C:\Users\Sumeet Maheshwari\anaconda3\lib\site-packages\xgboost\training.py", line 212, in train
    return _train_internal(params, dtrain,
  File "C:\Users\Sumeet Maheshwari\anaconda3\lib\site-packages\xgboost\training.py", line 74, in _train_internal
    bst.update(dtrain, i, obj)
  File "C:\Users\Sumeet Maheshwari\anaconda3\lib\site-packages\xgboost\core.py", line 1108, in update
    _check_call(_LIB.XGBoosterUpdateOneIter(self.handle, ctypes.c_int(iteration),
  File "C:\Users\Sumeet Maheshwari\anaconda3\lib\site-packages\xgboost\core.py", line 176, in _check_call
    raise XGBoostError(py_str(_LIB.XGBGetLastError()))
xgboost.core.XGBoostError: [09:01:50] C:\Jenkins\workspace\xgboost-win64_release_0.90\src\metric\metric.cc:23: Unknown metric function r2

--------------------------------------------------------------------------------
2 fits failed with the following error:
Traceback (most recent call last):
  File "C:\Users\Sumeet Maheshwari\anaconda3\lib\site-packages\sklearn\model_selection\_validation.py", line 686, in _fit_and_score
    estimator.fit(X_train, y_train, **fit_params)
  File "C:\Users\Sumeet Maheshwari\anaconda3\lib\site-packages\xgboost\sklearn.py", line 391, in fit
    self._Booster = train(params, trainDmatrix,
  File "C:\Users\Sumeet Maheshwari\anaconda3\lib\site-packages\xgboost\training.py", line 212, in train
    return _train_internal(params, dtrain,
  File "C:\Users\Sumeet Maheshwari\anaconda3\lib\site-packages\xgboost\training.py", line 74, in _train_internal
    bst.update(dtrain, i, obj)
  File "C:\Users\Sumeet Maheshwari\anaconda3\lib\site-packages\xgboost\core.py", line 1108, in update
    _check_call(_LIB.XGBoosterUpdateOneIter(self.handle, ctypes.c_int(iteration),
  File "C:\Users\Sumeet Maheshwari\anaconda3\lib\site-packages\xgboost\core.py", line 176, in _check_call
    raise XGBoostError(py_str(_LIB.XGBGetLastError()))
xgboost.core.XGBoostError: [09:01:51] C:\Jenkins\workspace\xgboost-win64_release_0.90\src\metric\metric.cc:23: Unknown metric function r2

--------------------------------------------------------------------------------
1 fits failed with the following error:
Traceback (most recent call last):
  File "C:\Users\Sumeet Maheshwari\anaconda3\lib\site-packages\sklearn\model_selection\_validation.py", line 686, in _fit_and_score
    estimator.fit(X_train, y_train, **fit_params)
  File "C:\Users\Sumeet Maheshwari\anaconda3\lib\site-packages\xgboost\sklearn.py", line 391, in fit
    self._Booster = train(params, trainDmatrix,
  File "C:\Users\Sumeet Maheshwari\anaconda3\lib\site-packages\xgboost\training.py", line 212, in train
    return _train_internal(params, dtrain,
  File "C:\Users\Sumeet Maheshwari\anaconda3\lib\site-packages\xgboost\training.py", line 74, in _train_internal
    bst.update(dtrain, i, obj)
  File "C:\Users\Sumeet Maheshwari\anaconda3\lib\site-packages\xgboost\core.py", line 1108, in update
    _check_call(_LIB.XGBoosterUpdateOneIter(self.handle, ctypes.c_int(iteration),
  File "C:\Users\Sumeet Maheshwari\anaconda3\lib\site-packages\xgboost\core.py", line 176, in _check_call
    raise XGBoostError(py_str(_LIB.XGBGetLastError()))
xgboost.core.XGBoostError: [09:01:52] C:\Jenkins\workspace\xgboost-win64_release_0.90\src\metric\metric.cc:23: Unknown metric function r2

--------------------------------------------------------------------------------
1 fits failed with the following error:
Traceback (most recent call last):
  File "C:\Users\Sumeet Maheshwari\anaconda3\lib\site-packages\sklearn\model_selection\_validation.py", line 686, in _fit_and_score
    estimator.fit(X_train, y_train, **fit_params)
  File "C:\Users\Sumeet Maheshwari\anaconda3\lib\site-packages\xgboost\sklearn.py", line 391, in fit
    self._Booster = train(params, trainDmatrix,
  File "C:\Users\Sumeet Maheshwari\anaconda3\lib\site-packages\xgboost\training.py", line 212, in train
    return _train_internal(params, dtrain,
  File "C:\Users\Sumeet Maheshwari\anaconda3\lib\site-packages\xgboost\training.py", line 74, in _train_internal
    bst.update(dtrain, i, obj)
  File "C:\Users\Sumeet Maheshwari\anaconda3\lib\site-packages\xgboost\core.py", line 1108, in update
    _check_call(_LIB.XGBoosterUpdateOneIter(self.handle, ctypes.c_int(iteration),
  File "C:\Users\Sumeet Maheshwari\anaconda3\lib\site-packages\xgboost\core.py", line 176, in _check_call
    raise XGBoostError(py_str(_LIB.XGBGetLastError()))
xgboost.core.XGBoostError: [09:01:53] C:\Jenkins\workspace\xgboost-win64_release_0.90\src\metric\metric.cc:23: Unknown metric function r2

--------------------------------------------------------------------------------
1 fits failed with the following error:
Traceback (most recent call last):
  File "C:\Users\Sumeet Maheshwari\anaconda3\lib\site-packages\sklearn\model_selection\_validation.py", line 686, in _fit_and_score
    estimator.fit(X_train, y_train, **fit_params)
  File "C:\Users\Sumeet Maheshwari\anaconda3\lib\site-packages\xgboost\sklearn.py", line 391, in fit
    self._Booster = train(params, trainDmatrix,
  File "C:\Users\Sumeet Maheshwari\anaconda3\lib\site-packages\xgboost\training.py", line 212, in train
    return _train_internal(params, dtrain,
  File "C:\Users\Sumeet Maheshwari\anaconda3\lib\site-packages\xgboost\training.py", line 74, in _train_internal
    bst.update(dtrain, i, obj)
  File "C:\Users\Sumeet Maheshwari\anaconda3\lib\site-packages\xgboost\core.py", line 1108, in update
    _check_call(_LIB.XGBoosterUpdateOneIter(self.handle, ctypes.c_int(iteration),
  File "C:\Users\Sumeet Maheshwari\anaconda3\lib\site-packages\xgboost\core.py", line 176, in _check_call
    raise XGBoostError(py_str(_LIB.XGBGetLastError()))
xgboost.core.XGBoostError: [09:01:54] C:\Jenkins\workspace\xgboost-win64_release_0.90\src\metric\metric.cc:23: Unknown metric function r2

--------------------------------------------------------------------------------
2 fits failed with the following error:
Traceback (most recent call last):
  File "C:\Users\Sumeet Maheshwari\anaconda3\lib\site-packages\sklearn\model_selection\_validation.py", line 686, in _fit_and_score
    estimator.fit(X_train, y_train, **fit_params)
  File "C:\Users\Sumeet Maheshwari\anaconda3\lib\site-packages\xgboost\sklearn.py", line 391, in fit
    self._Booster = train(params, trainDmatrix,
  File "C:\Users\Sumeet Maheshwari\anaconda3\lib\site-packages\xgboost\training.py", line 212, in train
    return _train_internal(params, dtrain,
  File "C:\Users\Sumeet Maheshwari\anaconda3\lib\site-packages\xgboost\training.py", line 74, in _train_internal
    bst.update(dtrain, i, obj)
  File "C:\Users\Sumeet Maheshwari\anaconda3\lib\site-packages\xgboost\core.py", line 1108, in update
    _check_call(_LIB.XGBoosterUpdateOneIter(self.handle, ctypes.c_int(iteration),
  File "C:\Users\Sumeet Maheshwari\anaconda3\lib\site-packages\xgboost\core.py", line 176, in _check_call
    raise XGBoostError(py_str(_LIB.XGBGetLastError()))
xgboost.core.XGBoostError: [09:01:55] C:\Jenkins\workspace\xgboost-win64_release_0.90\src\metric\metric.cc:23: Unknown metric function r2

--------------------------------------------------------------------------------
1 fits failed with the following error:
Traceback (most recent call last):
  File "C:\Users\Sumeet Maheshwari\anaconda3\lib\site-packages\sklearn\model_selection\_validation.py", line 686, in _fit_and_score
    estimator.fit(X_train, y_train, **fit_params)
  File "C:\Users\Sumeet Maheshwari\anaconda3\lib\site-packages\xgboost\sklearn.py", line 391, in fit
    self._Booster = train(params, trainDmatrix,
  File "C:\Users\Sumeet Maheshwari\anaconda3\lib\site-packages\xgboost\training.py", line 212, in train
    return _train_internal(params, dtrain,
  File "C:\Users\Sumeet Maheshwari\anaconda3\lib\site-packages\xgboost\training.py", line 74, in _train_internal
    bst.update(dtrain, i, obj)
  File "C:\Users\Sumeet Maheshwari\anaconda3\lib\site-packages\xgboost\core.py", line 1108, in update
    _check_call(_LIB.XGBoosterUpdateOneIter(self.handle, ctypes.c_int(iteration),
  File "C:\Users\Sumeet Maheshwari\anaconda3\lib\site-packages\xgboost\core.py", line 176, in _check_call
    raise XGBoostError(py_str(_LIB.XGBGetLastError()))
xgboost.core.XGBoostError: [09:01:56] C:\Jenkins\workspace\xgboost-win64_release_0.90\src\metric\metric.cc:23: Unknown metric function r2

--------------------------------------------------------------------------------
1 fits failed with the following error:
Traceback (most recent call last):
  File "C:\Users\Sumeet Maheshwari\anaconda3\lib\site-packages\sklearn\model_selection\_validation.py", line 686, in _fit_and_score
    estimator.fit(X_train, y_train, **fit_params)
  File "C:\Users\Sumeet Maheshwari\anaconda3\lib\site-packages\xgboost\sklearn.py", line 391, in fit
    self._Booster = train(params, trainDmatrix,
  File "C:\Users\Sumeet Maheshwari\anaconda3\lib\site-packages\xgboost\training.py", line 212, in train
    return _train_internal(params, dtrain,
  File "C:\Users\Sumeet Maheshwari\anaconda3\lib\site-packages\xgboost\training.py", line 74, in _train_internal
    bst.update(dtrain, i, obj)
  File "C:\Users\Sumeet Maheshwari\anaconda3\lib\site-packages\xgboost\core.py", line 1108, in update
    _check_call(_LIB.XGBoosterUpdateOneIter(self.handle, ctypes.c_int(iteration),
  File "C:\Users\Sumeet Maheshwari\anaconda3\lib\site-packages\xgboost\core.py", line 176, in _check_call
    raise XGBoostError(py_str(_LIB.XGBGetLastError()))
xgboost.core.XGBoostError: [09:01:57] C:\Jenkins\workspace\xgboost-win64_release_0.90\src\metric\metric.cc:23: Unknown metric function r2

--------------------------------------------------------------------------------
2 fits failed with the following error:
Traceback (most recent call last):
  File "C:\Users\Sumeet Maheshwari\anaconda3\lib\site-packages\sklearn\model_selection\_validation.py", line 686, in _fit_and_score
    estimator.fit(X_train, y_train, **fit_params)
  File "C:\Users\Sumeet Maheshwari\anaconda3\lib\site-packages\xgboost\sklearn.py", line 391, in fit
    self._Booster = train(params, trainDmatrix,
  File "C:\Users\Sumeet Maheshwari\anaconda3\lib\site-packages\xgboost\training.py", line 212, in train
    return _train_internal(params, dtrain,
  File "C:\Users\Sumeet Maheshwari\anaconda3\lib\site-packages\xgboost\training.py", line 74, in _train_internal
    bst.update(dtrain, i, obj)
  File "C:\Users\Sumeet Maheshwari\anaconda3\lib\site-packages\xgboost\core.py", line 1108, in update
    _check_call(_LIB.XGBoosterUpdateOneIter(self.handle, ctypes.c_int(iteration),
  File "C:\Users\Sumeet Maheshwari\anaconda3\lib\site-packages\xgboost\core.py", line 176, in _check_call
    raise XGBoostError(py_str(_LIB.XGBGetLastError()))
xgboost.core.XGBoostError: [09:01:58] C:\Jenkins\workspace\xgboost-win64_release_0.90\src\metric\metric.cc:23: Unknown metric function r2

--------------------------------------------------------------------------------
1 fits failed with the following error:
Traceback (most recent call last):
  File "C:\Users\Sumeet Maheshwari\anaconda3\lib\site-packages\sklearn\model_selection\_validation.py", line 686, in _fit_and_score
    estimator.fit(X_train, y_train, **fit_params)
  File "C:\Users\Sumeet Maheshwari\anaconda3\lib\site-packages\xgboost\sklearn.py", line 391, in fit
    self._Booster = train(params, trainDmatrix,
  File "C:\Users\Sumeet Maheshwari\anaconda3\lib\site-packages\xgboost\training.py", line 212, in train
    return _train_internal(params, dtrain,
  File "C:\Users\Sumeet Maheshwari\anaconda3\lib\site-packages\xgboost\training.py", line 74, in _train_internal
    bst.update(dtrain, i, obj)
  File "C:\Users\Sumeet Maheshwari\anaconda3\lib\site-packages\xgboost\core.py", line 1108, in update
    _check_call(_LIB.XGBoosterUpdateOneIter(self.handle, ctypes.c_int(iteration),
  File "C:\Users\Sumeet Maheshwari\anaconda3\lib\site-packages\xgboost\core.py", line 176, in _check_call
    raise XGBoostError(py_str(_LIB.XGBGetLastError()))
xgboost.core.XGBoostError: [09:01:59] C:\Jenkins\workspace\xgboost-win64_release_0.90\src\metric\metric.cc:23: Unknown metric function r2

--------------------------------------------------------------------------------
1 fits failed with the following error:
Traceback (most recent call last):
  File "C:\Users\Sumeet Maheshwari\anaconda3\lib\site-packages\sklearn\model_selection\_validation.py", line 686, in _fit_and_score
    estimator.fit(X_train, y_train, **fit_params)
  File "C:\Users\Sumeet Maheshwari\anaconda3\lib\site-packages\xgboost\sklearn.py", line 391, in fit
    self._Booster = train(params, trainDmatrix,
  File "C:\Users\Sumeet Maheshwari\anaconda3\lib\site-packages\xgboost\training.py", line 212, in train
    return _train_internal(params, dtrain,
  File "C:\Users\Sumeet Maheshwari\anaconda3\lib\site-packages\xgboost\training.py", line 74, in _train_internal
    bst.update(dtrain, i, obj)
  File "C:\Users\Sumeet Maheshwari\anaconda3\lib\site-packages\xgboost\core.py", line 1108, in update
    _check_call(_LIB.XGBoosterUpdateOneIter(self.handle, ctypes.c_int(iteration),
  File "C:\Users\Sumeet Maheshwari\anaconda3\lib\site-packages\xgboost\core.py", line 176, in _check_call
    raise XGBoostError(py_str(_LIB.XGBGetLastError()))
xgboost.core.XGBoostError: [09:02:00] C:\Jenkins\workspace\xgboost-win64_release_0.90\src\metric\metric.cc:23: Unknown metric function r2

--------------------------------------------------------------------------------
2 fits failed with the following error:
Traceback (most recent call last):
  File "C:\Users\Sumeet Maheshwari\anaconda3\lib\site-packages\sklearn\model_selection\_validation.py", line 686, in _fit_and_score
    estimator.fit(X_train, y_train, **fit_params)
  File "C:\Users\Sumeet Maheshwari\anaconda3\lib\site-packages\xgboost\sklearn.py", line 391, in fit
    self._Booster = train(params, trainDmatrix,
  File "C:\Users\Sumeet Maheshwari\anaconda3\lib\site-packages\xgboost\training.py", line 212, in train
    return _train_internal(params, dtrain,
  File "C:\Users\Sumeet Maheshwari\anaconda3\lib\site-packages\xgboost\training.py", line 74, in _train_internal
    bst.update(dtrain, i, obj)
  File "C:\Users\Sumeet Maheshwari\anaconda3\lib\site-packages\xgboost\core.py", line 1108, in update
    _check_call(_LIB.XGBoosterUpdateOneIter(self.handle, ctypes.c_int(iteration),
  File "C:\Users\Sumeet Maheshwari\anaconda3\lib\site-packages\xgboost\core.py", line 176, in _check_call
    raise XGBoostError(py_str(_LIB.XGBGetLastError()))
xgboost.core.XGBoostError: [09:02:01] C:\Jenkins\workspace\xgboost-win64_release_0.90\src\metric\metric.cc:23: Unknown metric function r2

--------------------------------------------------------------------------------
1 fits failed with the following error:
Traceback (most recent call last):
  File "C:\Users\Sumeet Maheshwari\anaconda3\lib\site-packages\sklearn\model_selection\_validation.py", line 686, in _fit_and_score
    estimator.fit(X_train, y_train, **fit_params)
  File "C:\Users\Sumeet Maheshwari\anaconda3\lib\site-packages\xgboost\sklearn.py", line 391, in fit
    self._Booster = train(params, trainDmatrix,
  File "C:\Users\Sumeet Maheshwari\anaconda3\lib\site-packages\xgboost\training.py", line 212, in train
    return _train_internal(params, dtrain,
  File "C:\Users\Sumeet Maheshwari\anaconda3\lib\site-packages\xgboost\training.py", line 74, in _train_internal
    bst.update(dtrain, i, obj)
  File "C:\Users\Sumeet Maheshwari\anaconda3\lib\site-packages\xgboost\core.py", line 1108, in update
    _check_call(_LIB.XGBoosterUpdateOneIter(self.handle, ctypes.c_int(iteration),
  File "C:\Users\Sumeet Maheshwari\anaconda3\lib\site-packages\xgboost\core.py", line 176, in _check_call
    raise XGBoostError(py_str(_LIB.XGBGetLastError()))
xgboost.core.XGBoostError: [09:02:02] C:\Jenkins\workspace\xgboost-win64_release_0.90\src\metric\metric.cc:23: Unknown metric function r2

--------------------------------------------------------------------------------
1 fits failed with the following error:
Traceback (most recent call last):
  File "C:\Users\Sumeet Maheshwari\anaconda3\lib\site-packages\sklearn\model_selection\_validation.py", line 686, in _fit_and_score
    estimator.fit(X_train, y_train, **fit_params)
  File "C:\Users\Sumeet Maheshwari\anaconda3\lib\site-packages\xgboost\sklearn.py", line 391, in fit
    self._Booster = train(params, trainDmatrix,
  File "C:\Users\Sumeet Maheshwari\anaconda3\lib\site-packages\xgboost\training.py", line 212, in train
    return _train_internal(params, dtrain,
  File "C:\Users\Sumeet Maheshwari\anaconda3\lib\site-packages\xgboost\training.py", line 74, in _train_internal
    bst.update(dtrain, i, obj)
  File "C:\Users\Sumeet Maheshwari\anaconda3\lib\site-packages\xgboost\core.py", line 1108, in update
    _check_call(_LIB.XGBoosterUpdateOneIter(self.handle, ctypes.c_int(iteration),
  File "C:\Users\Sumeet Maheshwari\anaconda3\lib\site-packages\xgboost\core.py", line 176, in _check_call
    raise XGBoostError(py_str(_LIB.XGBGetLastError()))
xgboost.core.XGBoostError: [09:02:03] C:\Jenkins\workspace\xgboost-win64_release_0.90\src\metric\metric.cc:23: Unknown metric function r2

--------------------------------------------------------------------------------
2 fits failed with the following error:
Traceback (most recent call last):
  File "C:\Users\Sumeet Maheshwari\anaconda3\lib\site-packages\sklearn\model_selection\_validation.py", line 686, in _fit_and_score
    estimator.fit(X_train, y_train, **fit_params)
  File "C:\Users\Sumeet Maheshwari\anaconda3\lib\site-packages\xgboost\sklearn.py", line 391, in fit
    self._Booster = train(params, trainDmatrix,
  File "C:\Users\Sumeet Maheshwari\anaconda3\lib\site-packages\xgboost\training.py", line 212, in train
    return _train_internal(params, dtrain,
  File "C:\Users\Sumeet Maheshwari\anaconda3\lib\site-packages\xgboost\training.py", line 74, in _train_internal
    bst.update(dtrain, i, obj)
  File "C:\Users\Sumeet Maheshwari\anaconda3\lib\site-packages\xgboost\core.py", line 1108, in update
    _check_call(_LIB.XGBoosterUpdateOneIter(self.handle, ctypes.c_int(iteration),
  File "C:\Users\Sumeet Maheshwari\anaconda3\lib\site-packages\xgboost\core.py", line 176, in _check_call
    raise XGBoostError(py_str(_LIB.XGBGetLastError()))
xgboost.core.XGBoostError: [09:02:04] C:\Jenkins\workspace\xgboost-win64_release_0.90\src\metric\metric.cc:23: Unknown metric function r2

--------------------------------------------------------------------------------
1 fits failed with the following error:
Traceback (most recent call last):
  File "C:\Users\Sumeet Maheshwari\anaconda3\lib\site-packages\sklearn\model_selection\_validation.py", line 686, in _fit_and_score
    estimator.fit(X_train, y_train, **fit_params)
  File "C:\Users\Sumeet Maheshwari\anaconda3\lib\site-packages\xgboost\sklearn.py", line 391, in fit
    self._Booster = train(params, trainDmatrix,
  File "C:\Users\Sumeet Maheshwari\anaconda3\lib\site-packages\xgboost\training.py", line 212, in train
    return _train_internal(params, dtrain,
  File "C:\Users\Sumeet Maheshwari\anaconda3\lib\site-packages\xgboost\training.py", line 74, in _train_internal
    bst.update(dtrain, i, obj)
  File "C:\Users\Sumeet Maheshwari\anaconda3\lib\site-packages\xgboost\core.py", line 1108, in update
    _check_call(_LIB.XGBoosterUpdateOneIter(self.handle, ctypes.c_int(iteration),
  File "C:\Users\Sumeet Maheshwari\anaconda3\lib\site-packages\xgboost\core.py", line 176, in _check_call
    raise XGBoostError(py_str(_LIB.XGBGetLastError()))
xgboost.core.XGBoostError: [09:02:05] C:\Jenkins\workspace\xgboost-win64_release_0.90\src\metric\metric.cc:23: Unknown metric function r2

--------------------------------------------------------------------------------
1 fits failed with the following error:
Traceback (most recent call last):
  File "C:\Users\Sumeet Maheshwari\anaconda3\lib\site-packages\sklearn\model_selection\_validation.py", line 686, in _fit_and_score
    estimator.fit(X_train, y_train, **fit_params)
  File "C:\Users\Sumeet Maheshwari\anaconda3\lib\site-packages\xgboost\sklearn.py", line 391, in fit
    self._Booster = train(params, trainDmatrix,
  File "C:\Users\Sumeet Maheshwari\anaconda3\lib\site-packages\xgboost\training.py", line 212, in train
    return _train_internal(params, dtrain,
  File "C:\Users\Sumeet Maheshwari\anaconda3\lib\site-packages\xgboost\training.py", line 74, in _train_internal
    bst.update(dtrain, i, obj)
  File "C:\Users\Sumeet Maheshwari\anaconda3\lib\site-packages\xgboost\core.py", line 1108, in update
    _check_call(_LIB.XGBoosterUpdateOneIter(self.handle, ctypes.c_int(iteration),
  File "C:\Users\Sumeet Maheshwari\anaconda3\lib\site-packages\xgboost\core.py", line 176, in _check_call
    raise XGBoostError(py_str(_LIB.XGBGetLastError()))
xgboost.core.XGBoostError: [09:02:06] C:\Jenkins\workspace\xgboost-win64_release_0.90\src\metric\metric.cc:23: Unknown metric function r2

--------------------------------------------------------------------------------
2 fits failed with the following error:
Traceback (most recent call last):
  File "C:\Users\Sumeet Maheshwari\anaconda3\lib\site-packages\sklearn\model_selection\_validation.py", line 686, in _fit_and_score
    estimator.fit(X_train, y_train, **fit_params)
  File "C:\Users\Sumeet Maheshwari\anaconda3\lib\site-packages\xgboost\sklearn.py", line 391, in fit
    self._Booster = train(params, trainDmatrix,
  File "C:\Users\Sumeet Maheshwari\anaconda3\lib\site-packages\xgboost\training.py", line 212, in train
    return _train_internal(params, dtrain,
  File "C:\Users\Sumeet Maheshwari\anaconda3\lib\site-packages\xgboost\training.py", line 74, in _train_internal
    bst.update(dtrain, i, obj)
  File "C:\Users\Sumeet Maheshwari\anaconda3\lib\site-packages\xgboost\core.py", line 1108, in update
    _check_call(_LIB.XGBoosterUpdateOneIter(self.handle, ctypes.c_int(iteration),
  File "C:\Users\Sumeet Maheshwari\anaconda3\lib\site-packages\xgboost\core.py", line 176, in _check_call
    raise XGBoostError(py_str(_LIB.XGBGetLastError()))
xgboost.core.XGBoostError: [09:02:07] C:\Jenkins\workspace\xgboost-win64_release_0.90\src\metric\metric.cc:23: Unknown metric function r2

--------------------------------------------------------------------------------
1 fits failed with the following error:
Traceback (most recent call last):
  File "C:\Users\Sumeet Maheshwari\anaconda3\lib\site-packages\sklearn\model_selection\_validation.py", line 686, in _fit_and_score
    estimator.fit(X_train, y_train, **fit_params)
  File "C:\Users\Sumeet Maheshwari\anaconda3\lib\site-packages\xgboost\sklearn.py", line 391, in fit
    self._Booster = train(params, trainDmatrix,
  File "C:\Users\Sumeet Maheshwari\anaconda3\lib\site-packages\xgboost\training.py", line 212, in train
    return _train_internal(params, dtrain,
  File "C:\Users\Sumeet Maheshwari\anaconda3\lib\site-packages\xgboost\training.py", line 74, in _train_internal
    bst.update(dtrain, i, obj)
  File "C:\Users\Sumeet Maheshwari\anaconda3\lib\site-packages\xgboost\core.py", line 1108, in update
    _check_call(_LIB.XGBoosterUpdateOneIter(self.handle, ctypes.c_int(iteration),
  File "C:\Users\Sumeet Maheshwari\anaconda3\lib\site-packages\xgboost\core.py", line 176, in _check_call
    raise XGBoostError(py_str(_LIB.XGBGetLastError()))
xgboost.core.XGBoostError: [09:02:08] C:\Jenkins\workspace\xgboost-win64_release_0.90\src\metric\metric.cc:23: Unknown metric function r2

--------------------------------------------------------------------------------
1 fits failed with the following error:
Traceback (most recent call last):
  File "C:\Users\Sumeet Maheshwari\anaconda3\lib\site-packages\sklearn\model_selection\_validation.py", line 686, in _fit_and_score
    estimator.fit(X_train, y_train, **fit_params)
  File "C:\Users\Sumeet Maheshwari\anaconda3\lib\site-packages\xgboost\sklearn.py", line 391, in fit
    self._Booster = train(params, trainDmatrix,
  File "C:\Users\Sumeet Maheshwari\anaconda3\lib\site-packages\xgboost\training.py", line 212, in train
    return _train_internal(params, dtrain,
  File "C:\Users\Sumeet Maheshwari\anaconda3\lib\site-packages\xgboost\training.py", line 74, in _train_internal
    bst.update(dtrain, i, obj)
  File "C:\Users\Sumeet Maheshwari\anaconda3\lib\site-packages\xgboost\core.py", line 1108, in update
    _check_call(_LIB.XGBoosterUpdateOneIter(self.handle, ctypes.c_int(iteration),
  File "C:\Users\Sumeet Maheshwari\anaconda3\lib\site-packages\xgboost\core.py", line 176, in _check_call
    raise XGBoostError(py_str(_LIB.XGBGetLastError()))
xgboost.core.XGBoostError: [09:02:09] C:\Jenkins\workspace\xgboost-win64_release_0.90\src\metric\metric.cc:23: Unknown metric function r2

--------------------------------------------------------------------------------
1 fits failed with the following error:
Traceback (most recent call last):
  File "C:\Users\Sumeet Maheshwari\anaconda3\lib\site-packages\sklearn\model_selection\_validation.py", line 686, in _fit_and_score
    estimator.fit(X_train, y_train, **fit_params)
  File "C:\Users\Sumeet Maheshwari\anaconda3\lib\site-packages\xgboost\sklearn.py", line 391, in fit
    self._Booster = train(params, trainDmatrix,
  File "C:\Users\Sumeet Maheshwari\anaconda3\lib\site-packages\xgboost\training.py", line 212, in train
    return _train_internal(params, dtrain,
  File "C:\Users\Sumeet Maheshwari\anaconda3\lib\site-packages\xgboost\training.py", line 74, in _train_internal
    bst.update(dtrain, i, obj)
  File "C:\Users\Sumeet Maheshwari\anaconda3\lib\site-packages\xgboost\core.py", line 1108, in update
    _check_call(_LIB.XGBoosterUpdateOneIter(self.handle, ctypes.c_int(iteration),
  File "C:\Users\Sumeet Maheshwari\anaconda3\lib\site-packages\xgboost\core.py", line 176, in _check_call
    raise XGBoostError(py_str(_LIB.XGBGetLastError()))
xgboost.core.XGBoostError: [09:02:10] C:\Jenkins\workspace\xgboost-win64_release_0.90\src\metric\metric.cc:23: Unknown metric function r2

--------------------------------------------------------------------------------
2 fits failed with the following error:
Traceback (most recent call last):
  File "C:\Users\Sumeet Maheshwari\anaconda3\lib\site-packages\sklearn\model_selection\_validation.py", line 686, in _fit_and_score
    estimator.fit(X_train, y_train, **fit_params)
  File "C:\Users\Sumeet Maheshwari\anaconda3\lib\site-packages\xgboost\sklearn.py", line 391, in fit
    self._Booster = train(params, trainDmatrix,
  File "C:\Users\Sumeet Maheshwari\anaconda3\lib\site-packages\xgboost\training.py", line 212, in train
    return _train_internal(params, dtrain,
  File "C:\Users\Sumeet Maheshwari\anaconda3\lib\site-packages\xgboost\training.py", line 74, in _train_internal
    bst.update(dtrain, i, obj)
  File "C:\Users\Sumeet Maheshwari\anaconda3\lib\site-packages\xgboost\core.py", line 1108, in update
    _check_call(_LIB.XGBoosterUpdateOneIter(self.handle, ctypes.c_int(iteration),
  File "C:\Users\Sumeet Maheshwari\anaconda3\lib\site-packages\xgboost\core.py", line 176, in _check_call
    raise XGBoostError(py_str(_LIB.XGBGetLastError()))
xgboost.core.XGBoostError: [09:02:11] C:\Jenkins\workspace\xgboost-win64_release_0.90\src\metric\metric.cc:23: Unknown metric function r2

--------------------------------------------------------------------------------
1 fits failed with the following error:
Traceback (most recent call last):
  File "C:\Users\Sumeet Maheshwari\anaconda3\lib\site-packages\sklearn\model_selection\_validation.py", line 686, in _fit_and_score
    estimator.fit(X_train, y_train, **fit_params)
  File "C:\Users\Sumeet Maheshwari\anaconda3\lib\site-packages\xgboost\sklearn.py", line 391, in fit
    self._Booster = train(params, trainDmatrix,
  File "C:\Users\Sumeet Maheshwari\anaconda3\lib\site-packages\xgboost\training.py", line 212, in train
    return _train_internal(params, dtrain,
  File "C:\Users\Sumeet Maheshwari\anaconda3\lib\site-packages\xgboost\training.py", line 74, in _train_internal
    bst.update(dtrain, i, obj)
  File "C:\Users\Sumeet Maheshwari\anaconda3\lib\site-packages\xgboost\core.py", line 1108, in update
    _check_call(_LIB.XGBoosterUpdateOneIter(self.handle, ctypes.c_int(iteration),
  File "C:\Users\Sumeet Maheshwari\anaconda3\lib\site-packages\xgboost\core.py", line 176, in _check_call
    raise XGBoostError(py_str(_LIB.XGBGetLastError()))
xgboost.core.XGBoostError: [09:02:12] C:\Jenkins\workspace\xgboost-win64_release_0.90\src\metric\metric.cc:23: Unknown metric function r2

--------------------------------------------------------------------------------
1 fits failed with the following error:
Traceback (most recent call last):
  File "C:\Users\Sumeet Maheshwari\anaconda3\lib\site-packages\sklearn\model_selection\_validation.py", line 686, in _fit_and_score
    estimator.fit(X_train, y_train, **fit_params)
  File "C:\Users\Sumeet Maheshwari\anaconda3\lib\site-packages\xgboost\sklearn.py", line 391, in fit
    self._Booster = train(params, trainDmatrix,
  File "C:\Users\Sumeet Maheshwari\anaconda3\lib\site-packages\xgboost\training.py", line 212, in train
    return _train_internal(params, dtrain,
  File "C:\Users\Sumeet Maheshwari\anaconda3\lib\site-packages\xgboost\training.py", line 74, in _train_internal
    bst.update(dtrain, i, obj)
  File "C:\Users\Sumeet Maheshwari\anaconda3\lib\site-packages\xgboost\core.py", line 1108, in update
    _check_call(_LIB.XGBoosterUpdateOneIter(self.handle, ctypes.c_int(iteration),
  File "C:\Users\Sumeet Maheshwari\anaconda3\lib\site-packages\xgboost\core.py", line 176, in _check_call
    raise XGBoostError(py_str(_LIB.XGBGetLastError()))
xgboost.core.XGBoostError: [09:02:13] C:\Jenkins\workspace\xgboost-win64_release_0.90\src\metric\metric.cc:23: Unknown metric function r2

--------------------------------------------------------------------------------
2 fits failed with the following error:
Traceback (most recent call last):
  File "C:\Users\Sumeet Maheshwari\anaconda3\lib\site-packages\sklearn\model_selection\_validation.py", line 686, in _fit_and_score
    estimator.fit(X_train, y_train, **fit_params)
  File "C:\Users\Sumeet Maheshwari\anaconda3\lib\site-packages\xgboost\sklearn.py", line 391, in fit
    self._Booster = train(params, trainDmatrix,
  File "C:\Users\Sumeet Maheshwari\anaconda3\lib\site-packages\xgboost\training.py", line 212, in train
    return _train_internal(params, dtrain,
  File "C:\Users\Sumeet Maheshwari\anaconda3\lib\site-packages\xgboost\training.py", line 74, in _train_internal
    bst.update(dtrain, i, obj)
  File "C:\Users\Sumeet Maheshwari\anaconda3\lib\site-packages\xgboost\core.py", line 1108, in update
    _check_call(_LIB.XGBoosterUpdateOneIter(self.handle, ctypes.c_int(iteration),
  File "C:\Users\Sumeet Maheshwari\anaconda3\lib\site-packages\xgboost\core.py", line 176, in _check_call
    raise XGBoostError(py_str(_LIB.XGBGetLastError()))
xgboost.core.XGBoostError: [09:02:14] C:\Jenkins\workspace\xgboost-win64_release_0.90\src\metric\metric.cc:23: Unknown metric function r2

--------------------------------------------------------------------------------
1 fits failed with the following error:
Traceback (most recent call last):
  File "C:\Users\Sumeet Maheshwari\anaconda3\lib\site-packages\sklearn\model_selection\_validation.py", line 686, in _fit_and_score
    estimator.fit(X_train, y_train, **fit_params)
  File "C:\Users\Sumeet Maheshwari\anaconda3\lib\site-packages\xgboost\sklearn.py", line 391, in fit
    self._Booster = train(params, trainDmatrix,
  File "C:\Users\Sumeet Maheshwari\anaconda3\lib\site-packages\xgboost\training.py", line 212, in train
    return _train_internal(params, dtrain,
  File "C:\Users\Sumeet Maheshwari\anaconda3\lib\site-packages\xgboost\training.py", line 74, in _train_internal
    bst.update(dtrain, i, obj)
  File "C:\Users\Sumeet Maheshwari\anaconda3\lib\site-packages\xgboost\core.py", line 1108, in update
    _check_call(_LIB.XGBoosterUpdateOneIter(self.handle, ctypes.c_int(iteration),
  File "C:\Users\Sumeet Maheshwari\anaconda3\lib\site-packages\xgboost\core.py", line 176, in _check_call
    raise XGBoostError(py_str(_LIB.XGBGetLastError()))
xgboost.core.XGBoostError: [09:02:15] C:\Jenkins\workspace\xgboost-win64_release_0.90\src\metric\metric.cc:23: Unknown metric function r2

--------------------------------------------------------------------------------
1 fits failed with the following error:
Traceback (most recent call last):
  File "C:\Users\Sumeet Maheshwari\anaconda3\lib\site-packages\sklearn\model_selection\_validation.py", line 686, in _fit_and_score
    estimator.fit(X_train, y_train, **fit_params)
  File "C:\Users\Sumeet Maheshwari\anaconda3\lib\site-packages\xgboost\sklearn.py", line 391, in fit
    self._Booster = train(params, trainDmatrix,
  File "C:\Users\Sumeet Maheshwari\anaconda3\lib\site-packages\xgboost\training.py", line 212, in train
    return _train_internal(params, dtrain,
  File "C:\Users\Sumeet Maheshwari\anaconda3\lib\site-packages\xgboost\training.py", line 74, in _train_internal
    bst.update(dtrain, i, obj)
  File "C:\Users\Sumeet Maheshwari\anaconda3\lib\site-packages\xgboost\core.py", line 1108, in update
    _check_call(_LIB.XGBoosterUpdateOneIter(self.handle, ctypes.c_int(iteration),
  File "C:\Users\Sumeet Maheshwari\anaconda3\lib\site-packages\xgboost\core.py", line 176, in _check_call
    raise XGBoostError(py_str(_LIB.XGBGetLastError()))
xgboost.core.XGBoostError: [09:02:16] C:\Jenkins\workspace\xgboost-win64_release_0.90\src\metric\metric.cc:23: Unknown metric function r2

--------------------------------------------------------------------------------
2 fits failed with the following error:
Traceback (most recent call last):
  File "C:\Users\Sumeet Maheshwari\anaconda3\lib\site-packages\sklearn\model_selection\_validation.py", line 686, in _fit_and_score
    estimator.fit(X_train, y_train, **fit_params)
  File "C:\Users\Sumeet Maheshwari\anaconda3\lib\site-packages\xgboost\sklearn.py", line 391, in fit
    self._Booster = train(params, trainDmatrix,
  File "C:\Users\Sumeet Maheshwari\anaconda3\lib\site-packages\xgboost\training.py", line 212, in train
    return _train_internal(params, dtrain,
  File "C:\Users\Sumeet Maheshwari\anaconda3\lib\site-packages\xgboost\training.py", line 74, in _train_internal
    bst.update(dtrain, i, obj)
  File "C:\Users\Sumeet Maheshwari\anaconda3\lib\site-packages\xgboost\core.py", line 1108, in update
    _check_call(_LIB.XGBoosterUpdateOneIter(self.handle, ctypes.c_int(iteration),
  File "C:\Users\Sumeet Maheshwari\anaconda3\lib\site-packages\xgboost\core.py", line 176, in _check_call
    raise XGBoostError(py_str(_LIB.XGBGetLastError()))
xgboost.core.XGBoostError: [09:02:17] C:\Jenkins\workspace\xgboost-win64_release_0.90\src\metric\metric.cc:23: Unknown metric function r2

--------------------------------------------------------------------------------
1 fits failed with the following error:
Traceback (most recent call last):
  File "C:\Users\Sumeet Maheshwari\anaconda3\lib\site-packages\sklearn\model_selection\_validation.py", line 686, in _fit_and_score
    estimator.fit(X_train, y_train, **fit_params)
  File "C:\Users\Sumeet Maheshwari\anaconda3\lib\site-packages\xgboost\sklearn.py", line 391, in fit
    self._Booster = train(params, trainDmatrix,
  File "C:\Users\Sumeet Maheshwari\anaconda3\lib\site-packages\xgboost\training.py", line 212, in train
    return _train_internal(params, dtrain,
  File "C:\Users\Sumeet Maheshwari\anaconda3\lib\site-packages\xgboost\training.py", line 74, in _train_internal
    bst.update(dtrain, i, obj)
  File "C:\Users\Sumeet Maheshwari\anaconda3\lib\site-packages\xgboost\core.py", line 1108, in update
    _check_call(_LIB.XGBoosterUpdateOneIter(self.handle, ctypes.c_int(iteration),
  File "C:\Users\Sumeet Maheshwari\anaconda3\lib\site-packages\xgboost\core.py", line 176, in _check_call
    raise XGBoostError(py_str(_LIB.XGBGetLastError()))
xgboost.core.XGBoostError: [09:02:18] C:\Jenkins\workspace\xgboost-win64_release_0.90\src\metric\metric.cc:23: Unknown metric function r2

--------------------------------------------------------------------------------
1 fits failed with the following error:
Traceback (most recent call last):
  File "C:\Users\Sumeet Maheshwari\anaconda3\lib\site-packages\sklearn\model_selection\_validation.py", line 686, in _fit_and_score
    estimator.fit(X_train, y_train, **fit_params)
  File "C:\Users\Sumeet Maheshwari\anaconda3\lib\site-packages\xgboost\sklearn.py", line 391, in fit
    self._Booster = train(params, trainDmatrix,
  File "C:\Users\Sumeet Maheshwari\anaconda3\lib\site-packages\xgboost\training.py", line 212, in train
    return _train_internal(params, dtrain,
  File "C:\Users\Sumeet Maheshwari\anaconda3\lib\site-packages\xgboost\training.py", line 74, in _train_internal
    bst.update(dtrain, i, obj)
  File "C:\Users\Sumeet Maheshwari\anaconda3\lib\site-packages\xgboost\core.py", line 1108, in update
    _check_call(_LIB.XGBoosterUpdateOneIter(self.handle, ctypes.c_int(iteration),
  File "C:\Users\Sumeet Maheshwari\anaconda3\lib\site-packages\xgboost\core.py", line 176, in _check_call
    raise XGBoostError(py_str(_LIB.XGBGetLastError()))
xgboost.core.XGBoostError: [09:02:19] C:\Jenkins\workspace\xgboost-win64_release_0.90\src\metric\metric.cc:23: Unknown metric function r2

--------------------------------------------------------------------------------
2 fits failed with the following error:
Traceback (most recent call last):
  File "C:\Users\Sumeet Maheshwari\anaconda3\lib\site-packages\sklearn\model_selection\_validation.py", line 686, in _fit_and_score
    estimator.fit(X_train, y_train, **fit_params)
  File "C:\Users\Sumeet Maheshwari\anaconda3\lib\site-packages\xgboost\sklearn.py", line 391, in fit
    self._Booster = train(params, trainDmatrix,
  File "C:\Users\Sumeet Maheshwari\anaconda3\lib\site-packages\xgboost\training.py", line 212, in train
    return _train_internal(params, dtrain,
  File "C:\Users\Sumeet Maheshwari\anaconda3\lib\site-packages\xgboost\training.py", line 74, in _train_internal
    bst.update(dtrain, i, obj)
  File "C:\Users\Sumeet Maheshwari\anaconda3\lib\site-packages\xgboost\core.py", line 1108, in update
    _check_call(_LIB.XGBoosterUpdateOneIter(self.handle, ctypes.c_int(iteration),
  File "C:\Users\Sumeet Maheshwari\anaconda3\lib\site-packages\xgboost\core.py", line 176, in _check_call
    raise XGBoostError(py_str(_LIB.XGBGetLastError()))
xgboost.core.XGBoostError: [09:02:20] C:\Jenkins\workspace\xgboost-win64_release_0.90\src\metric\metric.cc:23: Unknown metric function r2

--------------------------------------------------------------------------------
1 fits failed with the following error:
Traceback (most recent call last):
  File "C:\Users\Sumeet Maheshwari\anaconda3\lib\site-packages\sklearn\model_selection\_validation.py", line 686, in _fit_and_score
    estimator.fit(X_train, y_train, **fit_params)
  File "C:\Users\Sumeet Maheshwari\anaconda3\lib\site-packages\xgboost\sklearn.py", line 391, in fit
    self._Booster = train(params, trainDmatrix,
  File "C:\Users\Sumeet Maheshwari\anaconda3\lib\site-packages\xgboost\training.py", line 212, in train
    return _train_internal(params, dtrain,
  File "C:\Users\Sumeet Maheshwari\anaconda3\lib\site-packages\xgboost\training.py", line 74, in _train_internal
    bst.update(dtrain, i, obj)
  File "C:\Users\Sumeet Maheshwari\anaconda3\lib\site-packages\xgboost\core.py", line 1108, in update
    _check_call(_LIB.XGBoosterUpdateOneIter(self.handle, ctypes.c_int(iteration),
  File "C:\Users\Sumeet Maheshwari\anaconda3\lib\site-packages\xgboost\core.py", line 176, in _check_call
    raise XGBoostError(py_str(_LIB.XGBGetLastError()))
xgboost.core.XGBoostError: [09:02:21] C:\Jenkins\workspace\xgboost-win64_release_0.90\src\metric\metric.cc:23: Unknown metric function r2

--------------------------------------------------------------------------------
1 fits failed with the following error:
Traceback (most recent call last):
  File "C:\Users\Sumeet Maheshwari\anaconda3\lib\site-packages\sklearn\model_selection\_validation.py", line 686, in _fit_and_score
    estimator.fit(X_train, y_train, **fit_params)
  File "C:\Users\Sumeet Maheshwari\anaconda3\lib\site-packages\xgboost\sklearn.py", line 391, in fit
    self._Booster = train(params, trainDmatrix,
  File "C:\Users\Sumeet Maheshwari\anaconda3\lib\site-packages\xgboost\training.py", line 212, in train
    return _train_internal(params, dtrain,
  File "C:\Users\Sumeet Maheshwari\anaconda3\lib\site-packages\xgboost\training.py", line 74, in _train_internal
    bst.update(dtrain, i, obj)
  File "C:\Users\Sumeet Maheshwari\anaconda3\lib\site-packages\xgboost\core.py", line 1108, in update
    _check_call(_LIB.XGBoosterUpdateOneIter(self.handle, ctypes.c_int(iteration),
  File "C:\Users\Sumeet Maheshwari\anaconda3\lib\site-packages\xgboost\core.py", line 176, in _check_call
    raise XGBoostError(py_str(_LIB.XGBGetLastError()))
xgboost.core.XGBoostError: [09:02:22] C:\Jenkins\workspace\xgboost-win64_release_0.90\src\metric\metric.cc:23: Unknown metric function r2

--------------------------------------------------------------------------------
1 fits failed with the following error:
Traceback (most recent call last):
  File "C:\Users\Sumeet Maheshwari\anaconda3\lib\site-packages\sklearn\model_selection\_validation.py", line 686, in _fit_and_score
    estimator.fit(X_train, y_train, **fit_params)
  File "C:\Users\Sumeet Maheshwari\anaconda3\lib\site-packages\xgboost\sklearn.py", line 391, in fit
    self._Booster = train(params, trainDmatrix,
  File "C:\Users\Sumeet Maheshwari\anaconda3\lib\site-packages\xgboost\training.py", line 212, in train
    return _train_internal(params, dtrain,
  File "C:\Users\Sumeet Maheshwari\anaconda3\lib\site-packages\xgboost\training.py", line 74, in _train_internal
    bst.update(dtrain, i, obj)
  File "C:\Users\Sumeet Maheshwari\anaconda3\lib\site-packages\xgboost\core.py", line 1108, in update
    _check_call(_LIB.XGBoosterUpdateOneIter(self.handle, ctypes.c_int(iteration),
  File "C:\Users\Sumeet Maheshwari\anaconda3\lib\site-packages\xgboost\core.py", line 176, in _check_call
    raise XGBoostError(py_str(_LIB.XGBGetLastError()))
xgboost.core.XGBoostError: [09:02:23] C:\Jenkins\workspace\xgboost-win64_release_0.90\src\metric\metric.cc:23: Unknown metric function r2

--------------------------------------------------------------------------------
2 fits failed with the following error:
Traceback (most recent call last):
  File "C:\Users\Sumeet Maheshwari\anaconda3\lib\site-packages\sklearn\model_selection\_validation.py", line 686, in _fit_and_score
    estimator.fit(X_train, y_train, **fit_params)
  File "C:\Users\Sumeet Maheshwari\anaconda3\lib\site-packages\xgboost\sklearn.py", line 391, in fit
    self._Booster = train(params, trainDmatrix,
  File "C:\Users\Sumeet Maheshwari\anaconda3\lib\site-packages\xgboost\training.py", line 212, in train
    return _train_internal(params, dtrain,
  File "C:\Users\Sumeet Maheshwari\anaconda3\lib\site-packages\xgboost\training.py", line 74, in _train_internal
    bst.update(dtrain, i, obj)
  File "C:\Users\Sumeet Maheshwari\anaconda3\lib\site-packages\xgboost\core.py", line 1108, in update
    _check_call(_LIB.XGBoosterUpdateOneIter(self.handle, ctypes.c_int(iteration),
  File "C:\Users\Sumeet Maheshwari\anaconda3\lib\site-packages\xgboost\core.py", line 176, in _check_call
    raise XGBoostError(py_str(_LIB.XGBGetLastError()))
xgboost.core.XGBoostError: [09:02:24] C:\Jenkins\workspace\xgboost-win64_release_0.90\src\metric\metric.cc:23: Unknown metric function r2

--------------------------------------------------------------------------------
1 fits failed with the following error:
Traceback (most recent call last):
  File "C:\Users\Sumeet Maheshwari\anaconda3\lib\site-packages\sklearn\model_selection\_validation.py", line 686, in _fit_and_score
    estimator.fit(X_train, y_train, **fit_params)
  File "C:\Users\Sumeet Maheshwari\anaconda3\lib\site-packages\xgboost\sklearn.py", line 391, in fit
    self._Booster = train(params, trainDmatrix,
  File "C:\Users\Sumeet Maheshwari\anaconda3\lib\site-packages\xgboost\training.py", line 212, in train
    return _train_internal(params, dtrain,
  File "C:\Users\Sumeet Maheshwari\anaconda3\lib\site-packages\xgboost\training.py", line 74, in _train_internal
    bst.update(dtrain, i, obj)
  File "C:\Users\Sumeet Maheshwari\anaconda3\lib\site-packages\xgboost\core.py", line 1108, in update
    _check_call(_LIB.XGBoosterUpdateOneIter(self.handle, ctypes.c_int(iteration),
  File "C:\Users\Sumeet Maheshwari\anaconda3\lib\site-packages\xgboost\core.py", line 176, in _check_call
    raise XGBoostError(py_str(_LIB.XGBGetLastError()))
xgboost.core.XGBoostError: [09:02:25] C:\Jenkins\workspace\xgboost-win64_release_0.90\src\metric\metric.cc:23: Unknown metric function r2

--------------------------------------------------------------------------------
1 fits failed with the following error:
Traceback (most recent call last):
  File "C:\Users\Sumeet Maheshwari\anaconda3\lib\site-packages\sklearn\model_selection\_validation.py", line 686, in _fit_and_score
    estimator.fit(X_train, y_train, **fit_params)
  File "C:\Users\Sumeet Maheshwari\anaconda3\lib\site-packages\xgboost\sklearn.py", line 391, in fit
    self._Booster = train(params, trainDmatrix,
  File "C:\Users\Sumeet Maheshwari\anaconda3\lib\site-packages\xgboost\training.py", line 212, in train
    return _train_internal(params, dtrain,
  File "C:\Users\Sumeet Maheshwari\anaconda3\lib\site-packages\xgboost\training.py", line 74, in _train_internal
    bst.update(dtrain, i, obj)
  File "C:\Users\Sumeet Maheshwari\anaconda3\lib\site-packages\xgboost\core.py", line 1108, in update
    _check_call(_LIB.XGBoosterUpdateOneIter(self.handle, ctypes.c_int(iteration),
  File "C:\Users\Sumeet Maheshwari\anaconda3\lib\site-packages\xgboost\core.py", line 176, in _check_call
    raise XGBoostError(py_str(_LIB.XGBGetLastError()))
xgboost.core.XGBoostError: [09:02:26] C:\Jenkins\workspace\xgboost-win64_release_0.90\src\metric\metric.cc:23: Unknown metric function r2

--------------------------------------------------------------------------------
2 fits failed with the following error:
Traceback (most recent call last):
  File "C:\Users\Sumeet Maheshwari\anaconda3\lib\site-packages\sklearn\model_selection\_validation.py", line 686, in _fit_and_score
    estimator.fit(X_train, y_train, **fit_params)
  File "C:\Users\Sumeet Maheshwari\anaconda3\lib\site-packages\xgboost\sklearn.py", line 391, in fit
    self._Booster = train(params, trainDmatrix,
  File "C:\Users\Sumeet Maheshwari\anaconda3\lib\site-packages\xgboost\training.py", line 212, in train
    return _train_internal(params, dtrain,
  File "C:\Users\Sumeet Maheshwari\anaconda3\lib\site-packages\xgboost\training.py", line 74, in _train_internal
    bst.update(dtrain, i, obj)
  File "C:\Users\Sumeet Maheshwari\anaconda3\lib\site-packages\xgboost\core.py", line 1108, in update
    _check_call(_LIB.XGBoosterUpdateOneIter(self.handle, ctypes.c_int(iteration),
  File "C:\Users\Sumeet Maheshwari\anaconda3\lib\site-packages\xgboost\core.py", line 176, in _check_call
    raise XGBoostError(py_str(_LIB.XGBGetLastError()))
xgboost.core.XGBoostError: [09:02:27] C:\Jenkins\workspace\xgboost-win64_release_0.90\src\metric\metric.cc:23: Unknown metric function r2

--------------------------------------------------------------------------------
1 fits failed with the following error:
Traceback (most recent call last):
  File "C:\Users\Sumeet Maheshwari\anaconda3\lib\site-packages\sklearn\model_selection\_validation.py", line 686, in _fit_and_score
    estimator.fit(X_train, y_train, **fit_params)
  File "C:\Users\Sumeet Maheshwari\anaconda3\lib\site-packages\xgboost\sklearn.py", line 391, in fit
    self._Booster = train(params, trainDmatrix,
  File "C:\Users\Sumeet Maheshwari\anaconda3\lib\site-packages\xgboost\training.py", line 212, in train
    return _train_internal(params, dtrain,
  File "C:\Users\Sumeet Maheshwari\anaconda3\lib\site-packages\xgboost\training.py", line 74, in _train_internal
    bst.update(dtrain, i, obj)
  File "C:\Users\Sumeet Maheshwari\anaconda3\lib\site-packages\xgboost\core.py", line 1108, in update
    _check_call(_LIB.XGBoosterUpdateOneIter(self.handle, ctypes.c_int(iteration),
  File "C:\Users\Sumeet Maheshwari\anaconda3\lib\site-packages\xgboost\core.py", line 176, in _check_call
    raise XGBoostError(py_str(_LIB.XGBGetLastError()))
xgboost.core.XGBoostError: [09:02:28] C:\Jenkins\workspace\xgboost-win64_release_0.90\src\metric\metric.cc:23: Unknown metric function r2

--------------------------------------------------------------------------------
1 fits failed with the following error:
Traceback (most recent call last):
  File "C:\Users\Sumeet Maheshwari\anaconda3\lib\site-packages\sklearn\model_selection\_validation.py", line 686, in _fit_and_score
    estimator.fit(X_train, y_train, **fit_params)
  File "C:\Users\Sumeet Maheshwari\anaconda3\lib\site-packages\xgboost\sklearn.py", line 391, in fit
    self._Booster = train(params, trainDmatrix,
  File "C:\Users\Sumeet Maheshwari\anaconda3\lib\site-packages\xgboost\training.py", line 212, in train
    return _train_internal(params, dtrain,
  File "C:\Users\Sumeet Maheshwari\anaconda3\lib\site-packages\xgboost\training.py", line 74, in _train_internal
    bst.update(dtrain, i, obj)
  File "C:\Users\Sumeet Maheshwari\anaconda3\lib\site-packages\xgboost\core.py", line 1108, in update
    _check_call(_LIB.XGBoosterUpdateOneIter(self.handle, ctypes.c_int(iteration),
  File "C:\Users\Sumeet Maheshwari\anaconda3\lib\site-packages\xgboost\core.py", line 176, in _check_call
    raise XGBoostError(py_str(_LIB.XGBGetLastError()))
xgboost.core.XGBoostError: [09:02:29] C:\Jenkins\workspace\xgboost-win64_release_0.90\src\metric\metric.cc:23: Unknown metric function r2

--------------------------------------------------------------------------------
1 fits failed with the following error:
Traceback (most recent call last):
  File "C:\Users\Sumeet Maheshwari\anaconda3\lib\site-packages\sklearn\model_selection\_validation.py", line 686, in _fit_and_score
    estimator.fit(X_train, y_train, **fit_params)
  File "C:\Users\Sumeet Maheshwari\anaconda3\lib\site-packages\xgboost\sklearn.py", line 391, in fit
    self._Booster = train(params, trainDmatrix,
  File "C:\Users\Sumeet Maheshwari\anaconda3\lib\site-packages\xgboost\training.py", line 212, in train
    return _train_internal(params, dtrain,
  File "C:\Users\Sumeet Maheshwari\anaconda3\lib\site-packages\xgboost\training.py", line 74, in _train_internal
    bst.update(dtrain, i, obj)
  File "C:\Users\Sumeet Maheshwari\anaconda3\lib\site-packages\xgboost\core.py", line 1108, in update
    _check_call(_LIB.XGBoosterUpdateOneIter(self.handle, ctypes.c_int(iteration),
  File "C:\Users\Sumeet Maheshwari\anaconda3\lib\site-packages\xgboost\core.py", line 176, in _check_call
    raise XGBoostError(py_str(_LIB.XGBGetLastError()))
xgboost.core.XGBoostError: [09:02:30] C:\Jenkins\workspace\xgboost-win64_release_0.90\src\metric\metric.cc:23: Unknown metric function r2

--------------------------------------------------------------------------------
2 fits failed with the following error:
Traceback (most recent call last):
  File "C:\Users\Sumeet Maheshwari\anaconda3\lib\site-packages\sklearn\model_selection\_validation.py", line 686, in _fit_and_score
    estimator.fit(X_train, y_train, **fit_params)
  File "C:\Users\Sumeet Maheshwari\anaconda3\lib\site-packages\xgboost\sklearn.py", line 391, in fit
    self._Booster = train(params, trainDmatrix,
  File "C:\Users\Sumeet Maheshwari\anaconda3\lib\site-packages\xgboost\training.py", line 212, in train
    return _train_internal(params, dtrain,
  File "C:\Users\Sumeet Maheshwari\anaconda3\lib\site-packages\xgboost\training.py", line 74, in _train_internal
    bst.update(dtrain, i, obj)
  File "C:\Users\Sumeet Maheshwari\anaconda3\lib\site-packages\xgboost\core.py", line 1108, in update
    _check_call(_LIB.XGBoosterUpdateOneIter(self.handle, ctypes.c_int(iteration),
  File "C:\Users\Sumeet Maheshwari\anaconda3\lib\site-packages\xgboost\core.py", line 176, in _check_call
    raise XGBoostError(py_str(_LIB.XGBGetLastError()))
xgboost.core.XGBoostError: [09:02:31] C:\Jenkins\workspace\xgboost-win64_release_0.90\src\metric\metric.cc:23: Unknown metric function r2

--------------------------------------------------------------------------------
1 fits failed with the following error:
Traceback (most recent call last):
  File "C:\Users\Sumeet Maheshwari\anaconda3\lib\site-packages\sklearn\model_selection\_validation.py", line 686, in _fit_and_score
    estimator.fit(X_train, y_train, **fit_params)
  File "C:\Users\Sumeet Maheshwari\anaconda3\lib\site-packages\xgboost\sklearn.py", line 391, in fit
    self._Booster = train(params, trainDmatrix,
  File "C:\Users\Sumeet Maheshwari\anaconda3\lib\site-packages\xgboost\training.py", line 212, in train
    return _train_internal(params, dtrain,
  File "C:\Users\Sumeet Maheshwari\anaconda3\lib\site-packages\xgboost\training.py", line 74, in _train_internal
    bst.update(dtrain, i, obj)
  File "C:\Users\Sumeet Maheshwari\anaconda3\lib\site-packages\xgboost\core.py", line 1108, in update
    _check_call(_LIB.XGBoosterUpdateOneIter(self.handle, ctypes.c_int(iteration),
  File "C:\Users\Sumeet Maheshwari\anaconda3\lib\site-packages\xgboost\core.py", line 176, in _check_call
    raise XGBoostError(py_str(_LIB.XGBGetLastError()))
xgboost.core.XGBoostError: [09:02:32] C:\Jenkins\workspace\xgboost-win64_release_0.90\src\metric\metric.cc:23: Unknown metric function r2

--------------------------------------------------------------------------------
1 fits failed with the following error:
Traceback (most recent call last):
  File "C:\Users\Sumeet Maheshwari\anaconda3\lib\site-packages\sklearn\model_selection\_validation.py", line 686, in _fit_and_score
    estimator.fit(X_train, y_train, **fit_params)
  File "C:\Users\Sumeet Maheshwari\anaconda3\lib\site-packages\xgboost\sklearn.py", line 391, in fit
    self._Booster = train(params, trainDmatrix,
  File "C:\Users\Sumeet Maheshwari\anaconda3\lib\site-packages\xgboost\training.py", line 212, in train
    return _train_internal(params, dtrain,
  File "C:\Users\Sumeet Maheshwari\anaconda3\lib\site-packages\xgboost\training.py", line 74, in _train_internal
    bst.update(dtrain, i, obj)
  File "C:\Users\Sumeet Maheshwari\anaconda3\lib\site-packages\xgboost\core.py", line 1108, in update
    _check_call(_LIB.XGBoosterUpdateOneIter(self.handle, ctypes.c_int(iteration),
  File "C:\Users\Sumeet Maheshwari\anaconda3\lib\site-packages\xgboost\core.py", line 176, in _check_call
    raise XGBoostError(py_str(_LIB.XGBGetLastError()))
xgboost.core.XGBoostError: [09:02:33] C:\Jenkins\workspace\xgboost-win64_release_0.90\src\metric\metric.cc:23: Unknown metric function r2

--------------------------------------------------------------------------------
2 fits failed with the following error:
Traceback (most recent call last):
  File "C:\Users\Sumeet Maheshwari\anaconda3\lib\site-packages\sklearn\model_selection\_validation.py", line 686, in _fit_and_score
    estimator.fit(X_train, y_train, **fit_params)
  File "C:\Users\Sumeet Maheshwari\anaconda3\lib\site-packages\xgboost\sklearn.py", line 391, in fit
    self._Booster = train(params, trainDmatrix,
  File "C:\Users\Sumeet Maheshwari\anaconda3\lib\site-packages\xgboost\training.py", line 212, in train
    return _train_internal(params, dtrain,
  File "C:\Users\Sumeet Maheshwari\anaconda3\lib\site-packages\xgboost\training.py", line 74, in _train_internal
    bst.update(dtrain, i, obj)
  File "C:\Users\Sumeet Maheshwari\anaconda3\lib\site-packages\xgboost\core.py", line 1108, in update
    _check_call(_LIB.XGBoosterUpdateOneIter(self.handle, ctypes.c_int(iteration),
  File "C:\Users\Sumeet Maheshwari\anaconda3\lib\site-packages\xgboost\core.py", line 176, in _check_call
    raise XGBoostError(py_str(_LIB.XGBGetLastError()))
xgboost.core.XGBoostError: [09:02:34] C:\Jenkins\workspace\xgboost-win64_release_0.90\src\metric\metric.cc:23: Unknown metric function r2

--------------------------------------------------------------------------------
1 fits failed with the following error:
Traceback (most recent call last):
  File "C:\Users\Sumeet Maheshwari\anaconda3\lib\site-packages\sklearn\model_selection\_validation.py", line 686, in _fit_and_score
    estimator.fit(X_train, y_train, **fit_params)
  File "C:\Users\Sumeet Maheshwari\anaconda3\lib\site-packages\xgboost\sklearn.py", line 391, in fit
    self._Booster = train(params, trainDmatrix,
  File "C:\Users\Sumeet Maheshwari\anaconda3\lib\site-packages\xgboost\training.py", line 212, in train
    return _train_internal(params, dtrain,
  File "C:\Users\Sumeet Maheshwari\anaconda3\lib\site-packages\xgboost\training.py", line 74, in _train_internal
    bst.update(dtrain, i, obj)
  File "C:\Users\Sumeet Maheshwari\anaconda3\lib\site-packages\xgboost\core.py", line 1108, in update
    _check_call(_LIB.XGBoosterUpdateOneIter(self.handle, ctypes.c_int(iteration),
  File "C:\Users\Sumeet Maheshwari\anaconda3\lib\site-packages\xgboost\core.py", line 176, in _check_call
    raise XGBoostError(py_str(_LIB.XGBGetLastError()))
xgboost.core.XGBoostError: [09:02:35] C:\Jenkins\workspace\xgboost-win64_release_0.90\src\metric\metric.cc:23: Unknown metric function r2

--------------------------------------------------------------------------------
1 fits failed with the following error:
Traceback (most recent call last):
  File "C:\Users\Sumeet Maheshwari\anaconda3\lib\site-packages\sklearn\model_selection\_validation.py", line 686, in _fit_and_score
    estimator.fit(X_train, y_train, **fit_params)
  File "C:\Users\Sumeet Maheshwari\anaconda3\lib\site-packages\xgboost\sklearn.py", line 391, in fit
    self._Booster = train(params, trainDmatrix,
  File "C:\Users\Sumeet Maheshwari\anaconda3\lib\site-packages\xgboost\training.py", line 212, in train
    return _train_internal(params, dtrain,
  File "C:\Users\Sumeet Maheshwari\anaconda3\lib\site-packages\xgboost\training.py", line 74, in _train_internal
    bst.update(dtrain, i, obj)
  File "C:\Users\Sumeet Maheshwari\anaconda3\lib\site-packages\xgboost\core.py", line 1108, in update
    _check_call(_LIB.XGBoosterUpdateOneIter(self.handle, ctypes.c_int(iteration),
  File "C:\Users\Sumeet Maheshwari\anaconda3\lib\site-packages\xgboost\core.py", line 176, in _check_call
    raise XGBoostError(py_str(_LIB.XGBGetLastError()))
xgboost.core.XGBoostError: [09:02:36] C:\Jenkins\workspace\xgboost-win64_release_0.90\src\metric\metric.cc:23: Unknown metric function r2

--------------------------------------------------------------------------------
1 fits failed with the following error:
Traceback (most recent call last):
  File "C:\Users\Sumeet Maheshwari\anaconda3\lib\site-packages\sklearn\model_selection\_validation.py", line 686, in _fit_and_score
    estimator.fit(X_train, y_train, **fit_params)
  File "C:\Users\Sumeet Maheshwari\anaconda3\lib\site-packages\xgboost\sklearn.py", line 391, in fit
    self._Booster = train(params, trainDmatrix,
  File "C:\Users\Sumeet Maheshwari\anaconda3\lib\site-packages\xgboost\training.py", line 212, in train
    return _train_internal(params, dtrain,
  File "C:\Users\Sumeet Maheshwari\anaconda3\lib\site-packages\xgboost\training.py", line 74, in _train_internal
    bst.update(dtrain, i, obj)
  File "C:\Users\Sumeet Maheshwari\anaconda3\lib\site-packages\xgboost\core.py", line 1108, in update
    _check_call(_LIB.XGBoosterUpdateOneIter(self.handle, ctypes.c_int(iteration),
  File "C:\Users\Sumeet Maheshwari\anaconda3\lib\site-packages\xgboost\core.py", line 176, in _check_call
    raise XGBoostError(py_str(_LIB.XGBGetLastError()))
xgboost.core.XGBoostError: [09:02:37] C:\Jenkins\workspace\xgboost-win64_release_0.90\src\metric\metric.cc:23: Unknown metric function r2

--------------------------------------------------------------------------------
2 fits failed with the following error:
Traceback (most recent call last):
  File "C:\Users\Sumeet Maheshwari\anaconda3\lib\site-packages\sklearn\model_selection\_validation.py", line 686, in _fit_and_score
    estimator.fit(X_train, y_train, **fit_params)
  File "C:\Users\Sumeet Maheshwari\anaconda3\lib\site-packages\xgboost\sklearn.py", line 391, in fit
    self._Booster = train(params, trainDmatrix,
  File "C:\Users\Sumeet Maheshwari\anaconda3\lib\site-packages\xgboost\training.py", line 212, in train
    return _train_internal(params, dtrain,
  File "C:\Users\Sumeet Maheshwari\anaconda3\lib\site-packages\xgboost\training.py", line 74, in _train_internal
    bst.update(dtrain, i, obj)
  File "C:\Users\Sumeet Maheshwari\anaconda3\lib\site-packages\xgboost\core.py", line 1108, in update
    _check_call(_LIB.XGBoosterUpdateOneIter(self.handle, ctypes.c_int(iteration),
  File "C:\Users\Sumeet Maheshwari\anaconda3\lib\site-packages\xgboost\core.py", line 176, in _check_call
    raise XGBoostError(py_str(_LIB.XGBGetLastError()))
xgboost.core.XGBoostError: [09:02:38] C:\Jenkins\workspace\xgboost-win64_release_0.90\src\metric\metric.cc:23: Unknown metric function r2

--------------------------------------------------------------------------------
1 fits failed with the following error:
Traceback (most recent call last):
  File "C:\Users\Sumeet Maheshwari\anaconda3\lib\site-packages\sklearn\model_selection\_validation.py", line 686, in _fit_and_score
    estimator.fit(X_train, y_train, **fit_params)
  File "C:\Users\Sumeet Maheshwari\anaconda3\lib\site-packages\xgboost\sklearn.py", line 391, in fit
    self._Booster = train(params, trainDmatrix,
  File "C:\Users\Sumeet Maheshwari\anaconda3\lib\site-packages\xgboost\training.py", line 212, in train
    return _train_internal(params, dtrain,
  File "C:\Users\Sumeet Maheshwari\anaconda3\lib\site-packages\xgboost\training.py", line 74, in _train_internal
    bst.update(dtrain, i, obj)
  File "C:\Users\Sumeet Maheshwari\anaconda3\lib\site-packages\xgboost\core.py", line 1108, in update
    _check_call(_LIB.XGBoosterUpdateOneIter(self.handle, ctypes.c_int(iteration),
  File "C:\Users\Sumeet Maheshwari\anaconda3\lib\site-packages\xgboost\core.py", line 176, in _check_call
    raise XGBoostError(py_str(_LIB.XGBGetLastError()))
xgboost.core.XGBoostError: [09:02:39] C:\Jenkins\workspace\xgboost-win64_release_0.90\src\metric\metric.cc:23: Unknown metric function r2

--------------------------------------------------------------------------------
1 fits failed with the following error:
Traceback (most recent call last):
  File "C:\Users\Sumeet Maheshwari\anaconda3\lib\site-packages\sklearn\model_selection\_validation.py", line 686, in _fit_and_score
    estimator.fit(X_train, y_train, **fit_params)
  File "C:\Users\Sumeet Maheshwari\anaconda3\lib\site-packages\xgboost\sklearn.py", line 391, in fit
    self._Booster = train(params, trainDmatrix,
  File "C:\Users\Sumeet Maheshwari\anaconda3\lib\site-packages\xgboost\training.py", line 212, in train
    return _train_internal(params, dtrain,
  File "C:\Users\Sumeet Maheshwari\anaconda3\lib\site-packages\xgboost\training.py", line 74, in _train_internal
    bst.update(dtrain, i, obj)
  File "C:\Users\Sumeet Maheshwari\anaconda3\lib\site-packages\xgboost\core.py", line 1108, in update
    _check_call(_LIB.XGBoosterUpdateOneIter(self.handle, ctypes.c_int(iteration),
  File "C:\Users\Sumeet Maheshwari\anaconda3\lib\site-packages\xgboost\core.py", line 176, in _check_call
    raise XGBoostError(py_str(_LIB.XGBGetLastError()))
xgboost.core.XGBoostError: [09:02:40] C:\Jenkins\workspace\xgboost-win64_release_0.90\src\metric\metric.cc:23: Unknown metric function r2

--------------------------------------------------------------------------------
1 fits failed with the following error:
Traceback (most recent call last):
  File "C:\Users\Sumeet Maheshwari\anaconda3\lib\site-packages\sklearn\model_selection\_validation.py", line 686, in _fit_and_score
    estimator.fit(X_train, y_train, **fit_params)
  File "C:\Users\Sumeet Maheshwari\anaconda3\lib\site-packages\xgboost\sklearn.py", line 391, in fit
    self._Booster = train(params, trainDmatrix,
  File "C:\Users\Sumeet Maheshwari\anaconda3\lib\site-packages\xgboost\training.py", line 212, in train
    return _train_internal(params, dtrain,
  File "C:\Users\Sumeet Maheshwari\anaconda3\lib\site-packages\xgboost\training.py", line 74, in _train_internal
    bst.update(dtrain, i, obj)
  File "C:\Users\Sumeet Maheshwari\anaconda3\lib\site-packages\xgboost\core.py", line 1108, in update
    _check_call(_LIB.XGBoosterUpdateOneIter(self.handle, ctypes.c_int(iteration),
  File "C:\Users\Sumeet Maheshwari\anaconda3\lib\site-packages\xgboost\core.py", line 176, in _check_call
    raise XGBoostError(py_str(_LIB.XGBGetLastError()))
xgboost.core.XGBoostError: [09:02:41] C:\Jenkins\workspace\xgboost-win64_release_0.90\src\metric\metric.cc:23: Unknown metric function r2

--------------------------------------------------------------------------------
1 fits failed with the following error:
Traceback (most recent call last):
  File "C:\Users\Sumeet Maheshwari\anaconda3\lib\site-packages\sklearn\model_selection\_validation.py", line 686, in _fit_and_score
    estimator.fit(X_train, y_train, **fit_params)
  File "C:\Users\Sumeet Maheshwari\anaconda3\lib\site-packages\xgboost\sklearn.py", line 391, in fit
    self._Booster = train(params, trainDmatrix,
  File "C:\Users\Sumeet Maheshwari\anaconda3\lib\site-packages\xgboost\training.py", line 212, in train
    return _train_internal(params, dtrain,
  File "C:\Users\Sumeet Maheshwari\anaconda3\lib\site-packages\xgboost\training.py", line 74, in _train_internal
    bst.update(dtrain, i, obj)
  File "C:\Users\Sumeet Maheshwari\anaconda3\lib\site-packages\xgboost\core.py", line 1108, in update
    _check_call(_LIB.XGBoosterUpdateOneIter(self.handle, ctypes.c_int(iteration),
  File "C:\Users\Sumeet Maheshwari\anaconda3\lib\site-packages\xgboost\core.py", line 176, in _check_call
    raise XGBoostError(py_str(_LIB.XGBGetLastError()))
xgboost.core.XGBoostError: [09:02:42] C:\Jenkins\workspace\xgboost-win64_release_0.90\src\metric\metric.cc:23: Unknown metric function r2

--------------------------------------------------------------------------------
1 fits failed with the following error:
Traceback (most recent call last):
  File "C:\Users\Sumeet Maheshwari\anaconda3\lib\site-packages\sklearn\model_selection\_validation.py", line 686, in _fit_and_score
    estimator.fit(X_train, y_train, **fit_params)
  File "C:\Users\Sumeet Maheshwari\anaconda3\lib\site-packages\xgboost\sklearn.py", line 391, in fit
    self._Booster = train(params, trainDmatrix,
  File "C:\Users\Sumeet Maheshwari\anaconda3\lib\site-packages\xgboost\training.py", line 212, in train
    return _train_internal(params, dtrain,
  File "C:\Users\Sumeet Maheshwari\anaconda3\lib\site-packages\xgboost\training.py", line 74, in _train_internal
    bst.update(dtrain, i, obj)
  File "C:\Users\Sumeet Maheshwari\anaconda3\lib\site-packages\xgboost\core.py", line 1108, in update
    _check_call(_LIB.XGBoosterUpdateOneIter(self.handle, ctypes.c_int(iteration),
  File "C:\Users\Sumeet Maheshwari\anaconda3\lib\site-packages\xgboost\core.py", line 176, in _check_call
    raise XGBoostError(py_str(_LIB.XGBGetLastError()))
xgboost.core.XGBoostError: [09:02:43] C:\Jenkins\workspace\xgboost-win64_release_0.90\src\metric\metric.cc:23: Unknown metric function r2

--------------------------------------------------------------------------------
2 fits failed with the following error:
Traceback (most recent call last):
  File "C:\Users\Sumeet Maheshwari\anaconda3\lib\site-packages\sklearn\model_selection\_validation.py", line 686, in _fit_and_score
    estimator.fit(X_train, y_train, **fit_params)
  File "C:\Users\Sumeet Maheshwari\anaconda3\lib\site-packages\xgboost\sklearn.py", line 391, in fit
    self._Booster = train(params, trainDmatrix,
  File "C:\Users\Sumeet Maheshwari\anaconda3\lib\site-packages\xgboost\training.py", line 212, in train
    return _train_internal(params, dtrain,
  File "C:\Users\Sumeet Maheshwari\anaconda3\lib\site-packages\xgboost\training.py", line 74, in _train_internal
    bst.update(dtrain, i, obj)
  File "C:\Users\Sumeet Maheshwari\anaconda3\lib\site-packages\xgboost\core.py", line 1108, in update
    _check_call(_LIB.XGBoosterUpdateOneIter(self.handle, ctypes.c_int(iteration),
  File "C:\Users\Sumeet Maheshwari\anaconda3\lib\site-packages\xgboost\core.py", line 176, in _check_call
    raise XGBoostError(py_str(_LIB.XGBGetLastError()))
xgboost.core.XGBoostError: [09:02:44] C:\Jenkins\workspace\xgboost-win64_release_0.90\src\metric\metric.cc:23: Unknown metric function r2

--------------------------------------------------------------------------------
1 fits failed with the following error:
Traceback (most recent call last):
  File "C:\Users\Sumeet Maheshwari\anaconda3\lib\site-packages\sklearn\model_selection\_validation.py", line 686, in _fit_and_score
    estimator.fit(X_train, y_train, **fit_params)
  File "C:\Users\Sumeet Maheshwari\anaconda3\lib\site-packages\xgboost\sklearn.py", line 391, in fit
    self._Booster = train(params, trainDmatrix,
  File "C:\Users\Sumeet Maheshwari\anaconda3\lib\site-packages\xgboost\training.py", line 212, in train
    return _train_internal(params, dtrain,
  File "C:\Users\Sumeet Maheshwari\anaconda3\lib\site-packages\xgboost\training.py", line 74, in _train_internal
    bst.update(dtrain, i, obj)
  File "C:\Users\Sumeet Maheshwari\anaconda3\lib\site-packages\xgboost\core.py", line 1108, in update
    _check_call(_LIB.XGBoosterUpdateOneIter(self.handle, ctypes.c_int(iteration),
  File "C:\Users\Sumeet Maheshwari\anaconda3\lib\site-packages\xgboost\core.py", line 176, in _check_call
    raise XGBoostError(py_str(_LIB.XGBGetLastError()))
xgboost.core.XGBoostError: [09:02:45] C:\Jenkins\workspace\xgboost-win64_release_0.90\src\metric\metric.cc:23: Unknown metric function r2

--------------------------------------------------------------------------------
1 fits failed with the following error:
Traceback (most recent call last):
  File "C:\Users\Sumeet Maheshwari\anaconda3\lib\site-packages\sklearn\model_selection\_validation.py", line 686, in _fit_and_score
    estimator.fit(X_train, y_train, **fit_params)
  File "C:\Users\Sumeet Maheshwari\anaconda3\lib\site-packages\xgboost\sklearn.py", line 391, in fit
    self._Booster = train(params, trainDmatrix,
  File "C:\Users\Sumeet Maheshwari\anaconda3\lib\site-packages\xgboost\training.py", line 212, in train
    return _train_internal(params, dtrain,
  File "C:\Users\Sumeet Maheshwari\anaconda3\lib\site-packages\xgboost\training.py", line 74, in _train_internal
    bst.update(dtrain, i, obj)
  File "C:\Users\Sumeet Maheshwari\anaconda3\lib\site-packages\xgboost\core.py", line 1108, in update
    _check_call(_LIB.XGBoosterUpdateOneIter(self.handle, ctypes.c_int(iteration),
  File "C:\Users\Sumeet Maheshwari\anaconda3\lib\site-packages\xgboost\core.py", line 176, in _check_call
    raise XGBoostError(py_str(_LIB.XGBGetLastError()))
xgboost.core.XGBoostError: [09:02:46] C:\Jenkins\workspace\xgboost-win64_release_0.90\src\metric\metric.cc:23: Unknown metric function r2

--------------------------------------------------------------------------------
1 fits failed with the following error:
Traceback (most recent call last):
  File "C:\Users\Sumeet Maheshwari\anaconda3\lib\site-packages\sklearn\model_selection\_validation.py", line 686, in _fit_and_score
    estimator.fit(X_train, y_train, **fit_params)
  File "C:\Users\Sumeet Maheshwari\anaconda3\lib\site-packages\xgboost\sklearn.py", line 391, in fit
    self._Booster = train(params, trainDmatrix,
  File "C:\Users\Sumeet Maheshwari\anaconda3\lib\site-packages\xgboost\training.py", line 212, in train
    return _train_internal(params, dtrain,
  File "C:\Users\Sumeet Maheshwari\anaconda3\lib\site-packages\xgboost\training.py", line 74, in _train_internal
    bst.update(dtrain, i, obj)
  File "C:\Users\Sumeet Maheshwari\anaconda3\lib\site-packages\xgboost\core.py", line 1108, in update
    _check_call(_LIB.XGBoosterUpdateOneIter(self.handle, ctypes.c_int(iteration),
  File "C:\Users\Sumeet Maheshwari\anaconda3\lib\site-packages\xgboost\core.py", line 176, in _check_call
    raise XGBoostError(py_str(_LIB.XGBGetLastError()))
xgboost.core.XGBoostError: [09:02:47] C:\Jenkins\workspace\xgboost-win64_release_0.90\src\metric\metric.cc:23: Unknown metric function r2

--------------------------------------------------------------------------------
2 fits failed with the following error:
Traceback (most recent call last):
  File "C:\Users\Sumeet Maheshwari\anaconda3\lib\site-packages\sklearn\model_selection\_validation.py", line 686, in _fit_and_score
    estimator.fit(X_train, y_train, **fit_params)
  File "C:\Users\Sumeet Maheshwari\anaconda3\lib\site-packages\xgboost\sklearn.py", line 391, in fit
    self._Booster = train(params, trainDmatrix,
  File "C:\Users\Sumeet Maheshwari\anaconda3\lib\site-packages\xgboost\training.py", line 212, in train
    return _train_internal(params, dtrain,
  File "C:\Users\Sumeet Maheshwari\anaconda3\lib\site-packages\xgboost\training.py", line 74, in _train_internal
    bst.update(dtrain, i, obj)
  File "C:\Users\Sumeet Maheshwari\anaconda3\lib\site-packages\xgboost\core.py", line 1108, in update
    _check_call(_LIB.XGBoosterUpdateOneIter(self.handle, ctypes.c_int(iteration),
  File "C:\Users\Sumeet Maheshwari\anaconda3\lib\site-packages\xgboost\core.py", line 176, in _check_call
    raise XGBoostError(py_str(_LIB.XGBGetLastError()))
xgboost.core.XGBoostError: [09:02:48] C:\Jenkins\workspace\xgboost-win64_release_0.90\src\metric\metric.cc:23: Unknown metric function r2

--------------------------------------------------------------------------------
1 fits failed with the following error:
Traceback (most recent call last):
  File "C:\Users\Sumeet Maheshwari\anaconda3\lib\site-packages\sklearn\model_selection\_validation.py", line 686, in _fit_and_score
    estimator.fit(X_train, y_train, **fit_params)
  File "C:\Users\Sumeet Maheshwari\anaconda3\lib\site-packages\xgboost\sklearn.py", line 391, in fit
    self._Booster = train(params, trainDmatrix,
  File "C:\Users\Sumeet Maheshwari\anaconda3\lib\site-packages\xgboost\training.py", line 212, in train
    return _train_internal(params, dtrain,
  File "C:\Users\Sumeet Maheshwari\anaconda3\lib\site-packages\xgboost\training.py", line 74, in _train_internal
    bst.update(dtrain, i, obj)
  File "C:\Users\Sumeet Maheshwari\anaconda3\lib\site-packages\xgboost\core.py", line 1108, in update
    _check_call(_LIB.XGBoosterUpdateOneIter(self.handle, ctypes.c_int(iteration),
  File "C:\Users\Sumeet Maheshwari\anaconda3\lib\site-packages\xgboost\core.py", line 176, in _check_call
    raise XGBoostError(py_str(_LIB.XGBGetLastError()))
xgboost.core.XGBoostError: [09:02:49] C:\Jenkins\workspace\xgboost-win64_release_0.90\src\metric\metric.cc:23: Unknown metric function r2

--------------------------------------------------------------------------------
1 fits failed with the following error:
Traceback (most recent call last):
  File "C:\Users\Sumeet Maheshwari\anaconda3\lib\site-packages\sklearn\model_selection\_validation.py", line 686, in _fit_and_score
    estimator.fit(X_train, y_train, **fit_params)
  File "C:\Users\Sumeet Maheshwari\anaconda3\lib\site-packages\xgboost\sklearn.py", line 391, in fit
    self._Booster = train(params, trainDmatrix,
  File "C:\Users\Sumeet Maheshwari\anaconda3\lib\site-packages\xgboost\training.py", line 212, in train
    return _train_internal(params, dtrain,
  File "C:\Users\Sumeet Maheshwari\anaconda3\lib\site-packages\xgboost\training.py", line 74, in _train_internal
    bst.update(dtrain, i, obj)
  File "C:\Users\Sumeet Maheshwari\anaconda3\lib\site-packages\xgboost\core.py", line 1108, in update
    _check_call(_LIB.XGBoosterUpdateOneIter(self.handle, ctypes.c_int(iteration),
  File "C:\Users\Sumeet Maheshwari\anaconda3\lib\site-packages\xgboost\core.py", line 176, in _check_call
    raise XGBoostError(py_str(_LIB.XGBGetLastError()))
xgboost.core.XGBoostError: [09:02:50] C:\Jenkins\workspace\xgboost-win64_release_0.90\src\metric\metric.cc:23: Unknown metric function r2

--------------------------------------------------------------------------------
2 fits failed with the following error:
Traceback (most recent call last):
  File "C:\Users\Sumeet Maheshwari\anaconda3\lib\site-packages\sklearn\model_selection\_validation.py", line 686, in _fit_and_score
    estimator.fit(X_train, y_train, **fit_params)
  File "C:\Users\Sumeet Maheshwari\anaconda3\lib\site-packages\xgboost\sklearn.py", line 391, in fit
    self._Booster = train(params, trainDmatrix,
  File "C:\Users\Sumeet Maheshwari\anaconda3\lib\site-packages\xgboost\training.py", line 212, in train
    return _train_internal(params, dtrain,
  File "C:\Users\Sumeet Maheshwari\anaconda3\lib\site-packages\xgboost\training.py", line 74, in _train_internal
    bst.update(dtrain, i, obj)
  File "C:\Users\Sumeet Maheshwari\anaconda3\lib\site-packages\xgboost\core.py", line 1108, in update
    _check_call(_LIB.XGBoosterUpdateOneIter(self.handle, ctypes.c_int(iteration),
  File "C:\Users\Sumeet Maheshwari\anaconda3\lib\site-packages\xgboost\core.py", line 176, in _check_call
    raise XGBoostError(py_str(_LIB.XGBGetLastError()))
xgboost.core.XGBoostError: [09:02:51] C:\Jenkins\workspace\xgboost-win64_release_0.90\src\metric\metric.cc:23: Unknown metric function r2

--------------------------------------------------------------------------------
1 fits failed with the following error:
Traceback (most recent call last):
  File "C:\Users\Sumeet Maheshwari\anaconda3\lib\site-packages\sklearn\model_selection\_validation.py", line 686, in _fit_and_score
    estimator.fit(X_train, y_train, **fit_params)
  File "C:\Users\Sumeet Maheshwari\anaconda3\lib\site-packages\xgboost\sklearn.py", line 391, in fit
    self._Booster = train(params, trainDmatrix,
  File "C:\Users\Sumeet Maheshwari\anaconda3\lib\site-packages\xgboost\training.py", line 212, in train
    return _train_internal(params, dtrain,
  File "C:\Users\Sumeet Maheshwari\anaconda3\lib\site-packages\xgboost\training.py", line 74, in _train_internal
    bst.update(dtrain, i, obj)
  File "C:\Users\Sumeet Maheshwari\anaconda3\lib\site-packages\xgboost\core.py", line 1108, in update
    _check_call(_LIB.XGBoosterUpdateOneIter(self.handle, ctypes.c_int(iteration),
  File "C:\Users\Sumeet Maheshwari\anaconda3\lib\site-packages\xgboost\core.py", line 176, in _check_call
    raise XGBoostError(py_str(_LIB.XGBGetLastError()))
xgboost.core.XGBoostError: [09:02:52] C:\Jenkins\workspace\xgboost-win64_release_0.90\src\metric\metric.cc:23: Unknown metric function r2

--------------------------------------------------------------------------------
1 fits failed with the following error:
Traceback (most recent call last):
  File "C:\Users\Sumeet Maheshwari\anaconda3\lib\site-packages\sklearn\model_selection\_validation.py", line 686, in _fit_and_score
    estimator.fit(X_train, y_train, **fit_params)
  File "C:\Users\Sumeet Maheshwari\anaconda3\lib\site-packages\xgboost\sklearn.py", line 391, in fit
    self._Booster = train(params, trainDmatrix,
  File "C:\Users\Sumeet Maheshwari\anaconda3\lib\site-packages\xgboost\training.py", line 212, in train
    return _train_internal(params, dtrain,
  File "C:\Users\Sumeet Maheshwari\anaconda3\lib\site-packages\xgboost\training.py", line 74, in _train_internal
    bst.update(dtrain, i, obj)
  File "C:\Users\Sumeet Maheshwari\anaconda3\lib\site-packages\xgboost\core.py", line 1108, in update
    _check_call(_LIB.XGBoosterUpdateOneIter(self.handle, ctypes.c_int(iteration),
  File "C:\Users\Sumeet Maheshwari\anaconda3\lib\site-packages\xgboost\core.py", line 176, in _check_call
    raise XGBoostError(py_str(_LIB.XGBGetLastError()))
xgboost.core.XGBoostError: [09:02:53] C:\Jenkins\workspace\xgboost-win64_release_0.90\src\metric\metric.cc:23: Unknown metric function r2

--------------------------------------------------------------------------------
1 fits failed with the following error:
Traceback (most recent call last):
  File "C:\Users\Sumeet Maheshwari\anaconda3\lib\site-packages\sklearn\model_selection\_validation.py", line 686, in _fit_and_score
    estimator.fit(X_train, y_train, **fit_params)
  File "C:\Users\Sumeet Maheshwari\anaconda3\lib\site-packages\xgboost\sklearn.py", line 391, in fit
    self._Booster = train(params, trainDmatrix,
  File "C:\Users\Sumeet Maheshwari\anaconda3\lib\site-packages\xgboost\training.py", line 212, in train
    return _train_internal(params, dtrain,
  File "C:\Users\Sumeet Maheshwari\anaconda3\lib\site-packages\xgboost\training.py", line 74, in _train_internal
    bst.update(dtrain, i, obj)
  File "C:\Users\Sumeet Maheshwari\anaconda3\lib\site-packages\xgboost\core.py", line 1108, in update
    _check_call(_LIB.XGBoosterUpdateOneIter(self.handle, ctypes.c_int(iteration),
  File "C:\Users\Sumeet Maheshwari\anaconda3\lib\site-packages\xgboost\core.py", line 176, in _check_call
    raise XGBoostError(py_str(_LIB.XGBGetLastError()))
xgboost.core.XGBoostError: [09:02:54] C:\Jenkins\workspace\xgboost-win64_release_0.90\src\metric\metric.cc:23: Unknown metric function r2

--------------------------------------------------------------------------------
2 fits failed with the following error:
Traceback (most recent call last):
  File "C:\Users\Sumeet Maheshwari\anaconda3\lib\site-packages\sklearn\model_selection\_validation.py", line 686, in _fit_and_score
    estimator.fit(X_train, y_train, **fit_params)
  File "C:\Users\Sumeet Maheshwari\anaconda3\lib\site-packages\xgboost\sklearn.py", line 391, in fit
    self._Booster = train(params, trainDmatrix,
  File "C:\Users\Sumeet Maheshwari\anaconda3\lib\site-packages\xgboost\training.py", line 212, in train
    return _train_internal(params, dtrain,
  File "C:\Users\Sumeet Maheshwari\anaconda3\lib\site-packages\xgboost\training.py", line 74, in _train_internal
    bst.update(dtrain, i, obj)
  File "C:\Users\Sumeet Maheshwari\anaconda3\lib\site-packages\xgboost\core.py", line 1108, in update
    _check_call(_LIB.XGBoosterUpdateOneIter(self.handle, ctypes.c_int(iteration),
  File "C:\Users\Sumeet Maheshwari\anaconda3\lib\site-packages\xgboost\core.py", line 176, in _check_call
    raise XGBoostError(py_str(_LIB.XGBGetLastError()))
xgboost.core.XGBoostError: [09:02:55] C:\Jenkins\workspace\xgboost-win64_release_0.90\src\metric\metric.cc:23: Unknown metric function r2

--------------------------------------------------------------------------------
1 fits failed with the following error:
Traceback (most recent call last):
  File "C:\Users\Sumeet Maheshwari\anaconda3\lib\site-packages\sklearn\model_selection\_validation.py", line 686, in _fit_and_score
    estimator.fit(X_train, y_train, **fit_params)
  File "C:\Users\Sumeet Maheshwari\anaconda3\lib\site-packages\xgboost\sklearn.py", line 391, in fit
    self._Booster = train(params, trainDmatrix,
  File "C:\Users\Sumeet Maheshwari\anaconda3\lib\site-packages\xgboost\training.py", line 212, in train
    return _train_internal(params, dtrain,
  File "C:\Users\Sumeet Maheshwari\anaconda3\lib\site-packages\xgboost\training.py", line 74, in _train_internal
    bst.update(dtrain, i, obj)
  File "C:\Users\Sumeet Maheshwari\anaconda3\lib\site-packages\xgboost\core.py", line 1108, in update
    _check_call(_LIB.XGBoosterUpdateOneIter(self.handle, ctypes.c_int(iteration),
  File "C:\Users\Sumeet Maheshwari\anaconda3\lib\site-packages\xgboost\core.py", line 176, in _check_call
    raise XGBoostError(py_str(_LIB.XGBGetLastError()))
xgboost.core.XGBoostError: [09:02:56] C:\Jenkins\workspace\xgboost-win64_release_0.90\src\metric\metric.cc:23: Unknown metric function r2

--------------------------------------------------------------------------------
1 fits failed with the following error:
Traceback (most recent call last):
  File "C:\Users\Sumeet Maheshwari\anaconda3\lib\site-packages\sklearn\model_selection\_validation.py", line 686, in _fit_and_score
    estimator.fit(X_train, y_train, **fit_params)
  File "C:\Users\Sumeet Maheshwari\anaconda3\lib\site-packages\xgboost\sklearn.py", line 391, in fit
    self._Booster = train(params, trainDmatrix,
  File "C:\Users\Sumeet Maheshwari\anaconda3\lib\site-packages\xgboost\training.py", line 212, in train
    return _train_internal(params, dtrain,
  File "C:\Users\Sumeet Maheshwari\anaconda3\lib\site-packages\xgboost\training.py", line 74, in _train_internal
    bst.update(dtrain, i, obj)
  File "C:\Users\Sumeet Maheshwari\anaconda3\lib\site-packages\xgboost\core.py", line 1108, in update
    _check_call(_LIB.XGBoosterUpdateOneIter(self.handle, ctypes.c_int(iteration),
  File "C:\Users\Sumeet Maheshwari\anaconda3\lib\site-packages\xgboost\core.py", line 176, in _check_call
    raise XGBoostError(py_str(_LIB.XGBGetLastError()))
xgboost.core.XGBoostError: [09:02:57] C:\Jenkins\workspace\xgboost-win64_release_0.90\src\metric\metric.cc:23: Unknown metric function r2

--------------------------------------------------------------------------------
2 fits failed with the following error:
Traceback (most recent call last):
  File "C:\Users\Sumeet Maheshwari\anaconda3\lib\site-packages\sklearn\model_selection\_validation.py", line 686, in _fit_and_score
    estimator.fit(X_train, y_train, **fit_params)
  File "C:\Users\Sumeet Maheshwari\anaconda3\lib\site-packages\xgboost\sklearn.py", line 391, in fit
    self._Booster = train(params, trainDmatrix,
  File "C:\Users\Sumeet Maheshwari\anaconda3\lib\site-packages\xgboost\training.py", line 212, in train
    return _train_internal(params, dtrain,
  File "C:\Users\Sumeet Maheshwari\anaconda3\lib\site-packages\xgboost\training.py", line 74, in _train_internal
    bst.update(dtrain, i, obj)
  File "C:\Users\Sumeet Maheshwari\anaconda3\lib\site-packages\xgboost\core.py", line 1108, in update
    _check_call(_LIB.XGBoosterUpdateOneIter(self.handle, ctypes.c_int(iteration),
  File "C:\Users\Sumeet Maheshwari\anaconda3\lib\site-packages\xgboost\core.py", line 176, in _check_call
    raise XGBoostError(py_str(_LIB.XGBGetLastError()))
xgboost.core.XGBoostError: [09:02:58] C:\Jenkins\workspace\xgboost-win64_release_0.90\src\metric\metric.cc:23: Unknown metric function r2

--------------------------------------------------------------------------------
1 fits failed with the following error:
Traceback (most recent call last):
  File "C:\Users\Sumeet Maheshwari\anaconda3\lib\site-packages\sklearn\model_selection\_validation.py", line 686, in _fit_and_score
    estimator.fit(X_train, y_train, **fit_params)
  File "C:\Users\Sumeet Maheshwari\anaconda3\lib\site-packages\xgboost\sklearn.py", line 391, in fit
    self._Booster = train(params, trainDmatrix,
  File "C:\Users\Sumeet Maheshwari\anaconda3\lib\site-packages\xgboost\training.py", line 212, in train
    return _train_internal(params, dtrain,
  File "C:\Users\Sumeet Maheshwari\anaconda3\lib\site-packages\xgboost\training.py", line 74, in _train_internal
    bst.update(dtrain, i, obj)
  File "C:\Users\Sumeet Maheshwari\anaconda3\lib\site-packages\xgboost\core.py", line 1108, in update
    _check_call(_LIB.XGBoosterUpdateOneIter(self.handle, ctypes.c_int(iteration),
  File "C:\Users\Sumeet Maheshwari\anaconda3\lib\site-packages\xgboost\core.py", line 176, in _check_call
    raise XGBoostError(py_str(_LIB.XGBGetLastError()))
xgboost.core.XGBoostError: [09:02:59] C:\Jenkins\workspace\xgboost-win64_release_0.90\src\metric\metric.cc:23: Unknown metric function r2

--------------------------------------------------------------------------------
1 fits failed with the following error:
Traceback (most recent call last):
  File "C:\Users\Sumeet Maheshwari\anaconda3\lib\site-packages\sklearn\model_selection\_validation.py", line 686, in _fit_and_score
    estimator.fit(X_train, y_train, **fit_params)
  File "C:\Users\Sumeet Maheshwari\anaconda3\lib\site-packages\xgboost\sklearn.py", line 391, in fit
    self._Booster = train(params, trainDmatrix,
  File "C:\Users\Sumeet Maheshwari\anaconda3\lib\site-packages\xgboost\training.py", line 212, in train
    return _train_internal(params, dtrain,
  File "C:\Users\Sumeet Maheshwari\anaconda3\lib\site-packages\xgboost\training.py", line 74, in _train_internal
    bst.update(dtrain, i, obj)
  File "C:\Users\Sumeet Maheshwari\anaconda3\lib\site-packages\xgboost\core.py", line 1108, in update
    _check_call(_LIB.XGBoosterUpdateOneIter(self.handle, ctypes.c_int(iteration),
  File "C:\Users\Sumeet Maheshwari\anaconda3\lib\site-packages\xgboost\core.py", line 176, in _check_call
    raise XGBoostError(py_str(_LIB.XGBGetLastError()))
xgboost.core.XGBoostError: [09:03:00] C:\Jenkins\workspace\xgboost-win64_release_0.90\src\metric\metric.cc:23: Unknown metric function r2

--------------------------------------------------------------------------------
1 fits failed with the following error:
Traceback (most recent call last):
  File "C:\Users\Sumeet Maheshwari\anaconda3\lib\site-packages\sklearn\model_selection\_validation.py", line 686, in _fit_and_score
    estimator.fit(X_train, y_train, **fit_params)
  File "C:\Users\Sumeet Maheshwari\anaconda3\lib\site-packages\xgboost\sklearn.py", line 391, in fit
    self._Booster = train(params, trainDmatrix,
  File "C:\Users\Sumeet Maheshwari\anaconda3\lib\site-packages\xgboost\training.py", line 212, in train
    return _train_internal(params, dtrain,
  File "C:\Users\Sumeet Maheshwari\anaconda3\lib\site-packages\xgboost\training.py", line 74, in _train_internal
    bst.update(dtrain, i, obj)
  File "C:\Users\Sumeet Maheshwari\anaconda3\lib\site-packages\xgboost\core.py", line 1108, in update
    _check_call(_LIB.XGBoosterUpdateOneIter(self.handle, ctypes.c_int(iteration),
  File "C:\Users\Sumeet Maheshwari\anaconda3\lib\site-packages\xgboost\core.py", line 176, in _check_call
    raise XGBoostError(py_str(_LIB.XGBGetLastError()))
xgboost.core.XGBoostError: [09:03:01] C:\Jenkins\workspace\xgboost-win64_release_0.90\src\metric\metric.cc:23: Unknown metric function r2

--------------------------------------------------------------------------------
1 fits failed with the following error:
Traceback (most recent call last):
  File "C:\Users\Sumeet Maheshwari\anaconda3\lib\site-packages\sklearn\model_selection\_validation.py", line 686, in _fit_and_score
    estimator.fit(X_train, y_train, **fit_params)
  File "C:\Users\Sumeet Maheshwari\anaconda3\lib\site-packages\xgboost\sklearn.py", line 391, in fit
    self._Booster = train(params, trainDmatrix,
  File "C:\Users\Sumeet Maheshwari\anaconda3\lib\site-packages\xgboost\training.py", line 212, in train
    return _train_internal(params, dtrain,
  File "C:\Users\Sumeet Maheshwari\anaconda3\lib\site-packages\xgboost\training.py", line 74, in _train_internal
    bst.update(dtrain, i, obj)
  File "C:\Users\Sumeet Maheshwari\anaconda3\lib\site-packages\xgboost\core.py", line 1108, in update
    _check_call(_LIB.XGBoosterUpdateOneIter(self.handle, ctypes.c_int(iteration),
  File "C:\Users\Sumeet Maheshwari\anaconda3\lib\site-packages\xgboost\core.py", line 176, in _check_call
    raise XGBoostError(py_str(_LIB.XGBGetLastError()))
xgboost.core.XGBoostError: [09:03:02] C:\Jenkins\workspace\xgboost-win64_release_0.90\src\metric\metric.cc:23: Unknown metric function r2

--------------------------------------------------------------------------------
1 fits failed with the following error:
Traceback (most recent call last):
  File "C:\Users\Sumeet Maheshwari\anaconda3\lib\site-packages\sklearn\model_selection\_validation.py", line 686, in _fit_and_score
    estimator.fit(X_train, y_train, **fit_params)
  File "C:\Users\Sumeet Maheshwari\anaconda3\lib\site-packages\xgboost\sklearn.py", line 391, in fit
    self._Booster = train(params, trainDmatrix,
  File "C:\Users\Sumeet Maheshwari\anaconda3\lib\site-packages\xgboost\training.py", line 212, in train
    return _train_internal(params, dtrain,
  File "C:\Users\Sumeet Maheshwari\anaconda3\lib\site-packages\xgboost\training.py", line 74, in _train_internal
    bst.update(dtrain, i, obj)
  File "C:\Users\Sumeet Maheshwari\anaconda3\lib\site-packages\xgboost\core.py", line 1108, in update
    _check_call(_LIB.XGBoosterUpdateOneIter(self.handle, ctypes.c_int(iteration),
  File "C:\Users\Sumeet Maheshwari\anaconda3\lib\site-packages\xgboost\core.py", line 176, in _check_call
    raise XGBoostError(py_str(_LIB.XGBGetLastError()))
xgboost.core.XGBoostError: [09:03:03] C:\Jenkins\workspace\xgboost-win64_release_0.90\src\metric\metric.cc:23: Unknown metric function r2

--------------------------------------------------------------------------------
1 fits failed with the following error:
Traceback (most recent call last):
  File "C:\Users\Sumeet Maheshwari\anaconda3\lib\site-packages\sklearn\model_selection\_validation.py", line 686, in _fit_and_score
    estimator.fit(X_train, y_train, **fit_params)
  File "C:\Users\Sumeet Maheshwari\anaconda3\lib\site-packages\xgboost\sklearn.py", line 391, in fit
    self._Booster = train(params, trainDmatrix,
  File "C:\Users\Sumeet Maheshwari\anaconda3\lib\site-packages\xgboost\training.py", line 212, in train
    return _train_internal(params, dtrain,
  File "C:\Users\Sumeet Maheshwari\anaconda3\lib\site-packages\xgboost\training.py", line 74, in _train_internal
    bst.update(dtrain, i, obj)
  File "C:\Users\Sumeet Maheshwari\anaconda3\lib\site-packages\xgboost\core.py", line 1108, in update
    _check_call(_LIB.XGBoosterUpdateOneIter(self.handle, ctypes.c_int(iteration),
  File "C:\Users\Sumeet Maheshwari\anaconda3\lib\site-packages\xgboost\core.py", line 176, in _check_call
    raise XGBoostError(py_str(_LIB.XGBGetLastError()))
xgboost.core.XGBoostError: [09:03:04] C:\Jenkins\workspace\xgboost-win64_release_0.90\src\metric\metric.cc:23: Unknown metric function r2

--------------------------------------------------------------------------------
2 fits failed with the following error:
Traceback (most recent call last):
  File "C:\Users\Sumeet Maheshwari\anaconda3\lib\site-packages\sklearn\model_selection\_validation.py", line 686, in _fit_and_score
    estimator.fit(X_train, y_train, **fit_params)
  File "C:\Users\Sumeet Maheshwari\anaconda3\lib\site-packages\xgboost\sklearn.py", line 391, in fit
    self._Booster = train(params, trainDmatrix,
  File "C:\Users\Sumeet Maheshwari\anaconda3\lib\site-packages\xgboost\training.py", line 212, in train
    return _train_internal(params, dtrain,
  File "C:\Users\Sumeet Maheshwari\anaconda3\lib\site-packages\xgboost\training.py", line 74, in _train_internal
    bst.update(dtrain, i, obj)
  File "C:\Users\Sumeet Maheshwari\anaconda3\lib\site-packages\xgboost\core.py", line 1108, in update
    _check_call(_LIB.XGBoosterUpdateOneIter(self.handle, ctypes.c_int(iteration),
  File "C:\Users\Sumeet Maheshwari\anaconda3\lib\site-packages\xgboost\core.py", line 176, in _check_call
    raise XGBoostError(py_str(_LIB.XGBGetLastError()))
xgboost.core.XGBoostError: [09:03:05] C:\Jenkins\workspace\xgboost-win64_release_0.90\src\metric\metric.cc:23: Unknown metric function r2

--------------------------------------------------------------------------------
1 fits failed with the following error:
Traceback (most recent call last):
  File "C:\Users\Sumeet Maheshwari\anaconda3\lib\site-packages\sklearn\model_selection\_validation.py", line 686, in _fit_and_score
    estimator.fit(X_train, y_train, **fit_params)
  File "C:\Users\Sumeet Maheshwari\anaconda3\lib\site-packages\xgboost\sklearn.py", line 391, in fit
    self._Booster = train(params, trainDmatrix,
  File "C:\Users\Sumeet Maheshwari\anaconda3\lib\site-packages\xgboost\training.py", line 212, in train
    return _train_internal(params, dtrain,
  File "C:\Users\Sumeet Maheshwari\anaconda3\lib\site-packages\xgboost\training.py", line 74, in _train_internal
    bst.update(dtrain, i, obj)
  File "C:\Users\Sumeet Maheshwari\anaconda3\lib\site-packages\xgboost\core.py", line 1108, in update
    _check_call(_LIB.XGBoosterUpdateOneIter(self.handle, ctypes.c_int(iteration),
  File "C:\Users\Sumeet Maheshwari\anaconda3\lib\site-packages\xgboost\core.py", line 176, in _check_call
    raise XGBoostError(py_str(_LIB.XGBGetLastError()))
xgboost.core.XGBoostError: [09:03:06] C:\Jenkins\workspace\xgboost-win64_release_0.90\src\metric\metric.cc:23: Unknown metric function r2

--------------------------------------------------------------------------------
1 fits failed with the following error:
Traceback (most recent call last):
  File "C:\Users\Sumeet Maheshwari\anaconda3\lib\site-packages\sklearn\model_selection\_validation.py", line 686, in _fit_and_score
    estimator.fit(X_train, y_train, **fit_params)
  File "C:\Users\Sumeet Maheshwari\anaconda3\lib\site-packages\xgboost\sklearn.py", line 391, in fit
    self._Booster = train(params, trainDmatrix,
  File "C:\Users\Sumeet Maheshwari\anaconda3\lib\site-packages\xgboost\training.py", line 212, in train
    return _train_internal(params, dtrain,
  File "C:\Users\Sumeet Maheshwari\anaconda3\lib\site-packages\xgboost\training.py", line 74, in _train_internal
    bst.update(dtrain, i, obj)
  File "C:\Users\Sumeet Maheshwari\anaconda3\lib\site-packages\xgboost\core.py", line 1108, in update
    _check_call(_LIB.XGBoosterUpdateOneIter(self.handle, ctypes.c_int(iteration),
  File "C:\Users\Sumeet Maheshwari\anaconda3\lib\site-packages\xgboost\core.py", line 176, in _check_call
    raise XGBoostError(py_str(_LIB.XGBGetLastError()))
xgboost.core.XGBoostError: [09:03:07] C:\Jenkins\workspace\xgboost-win64_release_0.90\src\metric\metric.cc:23: Unknown metric function r2

--------------------------------------------------------------------------------
1 fits failed with the following error:
Traceback (most recent call last):
  File "C:\Users\Sumeet Maheshwari\anaconda3\lib\site-packages\sklearn\model_selection\_validation.py", line 686, in _fit_and_score
    estimator.fit(X_train, y_train, **fit_params)
  File "C:\Users\Sumeet Maheshwari\anaconda3\lib\site-packages\xgboost\sklearn.py", line 391, in fit
    self._Booster = train(params, trainDmatrix,
  File "C:\Users\Sumeet Maheshwari\anaconda3\lib\site-packages\xgboost\training.py", line 212, in train
    return _train_internal(params, dtrain,
  File "C:\Users\Sumeet Maheshwari\anaconda3\lib\site-packages\xgboost\training.py", line 74, in _train_internal
    bst.update(dtrain, i, obj)
  File "C:\Users\Sumeet Maheshwari\anaconda3\lib\site-packages\xgboost\core.py", line 1108, in update
    _check_call(_LIB.XGBoosterUpdateOneIter(self.handle, ctypes.c_int(iteration),
  File "C:\Users\Sumeet Maheshwari\anaconda3\lib\site-packages\xgboost\core.py", line 176, in _check_call
    raise XGBoostError(py_str(_LIB.XGBGetLastError()))
xgboost.core.XGBoostError: [09:03:08] C:\Jenkins\workspace\xgboost-win64_release_0.90\src\metric\metric.cc:23: Unknown metric function r2

--------------------------------------------------------------------------------
2 fits failed with the following error:
Traceback (most recent call last):
  File "C:\Users\Sumeet Maheshwari\anaconda3\lib\site-packages\sklearn\model_selection\_validation.py", line 686, in _fit_and_score
    estimator.fit(X_train, y_train, **fit_params)
  File "C:\Users\Sumeet Maheshwari\anaconda3\lib\site-packages\xgboost\sklearn.py", line 391, in fit
    self._Booster = train(params, trainDmatrix,
  File "C:\Users\Sumeet Maheshwari\anaconda3\lib\site-packages\xgboost\training.py", line 212, in train
    return _train_internal(params, dtrain,
  File "C:\Users\Sumeet Maheshwari\anaconda3\lib\site-packages\xgboost\training.py", line 74, in _train_internal
    bst.update(dtrain, i, obj)
  File "C:\Users\Sumeet Maheshwari\anaconda3\lib\site-packages\xgboost\core.py", line 1108, in update
    _check_call(_LIB.XGBoosterUpdateOneIter(self.handle, ctypes.c_int(iteration),
  File "C:\Users\Sumeet Maheshwari\anaconda3\lib\site-packages\xgboost\core.py", line 176, in _check_call
    raise XGBoostError(py_str(_LIB.XGBGetLastError()))
xgboost.core.XGBoostError: [09:03:09] C:\Jenkins\workspace\xgboost-win64_release_0.90\src\metric\metric.cc:23: Unknown metric function r2
]]]
[2023-06-12 09:03:10,298] root - INFO - 
******************** Model Training log completed ********************


